[2024-12-15T16:57:35.067+0000] {taskinstance.py:1159} INFO - Dependencies all met for dep_context=non-requeueable deps ti=<TaskInstance: All_Layer.clean_movies scheduled__2024-12-14T00:00:00+00:00 [queued]>
[2024-12-15T16:57:35.078+0000] {taskinstance.py:1159} INFO - Dependencies all met for dep_context=requeueable deps ti=<TaskInstance: All_Layer.clean_movies scheduled__2024-12-14T00:00:00+00:00 [queued]>
[2024-12-15T16:57:35.079+0000] {taskinstance.py:1361} INFO - Starting attempt 1 of 2
[2024-12-15T16:57:35.092+0000] {taskinstance.py:1382} INFO - Executing <Task(SparkSubmitOperator): clean_movies> on 2024-12-14 00:00:00+00:00
[2024-12-15T16:57:35.098+0000] {standard_task_runner.py:57} INFO - Started process 1803 to run task
[2024-12-15T16:57:35.101+0000] {standard_task_runner.py:84} INFO - Running: ['***', 'tasks', 'run', 'All_Layer', 'clean_movies', 'scheduled__2024-12-14T00:00:00+00:00', '--job-id', '61', '--raw', '--subdir', 'DAGS_FOLDER/All.py', '--cfg-path', '/tmp/tmpyodufxuj']
[2024-12-15T16:57:35.104+0000] {standard_task_runner.py:85} INFO - Job 61: Subtask clean_movies
[2024-12-15T16:57:35.153+0000] {task_command.py:416} INFO - Running <TaskInstance: All_Layer.clean_movies scheduled__2024-12-14T00:00:00+00:00 [running]> on host a2b73f6a4b3a
[2024-12-15T16:57:35.234+0000] {taskinstance.py:1662} INFO - Exporting env vars: AIRFLOW_CTX_DAG_OWNER='***' AIRFLOW_CTX_DAG_ID='All_Layer' AIRFLOW_CTX_TASK_ID='clean_movies' AIRFLOW_CTX_EXECUTION_DATE='2024-12-14T00:00:00+00:00' AIRFLOW_CTX_TRY_NUMBER='1' AIRFLOW_CTX_DAG_RUN_ID='scheduled__2024-12-14T00:00:00+00:00'
[2024-12-15T16:57:35.246+0000] {base.py:73} INFO - Using connection ID 'spark-conn' for task execution.
[2024-12-15T16:57:35.248+0000] {spark_submit.py:403} INFO - Spark-Submit cmd: spark-submit --master spark://spark-master:7077 --conf spark.sql.extensions=io.delta.sql.DeltaSparkSessionExtension --conf spark.sql.catalog.spark_catalog=org.apache.spark.sql.delta.catalog.DeltaCatalog --conf delta.enable-non-concurrent-writes=true --jars /opt/***/jars/hadoop-aws-3.3.4.jar,/opt/***/jars/s3-2.18.41.jar,/opt/***/jars/aws-java-sdk-1.12.367.jar,/opt/***/jars/delta-core_2.12-2.2.0.jar,/opt/***/jars/delta-storage-2.2.0.jar, --packages org.apache.hadoop:hadoop-aws:3.3.4 --num-executors 2 --total-executor-cores 2 --executor-cores 2 --executor-memory 2g --driver-memory 1g --name arrow-spark --deploy-mode client /opt/***/jobs/python/processing_movie.py s3a://lakehouse/bronze/movies.parquet s3a://lakehouse/sliver/movies
[2024-12-15T16:57:35.393+0000] {spark_submit.py:579} INFO - /home/***/.local/lib/python3.9/site-packages/pyspark/bin/load-spark-env.sh: line 68: ps: command not found
[2024-12-15T16:57:36.910+0000] {spark_submit.py:579} INFO - Warning: Ignoring non-Spark config property: delta.enable-non-concurrent-writes
[2024-12-15T16:57:37.159+0000] {spark_submit.py:579} INFO - :: loading settings :: url = jar:file:/home/***/.local/lib/python3.9/site-packages/pyspark/jars/ivy-2.5.1.jar!/org/apache/ivy/core/settings/ivysettings.xml
[2024-12-15T16:57:37.307+0000] {spark_submit.py:579} INFO - Ivy Default Cache set to: /home/***/.ivy2/cache
[2024-12-15T16:57:37.307+0000] {spark_submit.py:579} INFO - The jars for the packages stored in: /home/***/.ivy2/jars
[2024-12-15T16:57:37.313+0000] {spark_submit.py:579} INFO - org.apache.hadoop#hadoop-aws added as a dependency
[2024-12-15T16:57:37.315+0000] {spark_submit.py:579} INFO - :: resolving dependencies :: org.apache.spark#spark-submit-parent-b30684ec-4af8-4574-9813-529cc1e7495c;1.0
[2024-12-15T16:57:37.316+0000] {spark_submit.py:579} INFO - confs: [default]
[2024-12-15T16:57:37.471+0000] {spark_submit.py:579} INFO - found org.apache.hadoop#hadoop-aws;3.3.4 in spark-list
[2024-12-15T16:57:37.507+0000] {spark_submit.py:579} INFO - found com.amazonaws#aws-java-sdk-bundle;1.12.262 in central
[2024-12-15T16:57:37.536+0000] {spark_submit.py:579} INFO - found org.wildfly.openssl#wildfly-openssl;1.0.7.Final in central
[2024-12-15T16:57:37.559+0000] {spark_submit.py:579} INFO - :: resolution report :: resolve 235ms :: artifacts dl 9ms
[2024-12-15T16:57:37.560+0000] {spark_submit.py:579} INFO - :: modules in use:
[2024-12-15T16:57:37.561+0000] {spark_submit.py:579} INFO - com.amazonaws#aws-java-sdk-bundle;1.12.262 from central in [default]
[2024-12-15T16:57:37.561+0000] {spark_submit.py:579} INFO - org.apache.hadoop#hadoop-aws;3.3.4 from spark-list in [default]
[2024-12-15T16:57:37.562+0000] {spark_submit.py:579} INFO - org.wildfly.openssl#wildfly-openssl;1.0.7.Final from central in [default]
[2024-12-15T16:57:37.562+0000] {spark_submit.py:579} INFO - ---------------------------------------------------------------------
[2024-12-15T16:57:37.563+0000] {spark_submit.py:579} INFO - |                  |            modules            ||   artifacts   |
[2024-12-15T16:57:37.563+0000] {spark_submit.py:579} INFO - |       conf       | number| search|dwnlded|evicted|| number|dwnlded|
[2024-12-15T16:57:37.564+0000] {spark_submit.py:579} INFO - ---------------------------------------------------------------------
[2024-12-15T16:57:37.564+0000] {spark_submit.py:579} INFO - |      default     |   3   |   0   |   0   |   0   ||   3   |   0   |
[2024-12-15T16:57:37.565+0000] {spark_submit.py:579} INFO - ---------------------------------------------------------------------
[2024-12-15T16:57:37.565+0000] {spark_submit.py:579} INFO - :: retrieving :: org.apache.spark#spark-submit-parent-b30684ec-4af8-4574-9813-529cc1e7495c
[2024-12-15T16:57:37.565+0000] {spark_submit.py:579} INFO - confs: [default]
[2024-12-15T16:57:37.570+0000] {spark_submit.py:579} INFO - 0 artifacts copied, 3 already retrieved (0kB/6ms)
[2024-12-15T16:57:37.759+0000] {spark_submit.py:579} INFO - 24/12/15 16:57:37 WARN NativeCodeLoader: Unable to load native-hadoop library for your platform... using builtin-java classes where applicable
[2024-12-15T16:57:39.043+0000] {spark_submit.py:579} INFO - 2024-12-15 16:57:39,042 INFO: Initializing Spark session...
[2024-12-15T16:57:39.230+0000] {spark_submit.py:579} INFO - 24/12/15 16:57:39 INFO SparkContext: Running Spark version 3.3.2
[2024-12-15T16:57:39.263+0000] {spark_submit.py:579} INFO - 24/12/15 16:57:39 INFO ResourceUtils: ==============================================================
[2024-12-15T16:57:39.264+0000] {spark_submit.py:579} INFO - 24/12/15 16:57:39 INFO ResourceUtils: No custom resources configured for spark.driver.
[2024-12-15T16:57:39.264+0000] {spark_submit.py:579} INFO - 24/12/15 16:57:39 INFO ResourceUtils: ==============================================================
[2024-12-15T16:57:39.265+0000] {spark_submit.py:579} INFO - 24/12/15 16:57:39 INFO SparkContext: Submitted application: CleanMovies
[2024-12-15T16:57:39.287+0000] {spark_submit.py:579} INFO - 24/12/15 16:57:39 INFO ResourceProfile: Default ResourceProfile created, executor resources: Map(cores -> name: cores, amount: 2, script: , vendor: , memory -> name: memory, amount: 2048, script: , vendor: , offHeap -> name: offHeap, amount: 0, script: , vendor: ), task resources: Map(cpus -> name: cpus, amount: 1.0)
[2024-12-15T16:57:39.300+0000] {spark_submit.py:579} INFO - 24/12/15 16:57:39 INFO ResourceProfile: Limiting resource is cpus at 2 tasks per executor
[2024-12-15T16:57:39.302+0000] {spark_submit.py:579} INFO - 24/12/15 16:57:39 INFO ResourceProfileManager: Added ResourceProfile id: 0
[2024-12-15T16:57:39.351+0000] {spark_submit.py:579} INFO - 24/12/15 16:57:39 INFO SecurityManager: Changing view acls to: ***
[2024-12-15T16:57:39.352+0000] {spark_submit.py:579} INFO - 24/12/15 16:57:39 INFO SecurityManager: Changing modify acls to: ***
[2024-12-15T16:57:39.353+0000] {spark_submit.py:579} INFO - 24/12/15 16:57:39 INFO SecurityManager: Changing view acls groups to:
[2024-12-15T16:57:39.354+0000] {spark_submit.py:579} INFO - 24/12/15 16:57:39 INFO SecurityManager: Changing modify acls groups to:
[2024-12-15T16:57:39.355+0000] {spark_submit.py:579} INFO - 24/12/15 16:57:39 INFO SecurityManager: SecurityManager: authentication disabled; ui acls disabled; users  with view permissions: Set(***); groups with view permissions: Set(); users  with modify permissions: Set(***); groups with modify permissions: Set()
[2024-12-15T16:57:39.620+0000] {spark_submit.py:579} INFO - 24/12/15 16:57:39 INFO Utils: Successfully started service 'sparkDriver' on port 46791.
[2024-12-15T16:57:39.651+0000] {spark_submit.py:579} INFO - 24/12/15 16:57:39 INFO SparkEnv: Registering MapOutputTracker
[2024-12-15T16:57:39.685+0000] {spark_submit.py:579} INFO - 24/12/15 16:57:39 INFO SparkEnv: Registering BlockManagerMaster
[2024-12-15T16:57:39.701+0000] {spark_submit.py:579} INFO - 24/12/15 16:57:39 INFO BlockManagerMasterEndpoint: Using org.apache.spark.storage.DefaultTopologyMapper for getting topology information
[2024-12-15T16:57:39.702+0000] {spark_submit.py:579} INFO - 24/12/15 16:57:39 INFO BlockManagerMasterEndpoint: BlockManagerMasterEndpoint up
[2024-12-15T16:57:39.707+0000] {spark_submit.py:579} INFO - 24/12/15 16:57:39 INFO SparkEnv: Registering BlockManagerMasterHeartbeat
[2024-12-15T16:57:39.728+0000] {spark_submit.py:579} INFO - 24/12/15 16:57:39 INFO DiskBlockManager: Created local directory at /tmp/blockmgr-de95b51f-7a60-42a4-9a83-a3c68806492d
[2024-12-15T16:57:39.745+0000] {spark_submit.py:579} INFO - 24/12/15 16:57:39 INFO MemoryStore: MemoryStore started with capacity 434.4 MiB
[2024-12-15T16:57:39.765+0000] {spark_submit.py:579} INFO - 24/12/15 16:57:39 INFO SparkEnv: Registering OutputCommitCoordinator
[2024-12-15T16:57:39.973+0000] {spark_submit.py:579} INFO - 24/12/15 16:57:39 INFO Utils: Successfully started service 'SparkUI' on port 4040.
[2024-12-15T16:57:40.009+0000] {spark_submit.py:579} INFO - 24/12/15 16:57:40 INFO SparkContext: Added JAR file:///opt/***/jars/hadoop-aws-3.3.4.jar at spark://a2b73f6a4b3a:46791/jars/hadoop-aws-3.3.4.jar with timestamp 1734281859218
[2024-12-15T16:57:40.010+0000] {spark_submit.py:579} INFO - 24/12/15 16:57:40 INFO SparkContext: Added JAR file:///opt/***/jars/s3-2.18.41.jar at spark://a2b73f6a4b3a:46791/jars/s3-2.18.41.jar with timestamp 1734281859218
[2024-12-15T16:57:40.012+0000] {spark_submit.py:579} INFO - 24/12/15 16:57:40 INFO SparkContext: Added JAR file:///opt/***/jars/aws-java-sdk-1.12.367.jar at spark://a2b73f6a4b3a:46791/jars/aws-java-sdk-1.12.367.jar with timestamp 1734281859218
[2024-12-15T16:57:40.013+0000] {spark_submit.py:579} INFO - 24/12/15 16:57:40 INFO SparkContext: Added JAR file:///opt/***/jars/delta-core_2.12-2.2.0.jar at spark://a2b73f6a4b3a:46791/jars/delta-core_2.12-2.2.0.jar with timestamp 1734281859218
[2024-12-15T16:57:40.014+0000] {spark_submit.py:579} INFO - 24/12/15 16:57:40 INFO SparkContext: Added JAR file:///opt/***/jars/delta-storage-2.2.0.jar at spark://a2b73f6a4b3a:46791/jars/delta-storage-2.2.0.jar with timestamp 1734281859218
[2024-12-15T16:57:40.015+0000] {spark_submit.py:579} INFO - 24/12/15 16:57:40 INFO SparkContext: Added JAR file:///home/***/.ivy2/jars/org.apache.hadoop_hadoop-aws-3.3.4.jar at spark://a2b73f6a4b3a:46791/jars/org.apache.hadoop_hadoop-aws-3.3.4.jar with timestamp 1734281859218
[2024-12-15T16:57:40.016+0000] {spark_submit.py:579} INFO - 24/12/15 16:57:40 INFO SparkContext: Added JAR file:///home/***/.ivy2/jars/com.amazonaws_aws-java-sdk-bundle-1.12.262.jar at spark://a2b73f6a4b3a:46791/jars/com.amazonaws_aws-java-sdk-bundle-1.12.262.jar with timestamp 1734281859218
[2024-12-15T16:57:40.016+0000] {spark_submit.py:579} INFO - 24/12/15 16:57:40 INFO SparkContext: Added JAR file:///home/***/.ivy2/jars/org.wildfly.openssl_wildfly-openssl-1.0.7.Final.jar at spark://a2b73f6a4b3a:46791/jars/org.wildfly.openssl_wildfly-openssl-1.0.7.Final.jar with timestamp 1734281859218
[2024-12-15T16:57:40.018+0000] {spark_submit.py:579} INFO - 24/12/15 16:57:40 INFO SparkContext: Added file file:///home/***/.ivy2/jars/org.apache.hadoop_hadoop-aws-3.3.4.jar at spark://a2b73f6a4b3a:46791/files/org.apache.hadoop_hadoop-aws-3.3.4.jar with timestamp 1734281859218
[2024-12-15T16:57:40.020+0000] {spark_submit.py:579} INFO - 24/12/15 16:57:40 INFO Utils: Copying /home/***/.ivy2/jars/org.apache.hadoop_hadoop-aws-3.3.4.jar to /tmp/spark-dbec5d67-9fe6-4f89-9211-1d70e362f576/userFiles-9a70a116-e457-4f9d-bc7f-9fab9335d0fe/org.apache.hadoop_hadoop-aws-3.3.4.jar
[2024-12-15T16:57:40.031+0000] {spark_submit.py:579} INFO - 24/12/15 16:57:40 INFO SparkContext: Added file file:///home/***/.ivy2/jars/com.amazonaws_aws-java-sdk-bundle-1.12.262.jar at spark://a2b73f6a4b3a:46791/files/com.amazonaws_aws-java-sdk-bundle-1.12.262.jar with timestamp 1734281859218
[2024-12-15T16:57:40.032+0000] {spark_submit.py:579} INFO - 24/12/15 16:57:40 INFO Utils: Copying /home/***/.ivy2/jars/com.amazonaws_aws-java-sdk-bundle-1.12.262.jar to /tmp/spark-dbec5d67-9fe6-4f89-9211-1d70e362f576/userFiles-9a70a116-e457-4f9d-bc7f-9fab9335d0fe/com.amazonaws_aws-java-sdk-bundle-1.12.262.jar
[2024-12-15T16:57:40.259+0000] {spark_submit.py:579} INFO - 24/12/15 16:57:40 INFO SparkContext: Added file file:///home/***/.ivy2/jars/org.wildfly.openssl_wildfly-openssl-1.0.7.Final.jar at spark://a2b73f6a4b3a:46791/files/org.wildfly.openssl_wildfly-openssl-1.0.7.Final.jar with timestamp 1734281859218
[2024-12-15T16:57:40.259+0000] {spark_submit.py:579} INFO - 24/12/15 16:57:40 INFO Utils: Copying /home/***/.ivy2/jars/org.wildfly.openssl_wildfly-openssl-1.0.7.Final.jar to /tmp/spark-dbec5d67-9fe6-4f89-9211-1d70e362f576/userFiles-9a70a116-e457-4f9d-bc7f-9fab9335d0fe/org.wildfly.openssl_wildfly-openssl-1.0.7.Final.jar
[2024-12-15T16:57:40.375+0000] {spark_submit.py:579} INFO - 24/12/15 16:57:40 INFO StandaloneAppClient$ClientEndpoint: Connecting to master spark://spark-master:7077...
[2024-12-15T16:57:40.428+0000] {spark_submit.py:579} INFO - 24/12/15 16:57:40 INFO TransportClientFactory: Successfully created connection to spark-master/172.18.0.6:7077 after 32 ms (0 ms spent in bootstraps)
[2024-12-15T16:57:40.535+0000] {spark_submit.py:579} INFO - 24/12/15 16:57:40 INFO StandaloneSchedulerBackend: Connected to Spark cluster with app ID app-20241215165740-0004
[2024-12-15T16:57:40.538+0000] {spark_submit.py:579} INFO - 24/12/15 16:57:40 INFO StandaloneAppClient$ClientEndpoint: Executor added: app-20241215165740-0004/0 on worker-20241215164627-172.18.0.9-36685 (172.18.0.9:36685) with 2 core(s)
[2024-12-15T16:57:40.542+0000] {spark_submit.py:579} INFO - 24/12/15 16:57:40 INFO StandaloneSchedulerBackend: Granted executor ID app-20241215165740-0004/0 on hostPort 172.18.0.9:36685 with 2 core(s), 2.0 GiB RAM
[2024-12-15T16:57:40.546+0000] {spark_submit.py:579} INFO - 24/12/15 16:57:40 INFO Utils: Successfully started service 'org.apache.spark.network.netty.NettyBlockTransferService' on port 45891.
[2024-12-15T16:57:40.547+0000] {spark_submit.py:579} INFO - 24/12/15 16:57:40 INFO NettyBlockTransferService: Server created on a2b73f6a4b3a:45891
[2024-12-15T16:57:40.549+0000] {spark_submit.py:579} INFO - 24/12/15 16:57:40 INFO BlockManager: Using org.apache.spark.storage.RandomBlockReplicationPolicy for block replication policy
[2024-12-15T16:57:40.557+0000] {spark_submit.py:579} INFO - 24/12/15 16:57:40 INFO BlockManagerMaster: Registering BlockManager BlockManagerId(driver, a2b73f6a4b3a, 45891, None)
[2024-12-15T16:57:40.561+0000] {spark_submit.py:579} INFO - 24/12/15 16:57:40 INFO BlockManagerMasterEndpoint: Registering block manager a2b73f6a4b3a:45891 with 434.4 MiB RAM, BlockManagerId(driver, a2b73f6a4b3a, 45891, None)
[2024-12-15T16:57:40.564+0000] {spark_submit.py:579} INFO - 24/12/15 16:57:40 INFO BlockManagerMaster: Registered BlockManager BlockManagerId(driver, a2b73f6a4b3a, 45891, None)
[2024-12-15T16:57:40.565+0000] {spark_submit.py:579} INFO - 24/12/15 16:57:40 INFO BlockManager: Initialized BlockManager: BlockManagerId(driver, a2b73f6a4b3a, 45891, None)
[2024-12-15T16:57:40.597+0000] {spark_submit.py:579} INFO - 24/12/15 16:57:40 INFO StandaloneAppClient$ClientEndpoint: Executor updated: app-20241215165740-0004/0 is now RUNNING
[2024-12-15T16:57:40.818+0000] {spark_submit.py:579} INFO - 24/12/15 16:57:40 INFO StandaloneSchedulerBackend: SchedulerBackend is ready for scheduling beginning after reached minRegisteredResourcesRatio: 0.0
[2024-12-15T16:57:41.100+0000] {spark_submit.py:579} INFO - 2024-12-15 16:57:41,100 INFO: Spark session initialized successfully.
[2024-12-15T16:57:41.101+0000] {spark_submit.py:579} INFO - 2024-12-15 16:57:41,100 INFO: Reading data from s3a://lakehouse/bronze/movies.parquet
[2024-12-15T16:57:41.107+0000] {spark_submit.py:579} INFO - 24/12/15 16:57:41 INFO SharedState: Setting hive.metastore.warehouse.dir ('null') to the value of spark.sql.warehouse.dir.
[2024-12-15T16:57:41.309+0000] {spark_submit.py:579} INFO - 24/12/15 16:57:41 WARN MetricsConfig: Cannot locate configuration: tried hadoop-metrics2-s3a-file-system.properties,hadoop-metrics2.properties
[2024-12-15T16:57:41.323+0000] {spark_submit.py:579} INFO - 24/12/15 16:57:41 INFO MetricsSystemImpl: Scheduled Metric snapshot period at 10 second(s).
[2024-12-15T16:57:41.324+0000] {spark_submit.py:579} INFO - 24/12/15 16:57:41 INFO MetricsSystemImpl: s3a-file-system metrics system started
[2024-12-15T16:57:42.399+0000] {spark_submit.py:579} INFO - 24/12/15 16:57:42 INFO SharedState: Warehouse path is 's3a://lakehouse/'.
[2024-12-15T16:57:43.111+0000] {spark_submit.py:579} INFO - 24/12/15 16:57:43 INFO CoarseGrainedSchedulerBackend$DriverEndpoint: Registered executor NettyRpcEndpointRef(spark-client://Executor) (172.18.0.9:36176) with ID 0,  ResourceProfileId 0
[2024-12-15T16:57:43.188+0000] {spark_submit.py:579} INFO - 24/12/15 16:57:43 INFO BlockManagerMasterEndpoint: Registering block manager 172.18.0.9:33561 with 1048.8 MiB RAM, BlockManagerId(0, 172.18.0.9, 33561, None)
[2024-12-15T16:57:43.928+0000] {spark_submit.py:579} INFO - 24/12/15 16:57:43 INFO InMemoryFileIndex: It took 110 ms to list leaf files for 1 paths.
[2024-12-15T16:57:46.694+0000] {spark_submit.py:579} INFO - 2024-12-15 16:57:46,694 INFO: Saving cleaned data to s3a://lakehouse/sliver/movies
[2024-12-15T16:57:47.193+0000] {spark_submit.py:579} INFO - 24/12/15 16:57:47 WARN package: Truncated the string representation of a plan since it was too large. This behavior can be adjusted by setting 'spark.sql.debug.maxToStringFields'.
[2024-12-15T16:57:47.685+0000] {spark_submit.py:579} INFO - 24/12/15 16:57:47 INFO DeltaLog: Loading version 1.
[2024-12-15T16:57:47.829+0000] {spark_submit.py:579} INFO - 24/12/15 16:57:47 INFO Snapshot: [tableId=01fad178-79fd-48d8-a378-85cc2be36432] DELTA: Compute snapshot for version: 1
[2024-12-15T16:57:48.079+0000] {spark_submit.py:579} INFO - 24/12/15 16:57:48 INFO MemoryStore: Block broadcast_0 stored as values in memory (estimated size 204.6 KiB, free 434.2 MiB)
[2024-12-15T16:57:48.170+0000] {spark_submit.py:579} INFO - 24/12/15 16:57:48 INFO MemoryStore: Block broadcast_0_piece0 stored as bytes in memory (estimated size 35.5 KiB, free 434.2 MiB)
[2024-12-15T16:57:48.175+0000] {spark_submit.py:579} INFO - 24/12/15 16:57:48 INFO BlockManagerInfo: Added broadcast_0_piece0 in memory on a2b73f6a4b3a:45891 (size: 35.5 KiB, free: 434.4 MiB)
[2024-12-15T16:57:48.194+0000] {spark_submit.py:579} INFO - 24/12/15 16:57:48 INFO SparkContext: Created broadcast 0 from toString at String.java:2951
[2024-12-15T16:57:48.273+0000] {spark_submit.py:579} INFO - 24/12/15 16:57:48 INFO DeltaLogFileIndex: Created DeltaLogFileIndex(JSON, numFilesInSegment: 2, totalFileSize: 5960)
[2024-12-15T16:57:49.368+0000] {spark_submit.py:579} INFO - 24/12/15 16:57:49 INFO FileSourceStrategy: Pushed Filters:
[2024-12-15T16:57:49.370+0000] {spark_submit.py:579} INFO - 24/12/15 16:57:49 INFO FileSourceStrategy: Post-Scan Filters:
[2024-12-15T16:57:49.372+0000] {spark_submit.py:579} INFO - 24/12/15 16:57:49 INFO FileSourceStrategy: Output Data Schema: struct<txn: struct<appId: string, version: bigint, lastUpdated: bigint ... 1 more fields>, add: struct<path: string, partitionValues: map<string,string>, size: bigint, modificationTime: bigint, dataChange: boolean ... 5 more fields>, remove: struct<path: string, deletionTimestamp: bigint, dataChange: boolean, extendedFileMetadata: boolean, partitionValues: map<string,string> ... 5 more fields>, metaData: struct<id: string, name: string, description: string, format: struct<provider: string, options: map<string,string>>, schemaString: string ... 6 more fields>, protocol: struct<minReaderVersion: int, minWriterVersion: int> ... 5 more fields>
[2024-12-15T16:57:50.139+0000] {spark_submit.py:579} INFO - 24/12/15 16:57:50 INFO CodeGenerator: Code generated in 346.838066 ms
[2024-12-15T16:57:50.145+0000] {spark_submit.py:579} INFO - 24/12/15 16:57:50 INFO MemoryStore: Block broadcast_1 stored as values in memory (estimated size 204.9 KiB, free 434.0 MiB)
[2024-12-15T16:57:50.162+0000] {spark_submit.py:579} INFO - 24/12/15 16:57:50 INFO MemoryStore: Block broadcast_1_piece0 stored as bytes in memory (estimated size 35.6 KiB, free 433.9 MiB)
[2024-12-15T16:57:50.163+0000] {spark_submit.py:579} INFO - 24/12/15 16:57:50 INFO BlockManagerInfo: Added broadcast_1_piece0 in memory on a2b73f6a4b3a:45891 (size: 35.6 KiB, free: 434.3 MiB)
[2024-12-15T16:57:50.165+0000] {spark_submit.py:579} INFO - 24/12/15 16:57:50 INFO SparkContext: Created broadcast 1 from toString at String.java:2951
[2024-12-15T16:57:50.182+0000] {spark_submit.py:579} INFO - 24/12/15 16:57:50 INFO FileSourceScanExec: Planning scan with bin packing, max size: 4197284 bytes, open cost is considered as scanning 4194304 bytes.
[2024-12-15T16:57:50.341+0000] {spark_submit.py:579} INFO - 24/12/15 16:57:50 INFO DAGScheduler: Registering RDD 3 (toString at String.java:2951) as input to shuffle 0
[2024-12-15T16:57:50.345+0000] {spark_submit.py:579} INFO - 24/12/15 16:57:50 INFO DAGScheduler: Got map stage job 0 (toString at String.java:2951) with 2 output partitions
[2024-12-15T16:57:50.346+0000] {spark_submit.py:579} INFO - 24/12/15 16:57:50 INFO DAGScheduler: Final stage: ShuffleMapStage 0 (toString at String.java:2951)
[2024-12-15T16:57:50.347+0000] {spark_submit.py:579} INFO - 24/12/15 16:57:50 INFO DAGScheduler: Parents of final stage: List()
[2024-12-15T16:57:50.348+0000] {spark_submit.py:579} INFO - 24/12/15 16:57:50 INFO DAGScheduler: Missing parents: List()
[2024-12-15T16:57:50.352+0000] {spark_submit.py:579} INFO - 24/12/15 16:57:50 INFO DAGScheduler: Submitting ShuffleMapStage 0 (MapPartitionsRDD[3] at toString at String.java:2951), which has no missing parents
[2024-12-15T16:57:50.441+0000] {spark_submit.py:579} INFO - 24/12/15 16:57:50 INFO MemoryStore: Block broadcast_2 stored as values in memory (estimated size 124.3 KiB, free 433.8 MiB)
[2024-12-15T16:57:50.458+0000] {spark_submit.py:579} INFO - 24/12/15 16:57:50 INFO MemoryStore: Block broadcast_2_piece0 stored as bytes in memory (estimated size 35.1 KiB, free 433.8 MiB)
[2024-12-15T16:57:50.460+0000] {spark_submit.py:579} INFO - 24/12/15 16:57:50 INFO BlockManagerInfo: Added broadcast_2_piece0 in memory on a2b73f6a4b3a:45891 (size: 35.1 KiB, free: 434.3 MiB)
[2024-12-15T16:57:50.461+0000] {spark_submit.py:579} INFO - 24/12/15 16:57:50 INFO SparkContext: Created broadcast 2 from broadcast at DAGScheduler.scala:1513
[2024-12-15T16:57:50.481+0000] {spark_submit.py:579} INFO - 24/12/15 16:57:50 INFO DAGScheduler: Submitting 2 missing tasks from ShuffleMapStage 0 (MapPartitionsRDD[3] at toString at String.java:2951) (first 15 tasks are for partitions Vector(0, 1))
[2024-12-15T16:57:50.484+0000] {spark_submit.py:579} INFO - 24/12/15 16:57:50 INFO TaskSchedulerImpl: Adding task set 0.0 with 2 tasks resource profile 0
[2024-12-15T16:57:50.531+0000] {spark_submit.py:579} INFO - 24/12/15 16:57:50 INFO TaskSetManager: Starting task 0.0 in stage 0.0 (TID 0) (172.18.0.9, executor 0, partition 0, PROCESS_LOCAL, 4930 bytes) taskResourceAssignments Map()
[2024-12-15T16:57:50.535+0000] {spark_submit.py:579} INFO - 24/12/15 16:57:50 INFO TaskSetManager: Starting task 1.0 in stage 0.0 (TID 1) (172.18.0.9, executor 0, partition 1, PROCESS_LOCAL, 4930 bytes) taskResourceAssignments Map()
[2024-12-15T16:57:50.744+0000] {spark_submit.py:579} INFO - 24/12/15 16:57:50 INFO BlockManagerInfo: Added broadcast_2_piece0 in memory on 172.18.0.9:33561 (size: 35.1 KiB, free: 1048.8 MiB)
[2024-12-15T16:57:51.852+0000] {spark_submit.py:579} INFO - 24/12/15 16:57:51 INFO BlockManagerInfo: Added broadcast_1_piece0 in memory on 172.18.0.9:33561 (size: 35.6 KiB, free: 1048.7 MiB)
[2024-12-15T16:57:54.367+0000] {spark_submit.py:579} INFO - 24/12/15 16:57:54 INFO TaskSetManager: Finished task 1.0 in stage 0.0 (TID 1) in 3832 ms on 172.18.0.9 (executor 0) (1/2)
[2024-12-15T16:57:54.370+0000] {spark_submit.py:579} INFO - 24/12/15 16:57:54 INFO TaskSetManager: Finished task 0.0 in stage 0.0 (TID 0) in 3847 ms on 172.18.0.9 (executor 0) (2/2)
[2024-12-15T16:57:54.372+0000] {spark_submit.py:579} INFO - 24/12/15 16:57:54 INFO TaskSchedulerImpl: Removed TaskSet 0.0, whose tasks have all completed, from pool
[2024-12-15T16:57:54.393+0000] {spark_submit.py:579} INFO - 24/12/15 16:57:54 INFO DAGScheduler: ShuffleMapStage 0 (toString at String.java:2951) finished in 4.027 s
[2024-12-15T16:57:54.394+0000] {spark_submit.py:579} INFO - 24/12/15 16:57:54 INFO DAGScheduler: looking for newly runnable stages
[2024-12-15T16:57:54.397+0000] {spark_submit.py:579} INFO - 24/12/15 16:57:54 INFO DAGScheduler: running: Set()
[2024-12-15T16:57:54.398+0000] {spark_submit.py:579} INFO - 24/12/15 16:57:54 INFO DAGScheduler: waiting: Set()
[2024-12-15T16:57:54.399+0000] {spark_submit.py:579} INFO - 24/12/15 16:57:54 INFO DAGScheduler: failed: Set()
[2024-12-15T16:57:54.596+0000] {spark_submit.py:579} INFO - 24/12/15 16:57:54 INFO BlockManagerInfo: Removed broadcast_2_piece0 on a2b73f6a4b3a:45891 in memory (size: 35.1 KiB, free: 434.3 MiB)
[2024-12-15T16:57:54.609+0000] {spark_submit.py:579} INFO - 24/12/15 16:57:54 INFO BlockManagerInfo: Removed broadcast_2_piece0 on 172.18.0.9:33561 in memory (size: 35.1 KiB, free: 1048.8 MiB)
[2024-12-15T16:57:54.838+0000] {spark_submit.py:579} INFO - 24/12/15 16:57:54 INFO CodeGenerator: Generated method too long to be JIT compiled: org.apache.spark.sql.catalyst.expressions.GeneratedClass$GeneratedIteratorForCodegenStage3.serializefromobject_doConsume_0$ is 14899 bytes
[2024-12-15T16:57:54.839+0000] {spark_submit.py:579} INFO - 24/12/15 16:57:54 INFO CodeGenerator: Code generated in 236.642802 ms
[2024-12-15T16:57:54.905+0000] {spark_submit.py:579} INFO - 24/12/15 16:57:54 INFO CodeGenerator: Code generated in 44.800239 ms
[2024-12-15T16:57:55.277+0000] {spark_submit.py:579} INFO - 24/12/15 16:57:55 INFO CodeGenerator: Code generated in 56.418982 ms
[2024-12-15T16:57:55.291+0000] {spark_submit.py:579} INFO - 24/12/15 16:57:55 INFO DAGScheduler: Registering RDD 13 (toString at String.java:2951) as input to shuffle 1
[2024-12-15T16:57:55.292+0000] {spark_submit.py:579} INFO - 24/12/15 16:57:55 INFO DAGScheduler: Got map stage job 1 (toString at String.java:2951) with 50 output partitions
[2024-12-15T16:57:55.292+0000] {spark_submit.py:579} INFO - 24/12/15 16:57:55 INFO DAGScheduler: Final stage: ShuffleMapStage 2 (toString at String.java:2951)
[2024-12-15T16:57:55.293+0000] {spark_submit.py:579} INFO - 24/12/15 16:57:55 INFO DAGScheduler: Parents of final stage: List(ShuffleMapStage 1)
[2024-12-15T16:57:55.295+0000] {spark_submit.py:579} INFO - 24/12/15 16:57:55 INFO DAGScheduler: Missing parents: List()
[2024-12-15T16:57:55.296+0000] {spark_submit.py:579} INFO - 24/12/15 16:57:55 INFO DAGScheduler: Submitting ShuffleMapStage 2 (MapPartitionsRDD[13] at toString at String.java:2951), which has no missing parents
[2024-12-15T16:57:55.399+0000] {spark_submit.py:579} INFO - 24/12/15 16:57:55 INFO MemoryStore: Block broadcast_3 stored as values in memory (estimated size 426.3 KiB, free 433.5 MiB)
[2024-12-15T16:57:55.401+0000] {spark_submit.py:579} INFO - 24/12/15 16:57:55 INFO MemoryStore: Block broadcast_3_piece0 stored as bytes in memory (estimated size 102.5 KiB, free 433.4 MiB)
[2024-12-15T16:57:55.402+0000] {spark_submit.py:579} INFO - 24/12/15 16:57:55 INFO BlockManagerInfo: Added broadcast_3_piece0 in memory on a2b73f6a4b3a:45891 (size: 102.5 KiB, free: 434.2 MiB)
[2024-12-15T16:57:55.404+0000] {spark_submit.py:579} INFO - 24/12/15 16:57:55 INFO SparkContext: Created broadcast 3 from broadcast at DAGScheduler.scala:1513
[2024-12-15T16:57:55.405+0000] {spark_submit.py:579} INFO - 24/12/15 16:57:55 INFO DAGScheduler: Submitting 50 missing tasks from ShuffleMapStage 2 (MapPartitionsRDD[13] at toString at String.java:2951) (first 15 tasks are for partitions Vector(0, 1, 2, 3, 4, 5, 6, 7, 8, 9, 10, 11, 12, 13, 14))
[2024-12-15T16:57:55.405+0000] {spark_submit.py:579} INFO - 24/12/15 16:57:55 INFO TaskSchedulerImpl: Adding task set 2.0 with 50 tasks resource profile 0
[2024-12-15T16:57:55.411+0000] {spark_submit.py:579} INFO - 24/12/15 16:57:55 INFO TaskSetManager: Starting task 22.0 in stage 2.0 (TID 2) (172.18.0.9, executor 0, partition 22, NODE_LOCAL, 4446 bytes) taskResourceAssignments Map()
[2024-12-15T16:57:55.412+0000] {spark_submit.py:579} INFO - 24/12/15 16:57:55 INFO TaskSetManager: Starting task 42.0 in stage 2.0 (TID 3) (172.18.0.9, executor 0, partition 42, NODE_LOCAL, 4446 bytes) taskResourceAssignments Map()
[2024-12-15T16:57:55.477+0000] {spark_submit.py:579} INFO - 24/12/15 16:57:55 INFO BlockManagerInfo: Added broadcast_3_piece0 in memory on 172.18.0.9:33561 (size: 102.5 KiB, free: 1048.7 MiB)
[2024-12-15T16:57:55.683+0000] {spark_submit.py:579} INFO - 24/12/15 16:57:55 INFO MapOutputTrackerMasterEndpoint: Asked to send map output locations for shuffle 0 to 172.18.0.9:36176
[2024-12-15T16:57:56.463+0000] {spark_submit.py:579} INFO - 24/12/15 16:57:56 INFO BlockManagerInfo: Added rdd_10_22 in memory on 172.18.0.9:33561 (size: 1183.0 B, free: 1048.7 MiB)
[2024-12-15T16:57:56.520+0000] {spark_submit.py:579} INFO - 24/12/15 16:57:56 INFO BlockManagerInfo: Added rdd_10_42 in memory on 172.18.0.9:33561 (size: 669.0 B, free: 1048.7 MiB)
[2024-12-15T16:57:56.693+0000] {spark_submit.py:579} INFO - 24/12/15 16:57:56 INFO TaskSetManager: Starting task 44.0 in stage 2.0 (TID 4) (172.18.0.9, executor 0, partition 44, NODE_LOCAL, 4446 bytes) taskResourceAssignments Map()
[2024-12-15T16:57:56.696+0000] {spark_submit.py:579} INFO - 24/12/15 16:57:56 INFO TaskSetManager: Finished task 22.0 in stage 2.0 (TID 2) in 1286 ms on 172.18.0.9 (executor 0) (1/50)
[2024-12-15T16:57:56.701+0000] {spark_submit.py:579} INFO - 24/12/15 16:57:56 INFO TaskSetManager: Starting task 0.0 in stage 2.0 (TID 5) (172.18.0.9, executor 0, partition 0, PROCESS_LOCAL, 4446 bytes) taskResourceAssignments Map()
[2024-12-15T16:57:56.705+0000] {spark_submit.py:579} INFO - 24/12/15 16:57:56 INFO TaskSetManager: Finished task 42.0 in stage 2.0 (TID 3) in 1292 ms on 172.18.0.9 (executor 0) (2/50)
[2024-12-15T16:57:56.793+0000] {spark_submit.py:579} INFO - 24/12/15 16:57:56 INFO BlockManagerInfo: Added rdd_10_44 in memory on 172.18.0.9:33561 (size: 293.0 B, free: 1048.7 MiB)
[2024-12-15T16:57:56.802+0000] {spark_submit.py:579} INFO - 24/12/15 16:57:56 INFO BlockManagerInfo: Added rdd_10_0 in memory on 172.18.0.9:33561 (size: 46.0 B, free: 1048.7 MiB)
[2024-12-15T16:57:56.846+0000] {spark_submit.py:579} INFO - 24/12/15 16:57:56 INFO TaskSetManager: Starting task 1.0 in stage 2.0 (TID 6) (172.18.0.9, executor 0, partition 1, PROCESS_LOCAL, 4446 bytes) taskResourceAssignments Map()
[2024-12-15T16:57:56.848+0000] {spark_submit.py:579} INFO - 24/12/15 16:57:56 INFO TaskSetManager: Finished task 44.0 in stage 2.0 (TID 4) in 155 ms on 172.18.0.9 (executor 0) (3/50)
[2024-12-15T16:57:56.849+0000] {spark_submit.py:579} INFO - 24/12/15 16:57:56 INFO TaskSetManager: Starting task 2.0 in stage 2.0 (TID 7) (172.18.0.9, executor 0, partition 2, PROCESS_LOCAL, 4446 bytes) taskResourceAssignments Map()
[2024-12-15T16:57:56.852+0000] {spark_submit.py:579} INFO - 24/12/15 16:57:56 INFO TaskSetManager: Finished task 0.0 in stage 2.0 (TID 5) in 151 ms on 172.18.0.9 (executor 0) (4/50)
[2024-12-15T16:57:56.933+0000] {spark_submit.py:579} INFO - 24/12/15 16:57:56 INFO BlockManagerInfo: Added rdd_10_2 in memory on 172.18.0.9:33561 (size: 46.0 B, free: 1048.7 MiB)
[2024-12-15T16:57:56.934+0000] {spark_submit.py:579} INFO - 24/12/15 16:57:56 INFO BlockManagerInfo: Added rdd_10_1 in memory on 172.18.0.9:33561 (size: 46.0 B, free: 1048.7 MiB)
[2024-12-15T16:57:56.973+0000] {spark_submit.py:579} INFO - 24/12/15 16:57:56 INFO TaskSetManager: Starting task 3.0 in stage 2.0 (TID 8) (172.18.0.9, executor 0, partition 3, PROCESS_LOCAL, 4446 bytes) taskResourceAssignments Map()
[2024-12-15T16:57:56.974+0000] {spark_submit.py:579} INFO - 24/12/15 16:57:56 INFO TaskSetManager: Finished task 2.0 in stage 2.0 (TID 7) in 127 ms on 172.18.0.9 (executor 0) (5/50)
[2024-12-15T16:57:56.975+0000] {spark_submit.py:579} INFO - 24/12/15 16:57:56 INFO TaskSetManager: Starting task 4.0 in stage 2.0 (TID 9) (172.18.0.9, executor 0, partition 4, PROCESS_LOCAL, 4446 bytes) taskResourceAssignments Map()
[2024-12-15T16:57:56.976+0000] {spark_submit.py:579} INFO - 24/12/15 16:57:56 INFO TaskSetManager: Finished task 1.0 in stage 2.0 (TID 6) in 130 ms on 172.18.0.9 (executor 0) (6/50)
[2024-12-15T16:57:57.042+0000] {spark_submit.py:579} INFO - 24/12/15 16:57:57 INFO BlockManagerInfo: Added rdd_10_3 in memory on 172.18.0.9:33561 (size: 46.0 B, free: 1048.7 MiB)
[2024-12-15T16:57:57.046+0000] {spark_submit.py:579} INFO - 24/12/15 16:57:57 INFO BlockManagerInfo: Added rdd_10_4 in memory on 172.18.0.9:33561 (size: 46.0 B, free: 1048.7 MiB)
[2024-12-15T16:57:57.089+0000] {spark_submit.py:579} INFO - 24/12/15 16:57:57 INFO TaskSetManager: Finished task 4.0 in stage 2.0 (TID 9) in 113 ms on 172.18.0.9 (executor 0) (7/50)
[2024-12-15T16:57:57.093+0000] {spark_submit.py:579} INFO - 24/12/15 16:57:57 INFO TaskSetManager: Starting task 5.0 in stage 2.0 (TID 10) (172.18.0.9, executor 0, partition 5, PROCESS_LOCAL, 4446 bytes) taskResourceAssignments Map()
[2024-12-15T16:57:57.094+0000] {spark_submit.py:579} INFO - 24/12/15 16:57:57 INFO TaskSetManager: Starting task 6.0 in stage 2.0 (TID 11) (172.18.0.9, executor 0, partition 6, PROCESS_LOCAL, 4446 bytes) taskResourceAssignments Map()
[2024-12-15T16:57:57.094+0000] {spark_submit.py:579} INFO - 24/12/15 16:57:57 INFO TaskSetManager: Finished task 3.0 in stage 2.0 (TID 8) in 119 ms on 172.18.0.9 (executor 0) (8/50)
[2024-12-15T16:57:57.153+0000] {spark_submit.py:579} INFO - 24/12/15 16:57:57 INFO BlockManagerInfo: Added rdd_10_6 in memory on 172.18.0.9:33561 (size: 46.0 B, free: 1048.7 MiB)
[2024-12-15T16:57:57.154+0000] {spark_submit.py:579} INFO - 24/12/15 16:57:57 INFO BlockManagerInfo: Added rdd_10_5 in memory on 172.18.0.9:33561 (size: 46.0 B, free: 1048.7 MiB)
[2024-12-15T16:57:57.186+0000] {spark_submit.py:579} INFO - 24/12/15 16:57:57 INFO TaskSetManager: Starting task 7.0 in stage 2.0 (TID 12) (172.18.0.9, executor 0, partition 7, PROCESS_LOCAL, 4446 bytes) taskResourceAssignments Map()
[2024-12-15T16:57:57.188+0000] {spark_submit.py:579} INFO - 24/12/15 16:57:57 INFO TaskSetManager: Starting task 8.0 in stage 2.0 (TID 13) (172.18.0.9, executor 0, partition 8, PROCESS_LOCAL, 4446 bytes) taskResourceAssignments Map()
[2024-12-15T16:57:57.189+0000] {spark_submit.py:579} INFO - 24/12/15 16:57:57 INFO TaskSetManager: Finished task 6.0 in stage 2.0 (TID 11) in 97 ms on 172.18.0.9 (executor 0) (9/50)
[2024-12-15T16:57:57.190+0000] {spark_submit.py:579} INFO - 24/12/15 16:57:57 INFO TaskSetManager: Finished task 5.0 in stage 2.0 (TID 10) in 101 ms on 172.18.0.9 (executor 0) (10/50)
[2024-12-15T16:57:57.253+0000] {spark_submit.py:579} INFO - 24/12/15 16:57:57 INFO BlockManagerInfo: Added rdd_10_7 in memory on 172.18.0.9:33561 (size: 46.0 B, free: 1048.7 MiB)
[2024-12-15T16:57:57.257+0000] {spark_submit.py:579} INFO - 24/12/15 16:57:57 INFO BlockManagerInfo: Added rdd_10_8 in memory on 172.18.0.9:33561 (size: 46.0 B, free: 1048.7 MiB)
[2024-12-15T16:57:57.284+0000] {spark_submit.py:579} INFO - 24/12/15 16:57:57 INFO TaskSetManager: Starting task 9.0 in stage 2.0 (TID 14) (172.18.0.9, executor 0, partition 9, PROCESS_LOCAL, 4446 bytes) taskResourceAssignments Map()
[2024-12-15T16:57:57.285+0000] {spark_submit.py:579} INFO - 24/12/15 16:57:57 INFO TaskSetManager: Finished task 7.0 in stage 2.0 (TID 12) in 99 ms on 172.18.0.9 (executor 0) (11/50)
[2024-12-15T16:57:57.291+0000] {spark_submit.py:579} INFO - 24/12/15 16:57:57 INFO TaskSetManager: Starting task 10.0 in stage 2.0 (TID 15) (172.18.0.9, executor 0, partition 10, PROCESS_LOCAL, 4446 bytes) taskResourceAssignments Map()
[2024-12-15T16:57:57.293+0000] {spark_submit.py:579} INFO - 24/12/15 16:57:57 INFO TaskSetManager: Finished task 8.0 in stage 2.0 (TID 13) in 104 ms on 172.18.0.9 (executor 0) (12/50)
[2024-12-15T16:57:57.343+0000] {spark_submit.py:579} INFO - 24/12/15 16:57:57 INFO BlockManagerInfo: Added rdd_10_9 in memory on 172.18.0.9:33561 (size: 46.0 B, free: 1048.7 MiB)
[2024-12-15T16:57:57.348+0000] {spark_submit.py:579} INFO - 24/12/15 16:57:57 INFO BlockManagerInfo: Added rdd_10_10 in memory on 172.18.0.9:33561 (size: 46.0 B, free: 1048.7 MiB)
[2024-12-15T16:57:57.368+0000] {spark_submit.py:579} INFO - 24/12/15 16:57:57 INFO TaskSetManager: Starting task 11.0 in stage 2.0 (TID 16) (172.18.0.9, executor 0, partition 11, PROCESS_LOCAL, 4446 bytes) taskResourceAssignments Map()
[2024-12-15T16:57:57.369+0000] {spark_submit.py:579} INFO - 24/12/15 16:57:57 INFO TaskSetManager: Finished task 9.0 in stage 2.0 (TID 14) in 85 ms on 172.18.0.9 (executor 0) (13/50)
[2024-12-15T16:57:57.379+0000] {spark_submit.py:579} INFO - 24/12/15 16:57:57 INFO TaskSetManager: Starting task 12.0 in stage 2.0 (TID 17) (172.18.0.9, executor 0, partition 12, PROCESS_LOCAL, 4446 bytes) taskResourceAssignments Map()
[2024-12-15T16:57:57.380+0000] {spark_submit.py:579} INFO - 24/12/15 16:57:57 INFO TaskSetManager: Finished task 10.0 in stage 2.0 (TID 15) in 88 ms on 172.18.0.9 (executor 0) (14/50)
[2024-12-15T16:57:57.429+0000] {spark_submit.py:579} INFO - 24/12/15 16:57:57 INFO BlockManagerInfo: Added rdd_10_11 in memory on 172.18.0.9:33561 (size: 46.0 B, free: 1048.7 MiB)
[2024-12-15T16:57:57.443+0000] {spark_submit.py:579} INFO - 24/12/15 16:57:57 INFO BlockManagerInfo: Added rdd_10_12 in memory on 172.18.0.9:33561 (size: 46.0 B, free: 1048.7 MiB)
[2024-12-15T16:57:57.454+0000] {spark_submit.py:579} INFO - 24/12/15 16:57:57 INFO TaskSetManager: Starting task 13.0 in stage 2.0 (TID 18) (172.18.0.9, executor 0, partition 13, PROCESS_LOCAL, 4446 bytes) taskResourceAssignments Map()
[2024-12-15T16:57:57.455+0000] {spark_submit.py:579} INFO - 24/12/15 16:57:57 INFO TaskSetManager: Finished task 11.0 in stage 2.0 (TID 16) in 88 ms on 172.18.0.9 (executor 0) (15/50)
[2024-12-15T16:57:57.468+0000] {spark_submit.py:579} INFO - 24/12/15 16:57:57 INFO TaskSetManager: Starting task 14.0 in stage 2.0 (TID 19) (172.18.0.9, executor 0, partition 14, PROCESS_LOCAL, 4446 bytes) taskResourceAssignments Map()
[2024-12-15T16:57:57.469+0000] {spark_submit.py:579} INFO - 24/12/15 16:57:57 INFO TaskSetManager: Finished task 12.0 in stage 2.0 (TID 17) in 91 ms on 172.18.0.9 (executor 0) (16/50)
[2024-12-15T16:57:57.495+0000] {spark_submit.py:579} INFO - 24/12/15 16:57:57 INFO BlockManagerInfo: Added rdd_10_13 in memory on 172.18.0.9:33561 (size: 46.0 B, free: 1048.7 MiB)
[2024-12-15T16:57:57.510+0000] {spark_submit.py:579} INFO - 24/12/15 16:57:57 INFO BlockManagerInfo: Added rdd_10_14 in memory on 172.18.0.9:33561 (size: 46.0 B, free: 1048.7 MiB)
[2024-12-15T16:57:57.529+0000] {spark_submit.py:579} INFO - 24/12/15 16:57:57 INFO TaskSetManager: Starting task 15.0 in stage 2.0 (TID 20) (172.18.0.9, executor 0, partition 15, PROCESS_LOCAL, 4446 bytes) taskResourceAssignments Map()
[2024-12-15T16:57:57.531+0000] {spark_submit.py:579} INFO - 24/12/15 16:57:57 INFO TaskSetManager: Finished task 13.0 in stage 2.0 (TID 18) in 77 ms on 172.18.0.9 (executor 0) (17/50)
[2024-12-15T16:57:57.554+0000] {spark_submit.py:579} INFO - 24/12/15 16:57:57 INFO TaskSetManager: Starting task 16.0 in stage 2.0 (TID 21) (172.18.0.9, executor 0, partition 16, PROCESS_LOCAL, 4446 bytes) taskResourceAssignments Map()
[2024-12-15T16:57:57.558+0000] {spark_submit.py:579} INFO - 24/12/15 16:57:57 INFO TaskSetManager: Finished task 14.0 in stage 2.0 (TID 19) in 87 ms on 172.18.0.9 (executor 0) (18/50)
[2024-12-15T16:57:57.631+0000] {spark_submit.py:579} INFO - 24/12/15 16:57:57 INFO BlockManagerInfo: Added rdd_10_15 in memory on 172.18.0.9:33561 (size: 46.0 B, free: 1048.7 MiB)
[2024-12-15T16:57:57.642+0000] {spark_submit.py:579} INFO - 24/12/15 16:57:57 INFO BlockManagerInfo: Added rdd_10_16 in memory on 172.18.0.9:33561 (size: 46.0 B, free: 1048.7 MiB)
[2024-12-15T16:57:57.666+0000] {spark_submit.py:579} INFO - 24/12/15 16:57:57 INFO TaskSetManager: Starting task 17.0 in stage 2.0 (TID 22) (172.18.0.9, executor 0, partition 17, PROCESS_LOCAL, 4446 bytes) taskResourceAssignments Map()
[2024-12-15T16:57:57.667+0000] {spark_submit.py:579} INFO - 24/12/15 16:57:57 INFO TaskSetManager: Finished task 15.0 in stage 2.0 (TID 20) in 138 ms on 172.18.0.9 (executor 0) (19/50)
[2024-12-15T16:57:57.675+0000] {spark_submit.py:579} INFO - 24/12/15 16:57:57 INFO TaskSetManager: Starting task 18.0 in stage 2.0 (TID 23) (172.18.0.9, executor 0, partition 18, PROCESS_LOCAL, 4446 bytes) taskResourceAssignments Map()
[2024-12-15T16:57:57.675+0000] {spark_submit.py:579} INFO - 24/12/15 16:57:57 INFO TaskSetManager: Finished task 16.0 in stage 2.0 (TID 21) in 122 ms on 172.18.0.9 (executor 0) (20/50)
[2024-12-15T16:57:57.730+0000] {spark_submit.py:579} INFO - 24/12/15 16:57:57 INFO BlockManagerInfo: Added rdd_10_17 in memory on 172.18.0.9:33561 (size: 46.0 B, free: 1048.7 MiB)
[2024-12-15T16:57:57.734+0000] {spark_submit.py:579} INFO - 24/12/15 16:57:57 INFO BlockManagerInfo: Added rdd_10_18 in memory on 172.18.0.9:33561 (size: 46.0 B, free: 1048.7 MiB)
[2024-12-15T16:57:57.754+0000] {spark_submit.py:579} INFO - 24/12/15 16:57:57 INFO TaskSetManager: Starting task 19.0 in stage 2.0 (TID 24) (172.18.0.9, executor 0, partition 19, PROCESS_LOCAL, 4446 bytes) taskResourceAssignments Map()
[2024-12-15T16:57:57.755+0000] {spark_submit.py:579} INFO - 24/12/15 16:57:57 INFO TaskSetManager: Finished task 17.0 in stage 2.0 (TID 22) in 89 ms on 172.18.0.9 (executor 0) (21/50)
[2024-12-15T16:57:57.756+0000] {spark_submit.py:579} INFO - 24/12/15 16:57:57 INFO TaskSetManager: Starting task 20.0 in stage 2.0 (TID 25) (172.18.0.9, executor 0, partition 20, PROCESS_LOCAL, 4446 bytes) taskResourceAssignments Map()
[2024-12-15T16:57:57.757+0000] {spark_submit.py:579} INFO - 24/12/15 16:57:57 INFO TaskSetManager: Finished task 18.0 in stage 2.0 (TID 23) in 82 ms on 172.18.0.9 (executor 0) (22/50)
[2024-12-15T16:57:57.796+0000] {spark_submit.py:579} INFO - 24/12/15 16:57:57 INFO BlockManagerInfo: Added rdd_10_19 in memory on 172.18.0.9:33561 (size: 46.0 B, free: 1048.7 MiB)
[2024-12-15T16:57:57.798+0000] {spark_submit.py:579} INFO - 24/12/15 16:57:57 INFO BlockManagerInfo: Added rdd_10_20 in memory on 172.18.0.9:33561 (size: 46.0 B, free: 1048.7 MiB)
[2024-12-15T16:57:57.823+0000] {spark_submit.py:579} INFO - 24/12/15 16:57:57 INFO TaskSetManager: Starting task 21.0 in stage 2.0 (TID 26) (172.18.0.9, executor 0, partition 21, PROCESS_LOCAL, 4446 bytes) taskResourceAssignments Map()
[2024-12-15T16:57:57.824+0000] {spark_submit.py:579} INFO - 24/12/15 16:57:57 INFO TaskSetManager: Starting task 23.0 in stage 2.0 (TID 27) (172.18.0.9, executor 0, partition 23, PROCESS_LOCAL, 4446 bytes) taskResourceAssignments Map()
[2024-12-15T16:57:57.827+0000] {spark_submit.py:579} INFO - 24/12/15 16:57:57 INFO TaskSetManager: Finished task 19.0 in stage 2.0 (TID 24) in 72 ms on 172.18.0.9 (executor 0) (23/50)
[2024-12-15T16:57:57.829+0000] {spark_submit.py:579} INFO - 24/12/15 16:57:57 INFO TaskSetManager: Finished task 20.0 in stage 2.0 (TID 25) in 70 ms on 172.18.0.9 (executor 0) (24/50)
[2024-12-15T16:57:57.867+0000] {spark_submit.py:579} INFO - 24/12/15 16:57:57 INFO BlockManagerInfo: Added rdd_10_23 in memory on 172.18.0.9:33561 (size: 46.0 B, free: 1048.7 MiB)
[2024-12-15T16:57:57.870+0000] {spark_submit.py:579} INFO - 24/12/15 16:57:57 INFO BlockManagerInfo: Added rdd_10_21 in memory on 172.18.0.9:33561 (size: 46.0 B, free: 1048.7 MiB)
[2024-12-15T16:57:57.888+0000] {spark_submit.py:579} INFO - 24/12/15 16:57:57 INFO TaskSetManager: Starting task 24.0 in stage 2.0 (TID 28) (172.18.0.9, executor 0, partition 24, PROCESS_LOCAL, 4446 bytes) taskResourceAssignments Map()
[2024-12-15T16:57:57.889+0000] {spark_submit.py:579} INFO - 24/12/15 16:57:57 INFO TaskSetManager: Finished task 23.0 in stage 2.0 (TID 27) in 64 ms on 172.18.0.9 (executor 0) (25/50)
[2024-12-15T16:57:57.890+0000] {spark_submit.py:579} INFO - 24/12/15 16:57:57 INFO TaskSetManager: Starting task 25.0 in stage 2.0 (TID 29) (172.18.0.9, executor 0, partition 25, PROCESS_LOCAL, 4446 bytes) taskResourceAssignments Map()
[2024-12-15T16:57:57.890+0000] {spark_submit.py:579} INFO - 24/12/15 16:57:57 INFO TaskSetManager: Finished task 21.0 in stage 2.0 (TID 26) in 68 ms on 172.18.0.9 (executor 0) (26/50)
[2024-12-15T16:57:57.942+0000] {spark_submit.py:579} INFO - 24/12/15 16:57:57 INFO BlockManagerInfo: Added rdd_10_25 in memory on 172.18.0.9:33561 (size: 46.0 B, free: 1048.7 MiB)
[2024-12-15T16:57:57.946+0000] {spark_submit.py:579} INFO - 24/12/15 16:57:57 INFO BlockManagerInfo: Added rdd_10_24 in memory on 172.18.0.9:33561 (size: 46.0 B, free: 1048.7 MiB)
[2024-12-15T16:57:57.964+0000] {spark_submit.py:579} INFO - 24/12/15 16:57:57 INFO TaskSetManager: Starting task 26.0 in stage 2.0 (TID 30) (172.18.0.9, executor 0, partition 26, PROCESS_LOCAL, 4446 bytes) taskResourceAssignments Map()
[2024-12-15T16:57:57.965+0000] {spark_submit.py:579} INFO - 24/12/15 16:57:57 INFO TaskSetManager: Finished task 25.0 in stage 2.0 (TID 29) in 76 ms on 172.18.0.9 (executor 0) (27/50)
[2024-12-15T16:57:57.970+0000] {spark_submit.py:579} INFO - 24/12/15 16:57:57 INFO TaskSetManager: Starting task 27.0 in stage 2.0 (TID 31) (172.18.0.9, executor 0, partition 27, PROCESS_LOCAL, 4446 bytes) taskResourceAssignments Map()
[2024-12-15T16:57:57.972+0000] {spark_submit.py:579} INFO - 24/12/15 16:57:57 INFO TaskSetManager: Finished task 24.0 in stage 2.0 (TID 28) in 84 ms on 172.18.0.9 (executor 0) (28/50)
[2024-12-15T16:57:58.001+0000] {spark_submit.py:579} INFO - 24/12/15 16:57:58 INFO BlockManagerInfo: Added rdd_10_26 in memory on 172.18.0.9:33561 (size: 46.0 B, free: 1048.7 MiB)
[2024-12-15T16:57:58.014+0000] {spark_submit.py:579} INFO - 24/12/15 16:57:58 INFO BlockManagerInfo: Added rdd_10_27 in memory on 172.18.0.9:33561 (size: 46.0 B, free: 1048.7 MiB)
[2024-12-15T16:57:58.028+0000] {spark_submit.py:579} INFO - 24/12/15 16:57:58 INFO TaskSetManager: Starting task 28.0 in stage 2.0 (TID 32) (172.18.0.9, executor 0, partition 28, PROCESS_LOCAL, 4446 bytes) taskResourceAssignments Map()
[2024-12-15T16:57:58.029+0000] {spark_submit.py:579} INFO - 24/12/15 16:57:58 INFO TaskSetManager: Finished task 26.0 in stage 2.0 (TID 30) in 65 ms on 172.18.0.9 (executor 0) (29/50)
[2024-12-15T16:57:58.039+0000] {spark_submit.py:579} INFO - 24/12/15 16:57:58 INFO TaskSetManager: Starting task 29.0 in stage 2.0 (TID 33) (172.18.0.9, executor 0, partition 29, PROCESS_LOCAL, 4446 bytes) taskResourceAssignments Map()
[2024-12-15T16:57:58.040+0000] {spark_submit.py:579} INFO - 24/12/15 16:57:58 INFO TaskSetManager: Finished task 27.0 in stage 2.0 (TID 31) in 70 ms on 172.18.0.9 (executor 0) (30/50)
[2024-12-15T16:57:58.077+0000] {spark_submit.py:579} INFO - 24/12/15 16:57:58 INFO BlockManagerInfo: Added rdd_10_28 in memory on 172.18.0.9:33561 (size: 46.0 B, free: 1048.7 MiB)
[2024-12-15T16:57:58.087+0000] {spark_submit.py:579} INFO - 24/12/15 16:57:58 INFO BlockManagerInfo: Added rdd_10_29 in memory on 172.18.0.9:33561 (size: 46.0 B, free: 1048.7 MiB)
[2024-12-15T16:57:58.101+0000] {spark_submit.py:579} INFO - 24/12/15 16:57:58 INFO TaskSetManager: Starting task 30.0 in stage 2.0 (TID 34) (172.18.0.9, executor 0, partition 30, PROCESS_LOCAL, 4446 bytes) taskResourceAssignments Map()
[2024-12-15T16:57:58.102+0000] {spark_submit.py:579} INFO - 24/12/15 16:57:58 INFO TaskSetManager: Finished task 28.0 in stage 2.0 (TID 32) in 75 ms on 172.18.0.9 (executor 0) (31/50)
[2024-12-15T16:57:58.109+0000] {spark_submit.py:579} INFO - 24/12/15 16:57:58 INFO TaskSetManager: Finished task 29.0 in stage 2.0 (TID 33) in 70 ms on 172.18.0.9 (executor 0) (32/50)
[2024-12-15T16:57:58.117+0000] {spark_submit.py:579} INFO - 24/12/15 16:57:58 INFO TaskSetManager: Starting task 31.0 in stage 2.0 (TID 35) (172.18.0.9, executor 0, partition 31, PROCESS_LOCAL, 4446 bytes) taskResourceAssignments Map()
[2024-12-15T16:57:58.145+0000] {spark_submit.py:579} INFO - 24/12/15 16:57:58 INFO BlockManagerInfo: Added rdd_10_30 in memory on 172.18.0.9:33561 (size: 46.0 B, free: 1048.7 MiB)
[2024-12-15T16:57:58.150+0000] {spark_submit.py:579} INFO - 24/12/15 16:57:58 INFO BlockManagerInfo: Added rdd_10_31 in memory on 172.18.0.9:33561 (size: 46.0 B, free: 1048.7 MiB)
[2024-12-15T16:57:58.176+0000] {spark_submit.py:579} INFO - 24/12/15 16:57:58 INFO TaskSetManager: Starting task 32.0 in stage 2.0 (TID 36) (172.18.0.9, executor 0, partition 32, PROCESS_LOCAL, 4446 bytes) taskResourceAssignments Map()
[2024-12-15T16:57:58.177+0000] {spark_submit.py:579} INFO - 24/12/15 16:57:58 INFO TaskSetManager: Finished task 30.0 in stage 2.0 (TID 34) in 76 ms on 172.18.0.9 (executor 0) (33/50)
[2024-12-15T16:57:58.183+0000] {spark_submit.py:579} INFO - 24/12/15 16:57:58 INFO TaskSetManager: Starting task 33.0 in stage 2.0 (TID 37) (172.18.0.9, executor 0, partition 33, PROCESS_LOCAL, 4446 bytes) taskResourceAssignments Map()
[2024-12-15T16:57:58.184+0000] {spark_submit.py:579} INFO - 24/12/15 16:57:58 INFO TaskSetManager: Finished task 31.0 in stage 2.0 (TID 35) in 75 ms on 172.18.0.9 (executor 0) (34/50)
[2024-12-15T16:57:58.217+0000] {spark_submit.py:579} INFO - 24/12/15 16:57:58 INFO BlockManagerInfo: Added rdd_10_32 in memory on 172.18.0.9:33561 (size: 46.0 B, free: 1048.7 MiB)
[2024-12-15T16:57:58.222+0000] {spark_submit.py:579} INFO - 24/12/15 16:57:58 INFO BlockManagerInfo: Added rdd_10_33 in memory on 172.18.0.9:33561 (size: 46.0 B, free: 1048.7 MiB)
[2024-12-15T16:57:58.237+0000] {spark_submit.py:579} INFO - 24/12/15 16:57:58 INFO TaskSetManager: Starting task 34.0 in stage 2.0 (TID 38) (172.18.0.9, executor 0, partition 34, PROCESS_LOCAL, 4446 bytes) taskResourceAssignments Map()
[2024-12-15T16:57:58.238+0000] {spark_submit.py:579} INFO - 24/12/15 16:57:58 INFO TaskSetManager: Finished task 32.0 in stage 2.0 (TID 36) in 62 ms on 172.18.0.9 (executor 0) (35/50)
[2024-12-15T16:57:58.243+0000] {spark_submit.py:579} INFO - 24/12/15 16:57:58 INFO TaskSetManager: Starting task 35.0 in stage 2.0 (TID 39) (172.18.0.9, executor 0, partition 35, PROCESS_LOCAL, 4446 bytes) taskResourceAssignments Map()
[2024-12-15T16:57:58.244+0000] {spark_submit.py:579} INFO - 24/12/15 16:57:58 INFO TaskSetManager: Finished task 33.0 in stage 2.0 (TID 37) in 61 ms on 172.18.0.9 (executor 0) (36/50)
[2024-12-15T16:57:58.272+0000] {spark_submit.py:579} INFO - 24/12/15 16:57:58 INFO BlockManagerInfo: Added rdd_10_34 in memory on 172.18.0.9:33561 (size: 46.0 B, free: 1048.7 MiB)
[2024-12-15T16:57:58.281+0000] {spark_submit.py:579} INFO - 24/12/15 16:57:58 INFO BlockManagerInfo: Added rdd_10_35 in memory on 172.18.0.9:33561 (size: 46.0 B, free: 1048.7 MiB)
[2024-12-15T16:57:58.300+0000] {spark_submit.py:579} INFO - 24/12/15 16:57:58 INFO TaskSetManager: Starting task 36.0 in stage 2.0 (TID 40) (172.18.0.9, executor 0, partition 36, PROCESS_LOCAL, 4446 bytes) taskResourceAssignments Map()
[2024-12-15T16:57:58.302+0000] {spark_submit.py:579} INFO - 24/12/15 16:57:58 INFO TaskSetManager: Finished task 34.0 in stage 2.0 (TID 38) in 65 ms on 172.18.0.9 (executor 0) (37/50)
[2024-12-15T16:57:58.309+0000] {spark_submit.py:579} INFO - 24/12/15 16:57:58 INFO TaskSetManager: Starting task 37.0 in stage 2.0 (TID 41) (172.18.0.9, executor 0, partition 37, PROCESS_LOCAL, 4446 bytes) taskResourceAssignments Map()
[2024-12-15T16:57:58.310+0000] {spark_submit.py:579} INFO - 24/12/15 16:57:58 INFO TaskSetManager: Finished task 35.0 in stage 2.0 (TID 39) in 68 ms on 172.18.0.9 (executor 0) (38/50)
[2024-12-15T16:57:58.338+0000] {spark_submit.py:579} INFO - 24/12/15 16:57:58 INFO BlockManagerInfo: Added rdd_10_36 in memory on 172.18.0.9:33561 (size: 46.0 B, free: 1048.7 MiB)
[2024-12-15T16:57:58.346+0000] {spark_submit.py:579} INFO - 24/12/15 16:57:58 INFO BlockManagerInfo: Added rdd_10_37 in memory on 172.18.0.9:33561 (size: 46.0 B, free: 1048.7 MiB)
[2024-12-15T16:57:58.357+0000] {spark_submit.py:579} INFO - 24/12/15 16:57:58 INFO TaskSetManager: Starting task 38.0 in stage 2.0 (TID 42) (172.18.0.9, executor 0, partition 38, PROCESS_LOCAL, 4446 bytes) taskResourceAssignments Map()
[2024-12-15T16:57:58.358+0000] {spark_submit.py:579} INFO - 24/12/15 16:57:58 INFO TaskSetManager: Finished task 36.0 in stage 2.0 (TID 40) in 57 ms on 172.18.0.9 (executor 0) (39/50)
[2024-12-15T16:57:58.367+0000] {spark_submit.py:579} INFO - 24/12/15 16:57:58 INFO TaskSetManager: Starting task 39.0 in stage 2.0 (TID 43) (172.18.0.9, executor 0, partition 39, PROCESS_LOCAL, 4446 bytes) taskResourceAssignments Map()
[2024-12-15T16:57:58.368+0000] {spark_submit.py:579} INFO - 24/12/15 16:57:58 INFO TaskSetManager: Finished task 37.0 in stage 2.0 (TID 41) in 58 ms on 172.18.0.9 (executor 0) (40/50)
[2024-12-15T16:57:58.391+0000] {spark_submit.py:579} INFO - 24/12/15 16:57:58 INFO BlockManagerInfo: Added rdd_10_38 in memory on 172.18.0.9:33561 (size: 46.0 B, free: 1048.7 MiB)
[2024-12-15T16:57:58.400+0000] {spark_submit.py:579} INFO - 24/12/15 16:57:58 INFO BlockManagerInfo: Added rdd_10_39 in memory on 172.18.0.9:33561 (size: 46.0 B, free: 1048.7 MiB)
[2024-12-15T16:57:58.410+0000] {spark_submit.py:579} INFO - 24/12/15 16:57:58 INFO TaskSetManager: Starting task 40.0 in stage 2.0 (TID 44) (172.18.0.9, executor 0, partition 40, PROCESS_LOCAL, 4446 bytes) taskResourceAssignments Map()
[2024-12-15T16:57:58.411+0000] {spark_submit.py:579} INFO - 24/12/15 16:57:58 INFO TaskSetManager: Finished task 38.0 in stage 2.0 (TID 42) in 55 ms on 172.18.0.9 (executor 0) (41/50)
[2024-12-15T16:57:58.422+0000] {spark_submit.py:579} INFO - 24/12/15 16:57:58 INFO TaskSetManager: Starting task 41.0 in stage 2.0 (TID 45) (172.18.0.9, executor 0, partition 41, PROCESS_LOCAL, 4446 bytes) taskResourceAssignments Map()
[2024-12-15T16:57:58.424+0000] {spark_submit.py:579} INFO - 24/12/15 16:57:58 INFO TaskSetManager: Finished task 39.0 in stage 2.0 (TID 43) in 56 ms on 172.18.0.9 (executor 0) (42/50)
[2024-12-15T16:57:58.456+0000] {spark_submit.py:579} INFO - 24/12/15 16:57:58 INFO BlockManagerInfo: Added rdd_10_40 in memory on 172.18.0.9:33561 (size: 46.0 B, free: 1048.7 MiB)
[2024-12-15T16:57:58.467+0000] {spark_submit.py:579} INFO - 24/12/15 16:57:58 INFO BlockManagerInfo: Added rdd_10_41 in memory on 172.18.0.9:33561 (size: 46.0 B, free: 1048.7 MiB)
[2024-12-15T16:57:58.480+0000] {spark_submit.py:579} INFO - 24/12/15 16:57:58 INFO TaskSetManager: Starting task 43.0 in stage 2.0 (TID 46) (172.18.0.9, executor 0, partition 43, PROCESS_LOCAL, 4446 bytes) taskResourceAssignments Map()
[2024-12-15T16:57:58.481+0000] {spark_submit.py:579} INFO - 24/12/15 16:57:58 INFO TaskSetManager: Finished task 40.0 in stage 2.0 (TID 44) in 70 ms on 172.18.0.9 (executor 0) (43/50)
[2024-12-15T16:57:58.493+0000] {spark_submit.py:579} INFO - 24/12/15 16:57:58 INFO TaskSetManager: Starting task 45.0 in stage 2.0 (TID 47) (172.18.0.9, executor 0, partition 45, PROCESS_LOCAL, 4446 bytes) taskResourceAssignments Map()
[2024-12-15T16:57:58.494+0000] {spark_submit.py:579} INFO - 24/12/15 16:57:58 INFO TaskSetManager: Finished task 41.0 in stage 2.0 (TID 45) in 71 ms on 172.18.0.9 (executor 0) (44/50)
[2024-12-15T16:57:58.519+0000] {spark_submit.py:579} INFO - 24/12/15 16:57:58 INFO BlockManagerInfo: Added rdd_10_43 in memory on 172.18.0.9:33561 (size: 46.0 B, free: 1048.7 MiB)
[2024-12-15T16:57:58.538+0000] {spark_submit.py:579} INFO - 24/12/15 16:57:58 INFO BlockManagerInfo: Added rdd_10_45 in memory on 172.18.0.9:33561 (size: 46.0 B, free: 1048.7 MiB)
[2024-12-15T16:57:58.544+0000] {spark_submit.py:579} INFO - 24/12/15 16:57:58 INFO TaskSetManager: Starting task 46.0 in stage 2.0 (TID 48) (172.18.0.9, executor 0, partition 46, PROCESS_LOCAL, 4446 bytes) taskResourceAssignments Map()
[2024-12-15T16:57:58.545+0000] {spark_submit.py:579} INFO - 24/12/15 16:57:58 INFO TaskSetManager: Finished task 43.0 in stage 2.0 (TID 46) in 66 ms on 172.18.0.9 (executor 0) (45/50)
[2024-12-15T16:57:58.558+0000] {spark_submit.py:579} INFO - 24/12/15 16:57:58 INFO TaskSetManager: Starting task 47.0 in stage 2.0 (TID 49) (172.18.0.9, executor 0, partition 47, PROCESS_LOCAL, 4446 bytes) taskResourceAssignments Map()
[2024-12-15T16:57:58.559+0000] {spark_submit.py:579} INFO - 24/12/15 16:57:58 INFO TaskSetManager: Finished task 45.0 in stage 2.0 (TID 47) in 67 ms on 172.18.0.9 (executor 0) (46/50)
[2024-12-15T16:57:58.584+0000] {spark_submit.py:579} INFO - 24/12/15 16:57:58 INFO BlockManagerInfo: Added rdd_10_46 in memory on 172.18.0.9:33561 (size: 46.0 B, free: 1048.7 MiB)
[2024-12-15T16:57:58.591+0000] {spark_submit.py:579} INFO - 24/12/15 16:57:58 INFO BlockManagerInfo: Added rdd_10_47 in memory on 172.18.0.9:33561 (size: 46.0 B, free: 1048.7 MiB)
[2024-12-15T16:57:58.601+0000] {spark_submit.py:579} INFO - 24/12/15 16:57:58 INFO TaskSetManager: Starting task 48.0 in stage 2.0 (TID 50) (172.18.0.9, executor 0, partition 48, PROCESS_LOCAL, 4446 bytes) taskResourceAssignments Map()
[2024-12-15T16:57:58.602+0000] {spark_submit.py:579} INFO - 24/12/15 16:57:58 INFO TaskSetManager: Finished task 46.0 in stage 2.0 (TID 48) in 57 ms on 172.18.0.9 (executor 0) (47/50)
[2024-12-15T16:57:58.610+0000] {spark_submit.py:579} INFO - 24/12/15 16:57:58 INFO TaskSetManager: Starting task 49.0 in stage 2.0 (TID 51) (172.18.0.9, executor 0, partition 49, PROCESS_LOCAL, 4446 bytes) taskResourceAssignments Map()
[2024-12-15T16:57:58.611+0000] {spark_submit.py:579} INFO - 24/12/15 16:57:58 INFO TaskSetManager: Finished task 47.0 in stage 2.0 (TID 49) in 53 ms on 172.18.0.9 (executor 0) (48/50)
[2024-12-15T16:57:58.635+0000] {spark_submit.py:579} INFO - 24/12/15 16:57:58 INFO BlockManagerInfo: Added rdd_10_48 in memory on 172.18.0.9:33561 (size: 46.0 B, free: 1048.7 MiB)
[2024-12-15T16:57:58.641+0000] {spark_submit.py:579} INFO - 24/12/15 16:57:58 INFO BlockManagerInfo: Added rdd_10_49 in memory on 172.18.0.9:33561 (size: 46.0 B, free: 1048.7 MiB)
[2024-12-15T16:57:58.655+0000] {spark_submit.py:579} INFO - 24/12/15 16:57:58 INFO TaskSetManager: Finished task 48.0 in stage 2.0 (TID 50) in 54 ms on 172.18.0.9 (executor 0) (49/50)
[2024-12-15T16:57:58.661+0000] {spark_submit.py:579} INFO - 24/12/15 16:57:58 INFO TaskSetManager: Finished task 49.0 in stage 2.0 (TID 51) in 51 ms on 172.18.0.9 (executor 0) (50/50)
[2024-12-15T16:57:58.661+0000] {spark_submit.py:579} INFO - 24/12/15 16:57:58 INFO TaskSchedulerImpl: Removed TaskSet 2.0, whose tasks have all completed, from pool
[2024-12-15T16:57:58.662+0000] {spark_submit.py:579} INFO - 24/12/15 16:57:58 INFO DAGScheduler: ShuffleMapStage 2 (toString at String.java:2951) finished in 3.355 s
[2024-12-15T16:57:58.662+0000] {spark_submit.py:579} INFO - 24/12/15 16:57:58 INFO DAGScheduler: looking for newly runnable stages
[2024-12-15T16:57:58.663+0000] {spark_submit.py:579} INFO - 24/12/15 16:57:58 INFO DAGScheduler: running: Set()
[2024-12-15T16:57:58.663+0000] {spark_submit.py:579} INFO - 24/12/15 16:57:58 INFO DAGScheduler: waiting: Set()
[2024-12-15T16:57:58.663+0000] {spark_submit.py:579} INFO - 24/12/15 16:57:58 INFO DAGScheduler: failed: Set()
[2024-12-15T16:57:58.696+0000] {spark_submit.py:579} INFO - 24/12/15 16:57:58 INFO BlockManagerInfo: Removed broadcast_3_piece0 on a2b73f6a4b3a:45891 in memory (size: 102.5 KiB, free: 434.3 MiB)
[2024-12-15T16:57:58.704+0000] {spark_submit.py:579} INFO - 24/12/15 16:57:58 INFO BlockManagerInfo: Removed broadcast_3_piece0 on 172.18.0.9:33561 in memory (size: 102.5 KiB, free: 1048.8 MiB)
[2024-12-15T16:57:58.712+0000] {spark_submit.py:579} INFO - 24/12/15 16:57:58 INFO SparkContext: Starting job: toString at String.java:2951
[2024-12-15T16:57:58.716+0000] {spark_submit.py:579} INFO - 24/12/15 16:57:58 INFO DAGScheduler: Got job 2 (toString at String.java:2951) with 1 output partitions
[2024-12-15T16:57:58.717+0000] {spark_submit.py:579} INFO - 24/12/15 16:57:58 INFO DAGScheduler: Final stage: ResultStage 5 (toString at String.java:2951)
[2024-12-15T16:57:58.717+0000] {spark_submit.py:579} INFO - 24/12/15 16:57:58 INFO DAGScheduler: Parents of final stage: List(ShuffleMapStage 4)
[2024-12-15T16:57:58.719+0000] {spark_submit.py:579} INFO - 24/12/15 16:57:58 INFO DAGScheduler: Missing parents: List()
[2024-12-15T16:57:58.721+0000] {spark_submit.py:579} INFO - 24/12/15 16:57:58 INFO DAGScheduler: Submitting ResultStage 5 (MapPartitionsRDD[16] at toString at String.java:2951), which has no missing parents
[2024-12-15T16:57:58.728+0000] {spark_submit.py:579} INFO - 24/12/15 16:57:58 INFO MemoryStore: Block broadcast_4 stored as values in memory (estimated size 372.3 KiB, free 433.6 MiB)
[2024-12-15T16:57:58.730+0000] {spark_submit.py:579} INFO - 24/12/15 16:57:58 INFO MemoryStore: Block broadcast_4_piece0 stored as bytes in memory (estimated size 91.6 KiB, free 433.5 MiB)
[2024-12-15T16:57:58.732+0000] {spark_submit.py:579} INFO - 24/12/15 16:57:58 INFO BlockManagerInfo: Added broadcast_4_piece0 in memory on a2b73f6a4b3a:45891 (size: 91.6 KiB, free: 434.2 MiB)
[2024-12-15T16:57:58.733+0000] {spark_submit.py:579} INFO - 24/12/15 16:57:58 INFO SparkContext: Created broadcast 4 from broadcast at DAGScheduler.scala:1513
[2024-12-15T16:57:58.735+0000] {spark_submit.py:579} INFO - 24/12/15 16:57:58 INFO DAGScheduler: Submitting 1 missing tasks from ResultStage 5 (MapPartitionsRDD[16] at toString at String.java:2951) (first 15 tasks are for partitions Vector(0))
[2024-12-15T16:57:58.736+0000] {spark_submit.py:579} INFO - 24/12/15 16:57:58 INFO TaskSchedulerImpl: Adding task set 5.0 with 1 tasks resource profile 0
[2024-12-15T16:57:58.738+0000] {spark_submit.py:579} INFO - 24/12/15 16:57:58 INFO TaskSetManager: Starting task 0.0 in stage 5.0 (TID 52) (172.18.0.9, executor 0, partition 0, NODE_LOCAL, 4457 bytes) taskResourceAssignments Map()
[2024-12-15T16:57:58.784+0000] {spark_submit.py:579} INFO - 24/12/15 16:57:58 INFO BlockManagerInfo: Added broadcast_4_piece0 in memory on 172.18.0.9:33561 (size: 91.6 KiB, free: 1048.7 MiB)
[2024-12-15T16:57:58.837+0000] {spark_submit.py:579} INFO - 24/12/15 16:57:58 INFO MapOutputTrackerMasterEndpoint: Asked to send map output locations for shuffle 1 to 172.18.0.9:36176
[2024-12-15T16:57:58.926+0000] {spark_submit.py:579} INFO - 24/12/15 16:57:58 INFO TaskSetManager: Finished task 0.0 in stage 5.0 (TID 52) in 189 ms on 172.18.0.9 (executor 0) (1/1)
[2024-12-15T16:57:58.927+0000] {spark_submit.py:579} INFO - 24/12/15 16:57:58 INFO TaskSchedulerImpl: Removed TaskSet 5.0, whose tasks have all completed, from pool
[2024-12-15T16:57:58.927+0000] {spark_submit.py:579} INFO - 24/12/15 16:57:58 INFO DAGScheduler: ResultStage 5 (toString at String.java:2951) finished in 0.204 s
[2024-12-15T16:57:58.929+0000] {spark_submit.py:579} INFO - 24/12/15 16:57:58 INFO DAGScheduler: Job 2 is finished. Cancelling potential speculative or zombie tasks for this job
[2024-12-15T16:57:58.929+0000] {spark_submit.py:579} INFO - 24/12/15 16:57:58 INFO TaskSchedulerImpl: Killing all running tasks in stage 5: Stage finished
[2024-12-15T16:57:58.931+0000] {spark_submit.py:579} INFO - 24/12/15 16:57:58 INFO DAGScheduler: Job 2 finished: toString at String.java:2951, took 0.217955 s
[2024-12-15T16:57:58.981+0000] {spark_submit.py:579} INFO - 24/12/15 16:57:58 INFO CodeGenerator: Code generated in 24.767244 ms
[2024-12-15T16:57:58.987+0000] {spark_submit.py:579} INFO - 24/12/15 16:57:58 INFO Snapshot: [tableId=f1ff7a1b-e137-43c8-b702-cb67e6ff1a9d] DELTA: Done
[2024-12-15T16:57:58.988+0000] {spark_submit.py:579} INFO - 24/12/15 16:57:58 INFO Snapshot: [tableId=10300911-d473-40df-b698-e6e2d39b3c43] Created snapshot Snapshot(path=s3a://lakehouse/sliver/movies/_delta_log, version=1, metadata=Metadata(b45ba83f-a96f-4eac-b5d4-ae883121f780,null,null,Format(parquet,Map()),{"type":"struct","fields":[{"name":"budget","type":"integer","nullable":true,"metadata":{}},{"name":"genres","type":"string","nullable":true,"metadata":{}},{"name":"genres_convert","type":"string","nullable":true,"metadata":{}},{"name":"id","type":"string","nullable":true,"metadata":{}},{"name":"imdb_id","type":"string","nullable":true,"metadata":{}},{"name":"original_language","type":"string","nullable":true,"metadata":{}},{"name":"original_title","type":"string","nullable":true,"metadata":{}},{"name":"overview","type":"string","nullable":true,"metadata":{}},{"name":"popularity","type":"string","nullable":true,"metadata":{}},{"name":"poster_path","type":"string","nullable":true,"metadata":{}},{"name":"release_date","type":"date","nullable":true,"metadata":{}},{"name":"revenue","type":"double","nullable":true,"metadata":{}},{"name":"status","type":"string","nullable":true,"metadata":{}},{"name":"tagline","type":"string","nullable":true,"metadata":{}},{"name":"time","type":"string","nullable":true,"metadata":{}},{"name":"title","type":"string","nullable":true,"metadata":{}},{"name":"vote_average","type":"double","nullable":true,"metadata":{}},{"name":"vote_count","type":"double","nullable":true,"metadata":{}}]},List(),Map(),Some(1733921692315)), logSegment=LogSegment(s3a://lakehouse/sliver/movies/_delta_log,1,WrappedArray(S3AFileStatus{path=s3a://lakehouse/sliver/movies/_delta_log/00000000000000000000.json; isDirectory=false; length=3718; replication=1; blocksize=33554432; modification_time=1733921703321; access_time=0; owner=***; group=***; permission=rw-rw-rw-; isSymlink=false; hasAcl=false; isEncrypted=true; isErasureCoded=false} isEmptyDirectory=FALSE eTag=91800b08f15ae4ed3933c87d296d9c94 versionId=null, S3AFileStatus{path=s3a://lakehouse/sliver/movies/_delta_log/00000000000000000001.json; isDirectory=false; length=2242; replication=1; blocksize=33554432; modification_time=1734147345994; access_time=0; owner=***; group=***; permission=rw-rw-rw-; isSymlink=false; hasAcl=false; isEncrypted=true; isErasureCoded=false} isEmptyDirectory=FALSE eTag=47d01a428ca98b8b87ac3490bb1a86e3 versionId=null),List(),None,1734147345994), checksumOpt=None)
[2024-12-15T16:57:59.253+0000] {spark_submit.py:579} INFO - 24/12/15 16:57:59 INFO FileSourceStrategy: Pushed Filters:
[2024-12-15T16:57:59.254+0000] {spark_submit.py:579} INFO - 24/12/15 16:57:59 INFO FileSourceStrategy: Post-Scan Filters:
[2024-12-15T16:57:59.254+0000] {spark_submit.py:579} INFO - 24/12/15 16:57:59 INFO FileSourceStrategy: Output Data Schema: struct<budget: string, genres: string, id: string, imdb_id: string, original_language: string ... 15 more fields>
[2024-12-15T16:57:59.305+0000] {spark_submit.py:579} INFO - 24/12/15 16:57:59 INFO BlockManagerInfo: Removed broadcast_4_piece0 on a2b73f6a4b3a:45891 in memory (size: 91.6 KiB, free: 434.3 MiB)
[2024-12-15T16:57:59.307+0000] {spark_submit.py:579} INFO - 24/12/15 16:57:59 INFO BlockManagerInfo: Removed broadcast_4_piece0 on 172.18.0.9:33561 in memory (size: 91.6 KiB, free: 1048.8 MiB)
[2024-12-15T16:57:59.308+0000] {spark_submit.py:579} INFO - 24/12/15 16:57:59 INFO DeltaParquetFileFormat: Using default output committer for Parquet: org.apache.parquet.hadoop.ParquetOutputCommitter
[2024-12-15T16:57:59.354+0000] {spark_submit.py:579} INFO - 24/12/15 16:57:59 INFO CodeGenerator: Code generated in 18.531744 ms
[2024-12-15T16:57:59.363+0000] {spark_submit.py:579} INFO - 24/12/15 16:57:59 INFO MemoryStore: Block broadcast_5 stored as values in memory (estimated size 208.3 KiB, free 433.7 MiB)
[2024-12-15T16:57:59.375+0000] {spark_submit.py:579} INFO - 24/12/15 16:57:59 INFO MemoryStore: Block broadcast_5_piece0 stored as bytes in memory (estimated size 36.6 KiB, free 433.7 MiB)
[2024-12-15T16:57:59.376+0000] {spark_submit.py:579} INFO - 24/12/15 16:57:59 INFO BlockManagerInfo: Added broadcast_5_piece0 in memory on a2b73f6a4b3a:45891 (size: 36.6 KiB, free: 434.3 MiB)
[2024-12-15T16:57:59.377+0000] {spark_submit.py:579} INFO - 24/12/15 16:57:59 INFO SparkContext: Created broadcast 5 from save at NativeMethodAccessorImpl.java:0
[2024-12-15T16:57:59.382+0000] {spark_submit.py:579} INFO - 24/12/15 16:57:59 INFO FileSourceScanExec: Planning scan with bin packing, max size: 10691623 bytes, open cost is considered as scanning 4194304 bytes.
[2024-12-15T16:57:59.462+0000] {spark_submit.py:579} INFO - 24/12/15 16:57:59 INFO SparkContext: Starting job: save at NativeMethodAccessorImpl.java:0
[2024-12-15T16:57:59.463+0000] {spark_submit.py:579} INFO - 24/12/15 16:57:59 INFO DAGScheduler: Got job 3 (save at NativeMethodAccessorImpl.java:0) with 2 output partitions
[2024-12-15T16:57:59.464+0000] {spark_submit.py:579} INFO - 24/12/15 16:57:59 INFO DAGScheduler: Final stage: ResultStage 6 (save at NativeMethodAccessorImpl.java:0)
[2024-12-15T16:57:59.464+0000] {spark_submit.py:579} INFO - 24/12/15 16:57:59 INFO DAGScheduler: Parents of final stage: List()
[2024-12-15T16:57:59.464+0000] {spark_submit.py:579} INFO - 24/12/15 16:57:59 INFO DAGScheduler: Missing parents: List()
[2024-12-15T16:57:59.465+0000] {spark_submit.py:579} INFO - 24/12/15 16:57:59 INFO DAGScheduler: Submitting ResultStage 6 (MapPartitionsRDD[20] at save at NativeMethodAccessorImpl.java:0), which has no missing parents
[2024-12-15T16:57:59.527+0000] {spark_submit.py:579} INFO - 24/12/15 16:57:59 INFO MemoryStore: Block broadcast_6 stored as values in memory (estimated size 381.9 KiB, free 433.3 MiB)
[2024-12-15T16:57:59.530+0000] {spark_submit.py:579} INFO - 24/12/15 16:57:59 INFO MemoryStore: Block broadcast_6_piece0 stored as bytes in memory (estimated size 133.1 KiB, free 433.2 MiB)
[2024-12-15T16:57:59.531+0000] {spark_submit.py:579} INFO - 24/12/15 16:57:59 INFO BlockManagerInfo: Added broadcast_6_piece0 in memory on a2b73f6a4b3a:45891 (size: 133.1 KiB, free: 434.2 MiB)
[2024-12-15T16:57:59.532+0000] {spark_submit.py:579} INFO - 24/12/15 16:57:59 INFO SparkContext: Created broadcast 6 from broadcast at DAGScheduler.scala:1513
[2024-12-15T16:57:59.533+0000] {spark_submit.py:579} INFO - 24/12/15 16:57:59 INFO DAGScheduler: Submitting 2 missing tasks from ResultStage 6 (MapPartitionsRDD[20] at save at NativeMethodAccessorImpl.java:0) (first 15 tasks are for partitions Vector(0, 1))
[2024-12-15T16:57:59.533+0000] {spark_submit.py:579} INFO - 24/12/15 16:57:59 INFO TaskSchedulerImpl: Adding task set 6.0 with 2 tasks resource profile 0
[2024-12-15T16:57:59.535+0000] {spark_submit.py:579} INFO - 24/12/15 16:57:59 INFO TaskSetManager: Starting task 0.0 in stage 6.0 (TID 53) (172.18.0.9, executor 0, partition 0, PROCESS_LOCAL, 4912 bytes) taskResourceAssignments Map()
[2024-12-15T16:57:59.535+0000] {spark_submit.py:579} INFO - 24/12/15 16:57:59 INFO TaskSetManager: Starting task 1.0 in stage 6.0 (TID 54) (172.18.0.9, executor 0, partition 1, PROCESS_LOCAL, 4912 bytes) taskResourceAssignments Map()
[2024-12-15T16:57:59.550+0000] {spark_submit.py:579} INFO - 24/12/15 16:57:59 INFO BlockManagerInfo: Added broadcast_6_piece0 in memory on 172.18.0.9:33561 (size: 133.1 KiB, free: 1048.6 MiB)
[2024-12-15T16:57:59.770+0000] {spark_submit.py:579} INFO - 24/12/15 16:57:59 INFO BlockManagerInfo: Added broadcast_5_piece0 in memory on 172.18.0.9:33561 (size: 36.6 KiB, free: 1048.6 MiB)
[2024-12-15T16:58:00.127+0000] {spark_submit.py:579} INFO - 24/12/15 16:58:00 INFO TaskSetManager: Finished task 1.0 in stage 6.0 (TID 54) in 592 ms on 172.18.0.9 (executor 0) (1/2)
[2024-12-15T16:58:03.486+0000] {spark_submit.py:579} INFO - 24/12/15 16:58:03 INFO TaskSetManager: Finished task 0.0 in stage 6.0 (TID 53) in 3952 ms on 172.18.0.9 (executor 0) (2/2)
[2024-12-15T16:58:03.487+0000] {spark_submit.py:579} INFO - 24/12/15 16:58:03 INFO TaskSchedulerImpl: Removed TaskSet 6.0, whose tasks have all completed, from pool
[2024-12-15T16:58:03.488+0000] {spark_submit.py:579} INFO - 24/12/15 16:58:03 INFO DAGScheduler: ResultStage 6 (save at NativeMethodAccessorImpl.java:0) finished in 4.022 s
[2024-12-15T16:58:03.489+0000] {spark_submit.py:579} INFO - 24/12/15 16:58:03 INFO DAGScheduler: Job 3 is finished. Cancelling potential speculative or zombie tasks for this job
[2024-12-15T16:58:03.489+0000] {spark_submit.py:579} INFO - 24/12/15 16:58:03 INFO TaskSchedulerImpl: Killing all running tasks in stage 6: Stage finished
[2024-12-15T16:58:03.490+0000] {spark_submit.py:579} INFO - 24/12/15 16:58:03 INFO DAGScheduler: Job 3 finished: save at NativeMethodAccessorImpl.java:0, took 4.025600 s
[2024-12-15T16:58:03.490+0000] {spark_submit.py:579} INFO - 24/12/15 16:58:03 INFO FileFormatWriter: Start to commit write Job 0595d028-52a5-49b7-87fd-d0de2d663dd2.
[2024-12-15T16:58:03.493+0000] {spark_submit.py:579} INFO - 24/12/15 16:58:03 INFO FileFormatWriter: Write Job 0595d028-52a5-49b7-87fd-d0de2d663dd2 committed. Elapsed time: 1 ms.
[2024-12-15T16:58:03.498+0000] {spark_submit.py:579} INFO - 24/12/15 16:58:03 INFO FileFormatWriter: Finished processing stats for write job 0595d028-52a5-49b7-87fd-d0de2d663dd2.
[2024-12-15T16:58:03.738+0000] {spark_submit.py:579} INFO - 24/12/15 16:58:03 INFO BlockManagerInfo: Removed broadcast_6_piece0 on a2b73f6a4b3a:45891 in memory (size: 133.1 KiB, free: 434.3 MiB)
[2024-12-15T16:58:03.741+0000] {spark_submit.py:579} INFO - 24/12/15 16:58:03 INFO BlockManagerInfo: Removed broadcast_6_piece0 on 172.18.0.9:33561 in memory (size: 133.1 KiB, free: 1048.7 MiB)
[2024-12-15T16:58:03.853+0000] {spark_submit.py:579} INFO - 24/12/15 16:58:03 INFO CodeGenerator: Code generated in 101.487092 ms
[2024-12-15T16:58:03.873+0000] {spark_submit.py:579} INFO - 24/12/15 16:58:03 INFO SparkContext: Starting job: $anonfun$recordDeltaOperationInternal$1 at DatabricksLogging.scala:128
[2024-12-15T16:58:03.874+0000] {spark_submit.py:579} INFO - 24/12/15 16:58:03 INFO DAGScheduler: Got job 4 ($anonfun$recordDeltaOperationInternal$1 at DatabricksLogging.scala:128) with 50 output partitions
[2024-12-15T16:58:03.875+0000] {spark_submit.py:579} INFO - 24/12/15 16:58:03 INFO DAGScheduler: Final stage: ResultStage 8 ($anonfun$recordDeltaOperationInternal$1 at DatabricksLogging.scala:128)
[2024-12-15T16:58:03.876+0000] {spark_submit.py:579} INFO - 24/12/15 16:58:03 INFO DAGScheduler: Parents of final stage: List(ShuffleMapStage 7)
[2024-12-15T16:58:03.876+0000] {spark_submit.py:579} INFO - 24/12/15 16:58:03 INFO DAGScheduler: Missing parents: List()
[2024-12-15T16:58:03.877+0000] {spark_submit.py:579} INFO - 24/12/15 16:58:03 INFO DAGScheduler: Submitting ResultStage 8 (MapPartitionsRDD[22] at $anonfun$recordDeltaOperationInternal$1 at DatabricksLogging.scala:128), which has no missing parents
[2024-12-15T16:58:03.884+0000] {spark_submit.py:579} INFO - 24/12/15 16:58:03 INFO MemoryStore: Block broadcast_7 stored as values in memory (estimated size 475.1 KiB, free 433.2 MiB)
[2024-12-15T16:58:03.887+0000] {spark_submit.py:579} INFO - 24/12/15 16:58:03 INFO MemoryStore: Block broadcast_7_piece0 stored as bytes in memory (estimated size 112.5 KiB, free 433.1 MiB)
[2024-12-15T16:58:03.898+0000] {spark_submit.py:579} INFO - 24/12/15 16:58:03 INFO BlockManagerInfo: Added broadcast_7_piece0 in memory on a2b73f6a4b3a:45891 (size: 112.5 KiB, free: 434.2 MiB)
[2024-12-15T16:58:03.899+0000] {spark_submit.py:579} INFO - 24/12/15 16:58:03 INFO SparkContext: Created broadcast 7 from broadcast at DAGScheduler.scala:1513
[2024-12-15T16:58:03.900+0000] {spark_submit.py:579} INFO - 24/12/15 16:58:03 INFO DAGScheduler: Submitting 50 missing tasks from ResultStage 8 (MapPartitionsRDD[22] at $anonfun$recordDeltaOperationInternal$1 at DatabricksLogging.scala:128) (first 15 tasks are for partitions Vector(0, 1, 2, 3, 4, 5, 6, 7, 8, 9, 10, 11, 12, 13, 14))
[2024-12-15T16:58:03.900+0000] {spark_submit.py:579} INFO - 24/12/15 16:58:03 INFO TaskSchedulerImpl: Adding task set 8.0 with 50 tasks resource profile 0
[2024-12-15T16:58:03.903+0000] {spark_submit.py:579} INFO - 24/12/15 16:58:03 INFO TaskSetManager: Starting task 0.0 in stage 8.0 (TID 55) (172.18.0.9, executor 0, partition 0, PROCESS_LOCAL, 4457 bytes) taskResourceAssignments Map()
[2024-12-15T16:58:03.904+0000] {spark_submit.py:579} INFO - 24/12/15 16:58:03 INFO TaskSetManager: Starting task 1.0 in stage 8.0 (TID 56) (172.18.0.9, executor 0, partition 1, PROCESS_LOCAL, 4457 bytes) taskResourceAssignments Map()
[2024-12-15T16:58:03.926+0000] {spark_submit.py:579} INFO - 24/12/15 16:58:03 INFO BlockManagerInfo: Added broadcast_7_piece0 in memory on 172.18.0.9:33561 (size: 112.5 KiB, free: 1048.6 MiB)
[2024-12-15T16:58:04.086+0000] {spark_submit.py:579} INFO - 24/12/15 16:58:04 INFO TaskSetManager: Starting task 2.0 in stage 8.0 (TID 57) (172.18.0.9, executor 0, partition 2, PROCESS_LOCAL, 4457 bytes) taskResourceAssignments Map()
[2024-12-15T16:58:04.088+0000] {spark_submit.py:579} INFO - 24/12/15 16:58:04 INFO TaskSetManager: Finished task 1.0 in stage 8.0 (TID 56) in 183 ms on 172.18.0.9 (executor 0) (1/50)
[2024-12-15T16:58:04.091+0000] {spark_submit.py:579} INFO - 24/12/15 16:58:04 INFO TaskSetManager: Starting task 3.0 in stage 8.0 (TID 58) (172.18.0.9, executor 0, partition 3, PROCESS_LOCAL, 4457 bytes) taskResourceAssignments Map()
[2024-12-15T16:58:04.092+0000] {spark_submit.py:579} INFO - 24/12/15 16:58:04 INFO TaskSetManager: Finished task 0.0 in stage 8.0 (TID 55) in 184 ms on 172.18.0.9 (executor 0) (2/50)
[2024-12-15T16:58:04.103+0000] {spark_submit.py:579} INFO - 24/12/15 16:58:04 INFO TaskSetManager: Starting task 4.0 in stage 8.0 (TID 59) (172.18.0.9, executor 0, partition 4, PROCESS_LOCAL, 4457 bytes) taskResourceAssignments Map()
[2024-12-15T16:58:04.105+0000] {spark_submit.py:579} INFO - 24/12/15 16:58:04 INFO TaskSetManager: Finished task 2.0 in stage 8.0 (TID 57) in 19 ms on 172.18.0.9 (executor 0) (3/50)
[2024-12-15T16:58:04.105+0000] {spark_submit.py:579} INFO - 24/12/15 16:58:04 INFO TaskSetManager: Starting task 5.0 in stage 8.0 (TID 60) (172.18.0.9, executor 0, partition 5, PROCESS_LOCAL, 4457 bytes) taskResourceAssignments Map()
[2024-12-15T16:58:04.106+0000] {spark_submit.py:579} INFO - 24/12/15 16:58:04 INFO TaskSetManager: Finished task 3.0 in stage 8.0 (TID 58) in 18 ms on 172.18.0.9 (executor 0) (4/50)
[2024-12-15T16:58:04.121+0000] {spark_submit.py:579} INFO - 24/12/15 16:58:04 INFO TaskSetManager: Starting task 6.0 in stage 8.0 (TID 61) (172.18.0.9, executor 0, partition 6, PROCESS_LOCAL, 4457 bytes) taskResourceAssignments Map()
[2024-12-15T16:58:04.123+0000] {spark_submit.py:579} INFO - 24/12/15 16:58:04 INFO TaskSetManager: Finished task 4.0 in stage 8.0 (TID 59) in 18 ms on 172.18.0.9 (executor 0) (5/50)
[2024-12-15T16:58:04.125+0000] {spark_submit.py:579} INFO - 24/12/15 16:58:04 INFO TaskSetManager: Starting task 7.0 in stage 8.0 (TID 62) (172.18.0.9, executor 0, partition 7, PROCESS_LOCAL, 4457 bytes) taskResourceAssignments Map()
[2024-12-15T16:58:04.125+0000] {spark_submit.py:579} INFO - 24/12/15 16:58:04 INFO TaskSetManager: Finished task 5.0 in stage 8.0 (TID 60) in 19 ms on 172.18.0.9 (executor 0) (6/50)
[2024-12-15T16:58:04.145+0000] {spark_submit.py:579} INFO - 24/12/15 16:58:04 INFO TaskSetManager: Starting task 8.0 in stage 8.0 (TID 63) (172.18.0.9, executor 0, partition 8, PROCESS_LOCAL, 4457 bytes) taskResourceAssignments Map()
[2024-12-15T16:58:04.147+0000] {spark_submit.py:579} INFO - 24/12/15 16:58:04 INFO TaskSetManager: Finished task 6.0 in stage 8.0 (TID 61) in 26 ms on 172.18.0.9 (executor 0) (7/50)
[2024-12-15T16:58:04.148+0000] {spark_submit.py:579} INFO - 24/12/15 16:58:04 INFO TaskSetManager: Starting task 9.0 in stage 8.0 (TID 64) (172.18.0.9, executor 0, partition 9, PROCESS_LOCAL, 4457 bytes) taskResourceAssignments Map()
[2024-12-15T16:58:04.150+0000] {spark_submit.py:579} INFO - 24/12/15 16:58:04 INFO TaskSetManager: Finished task 7.0 in stage 8.0 (TID 62) in 26 ms on 172.18.0.9 (executor 0) (8/50)
[2024-12-15T16:58:04.165+0000] {spark_submit.py:579} INFO - 24/12/15 16:58:04 INFO TaskSetManager: Starting task 10.0 in stage 8.0 (TID 65) (172.18.0.9, executor 0, partition 10, PROCESS_LOCAL, 4457 bytes) taskResourceAssignments Map()
[2024-12-15T16:58:04.166+0000] {spark_submit.py:579} INFO - 24/12/15 16:58:04 INFO TaskSetManager: Finished task 9.0 in stage 8.0 (TID 64) in 18 ms on 172.18.0.9 (executor 0) (9/50)
[2024-12-15T16:58:04.167+0000] {spark_submit.py:579} INFO - 24/12/15 16:58:04 INFO TaskSetManager: Starting task 11.0 in stage 8.0 (TID 66) (172.18.0.9, executor 0, partition 11, PROCESS_LOCAL, 4457 bytes) taskResourceAssignments Map()
[2024-12-15T16:58:04.167+0000] {spark_submit.py:579} INFO - 24/12/15 16:58:04 INFO TaskSetManager: Finished task 8.0 in stage 8.0 (TID 63) in 22 ms on 172.18.0.9 (executor 0) (10/50)
[2024-12-15T16:58:04.183+0000] {spark_submit.py:579} INFO - 24/12/15 16:58:04 INFO TaskSetManager: Starting task 12.0 in stage 8.0 (TID 67) (172.18.0.9, executor 0, partition 12, PROCESS_LOCAL, 4457 bytes) taskResourceAssignments Map()
[2024-12-15T16:58:04.184+0000] {spark_submit.py:579} INFO - 24/12/15 16:58:04 INFO TaskSetManager: Finished task 10.0 in stage 8.0 (TID 65) in 19 ms on 172.18.0.9 (executor 0) (11/50)
[2024-12-15T16:58:04.185+0000] {spark_submit.py:579} INFO - 24/12/15 16:58:04 INFO TaskSetManager: Starting task 13.0 in stage 8.0 (TID 68) (172.18.0.9, executor 0, partition 13, PROCESS_LOCAL, 4457 bytes) taskResourceAssignments Map()
[2024-12-15T16:58:04.187+0000] {spark_submit.py:579} INFO - 24/12/15 16:58:04 INFO TaskSetManager: Finished task 11.0 in stage 8.0 (TID 66) in 19 ms on 172.18.0.9 (executor 0) (12/50)
[2024-12-15T16:58:04.201+0000] {spark_submit.py:579} INFO - 24/12/15 16:58:04 INFO TaskSetManager: Starting task 14.0 in stage 8.0 (TID 69) (172.18.0.9, executor 0, partition 14, PROCESS_LOCAL, 4457 bytes) taskResourceAssignments Map()
[2024-12-15T16:58:04.202+0000] {spark_submit.py:579} INFO - 24/12/15 16:58:04 INFO TaskSetManager: Finished task 12.0 in stage 8.0 (TID 67) in 18 ms on 172.18.0.9 (executor 0) (13/50)
[2024-12-15T16:58:04.203+0000] {spark_submit.py:579} INFO - 24/12/15 16:58:04 INFO TaskSetManager: Starting task 15.0 in stage 8.0 (TID 70) (172.18.0.9, executor 0, partition 15, PROCESS_LOCAL, 4457 bytes) taskResourceAssignments Map()
[2024-12-15T16:58:04.203+0000] {spark_submit.py:579} INFO - 24/12/15 16:58:04 INFO TaskSetManager: Finished task 13.0 in stage 8.0 (TID 68) in 19 ms on 172.18.0.9 (executor 0) (14/50)
[2024-12-15T16:58:04.219+0000] {spark_submit.py:579} INFO - 24/12/15 16:58:04 INFO TaskSetManager: Starting task 16.0 in stage 8.0 (TID 71) (172.18.0.9, executor 0, partition 16, PROCESS_LOCAL, 4457 bytes) taskResourceAssignments Map()
[2024-12-15T16:58:04.220+0000] {spark_submit.py:579} INFO - 24/12/15 16:58:04 INFO TaskSetManager: Finished task 15.0 in stage 8.0 (TID 70) in 17 ms on 172.18.0.9 (executor 0) (15/50)
[2024-12-15T16:58:04.221+0000] {spark_submit.py:579} INFO - 24/12/15 16:58:04 INFO TaskSetManager: Starting task 17.0 in stage 8.0 (TID 72) (172.18.0.9, executor 0, partition 17, PROCESS_LOCAL, 4457 bytes) taskResourceAssignments Map()
[2024-12-15T16:58:04.223+0000] {spark_submit.py:579} INFO - 24/12/15 16:58:04 INFO TaskSetManager: Finished task 14.0 in stage 8.0 (TID 69) in 21 ms on 172.18.0.9 (executor 0) (16/50)
[2024-12-15T16:58:04.236+0000] {spark_submit.py:579} INFO - 24/12/15 16:58:04 INFO TaskSetManager: Starting task 18.0 in stage 8.0 (TID 73) (172.18.0.9, executor 0, partition 18, PROCESS_LOCAL, 4457 bytes) taskResourceAssignments Map()
[2024-12-15T16:58:04.237+0000] {spark_submit.py:579} INFO - 24/12/15 16:58:04 INFO TaskSetManager: Finished task 17.0 in stage 8.0 (TID 72) in 16 ms on 172.18.0.9 (executor 0) (17/50)
[2024-12-15T16:58:04.237+0000] {spark_submit.py:579} INFO - 24/12/15 16:58:04 INFO TaskSetManager: Starting task 19.0 in stage 8.0 (TID 74) (172.18.0.9, executor 0, partition 19, PROCESS_LOCAL, 4457 bytes) taskResourceAssignments Map()
[2024-12-15T16:58:04.238+0000] {spark_submit.py:579} INFO - 24/12/15 16:58:04 INFO TaskSetManager: Finished task 16.0 in stage 8.0 (TID 71) in 20 ms on 172.18.0.9 (executor 0) (18/50)
[2024-12-15T16:58:04.252+0000] {spark_submit.py:579} INFO - 24/12/15 16:58:04 INFO TaskSetManager: Starting task 20.0 in stage 8.0 (TID 75) (172.18.0.9, executor 0, partition 20, PROCESS_LOCAL, 4457 bytes) taskResourceAssignments Map()
[2024-12-15T16:58:04.253+0000] {spark_submit.py:579} INFO - 24/12/15 16:58:04 INFO TaskSetManager: Finished task 19.0 in stage 8.0 (TID 74) in 15 ms on 172.18.0.9 (executor 0) (19/50)
[2024-12-15T16:58:04.254+0000] {spark_submit.py:579} INFO - 24/12/15 16:58:04 INFO TaskSetManager: Starting task 21.0 in stage 8.0 (TID 76) (172.18.0.9, executor 0, partition 21, PROCESS_LOCAL, 4457 bytes) taskResourceAssignments Map()
[2024-12-15T16:58:04.255+0000] {spark_submit.py:579} INFO - 24/12/15 16:58:04 INFO TaskSetManager: Finished task 18.0 in stage 8.0 (TID 73) in 19 ms on 172.18.0.9 (executor 0) (20/50)
[2024-12-15T16:58:04.268+0000] {spark_submit.py:579} INFO - 24/12/15 16:58:04 INFO TaskSetManager: Starting task 22.0 in stage 8.0 (TID 77) (172.18.0.9, executor 0, partition 22, PROCESS_LOCAL, 4457 bytes) taskResourceAssignments Map()
[2024-12-15T16:58:04.269+0000] {spark_submit.py:579} INFO - 24/12/15 16:58:04 INFO TaskSetManager: Finished task 20.0 in stage 8.0 (TID 75) in 16 ms on 172.18.0.9 (executor 0) (21/50)
[2024-12-15T16:58:04.271+0000] {spark_submit.py:579} INFO - 24/12/15 16:58:04 INFO TaskSetManager: Starting task 23.0 in stage 8.0 (TID 78) (172.18.0.9, executor 0, partition 23, PROCESS_LOCAL, 4457 bytes) taskResourceAssignments Map()
[2024-12-15T16:58:04.272+0000] {spark_submit.py:579} INFO - 24/12/15 16:58:04 INFO TaskSetManager: Finished task 21.0 in stage 8.0 (TID 76) in 18 ms on 172.18.0.9 (executor 0) (22/50)
[2024-12-15T16:58:04.286+0000] {spark_submit.py:579} INFO - 24/12/15 16:58:04 INFO TaskSetManager: Starting task 24.0 in stage 8.0 (TID 79) (172.18.0.9, executor 0, partition 24, PROCESS_LOCAL, 4457 bytes) taskResourceAssignments Map()
[2024-12-15T16:58:04.287+0000] {spark_submit.py:579} INFO - 24/12/15 16:58:04 INFO TaskSetManager: Finished task 23.0 in stage 8.0 (TID 78) in 16 ms on 172.18.0.9 (executor 0) (23/50)
[2024-12-15T16:58:04.288+0000] {spark_submit.py:579} INFO - 24/12/15 16:58:04 INFO TaskSetManager: Starting task 25.0 in stage 8.0 (TID 80) (172.18.0.9, executor 0, partition 25, PROCESS_LOCAL, 4457 bytes) taskResourceAssignments Map()
[2024-12-15T16:58:04.289+0000] {spark_submit.py:579} INFO - 24/12/15 16:58:04 INFO TaskSetManager: Finished task 22.0 in stage 8.0 (TID 77) in 19 ms on 172.18.0.9 (executor 0) (24/50)
[2024-12-15T16:58:04.311+0000] {spark_submit.py:579} INFO - 24/12/15 16:58:04 INFO TaskSetManager: Starting task 26.0 in stage 8.0 (TID 81) (172.18.0.9, executor 0, partition 26, PROCESS_LOCAL, 4457 bytes) taskResourceAssignments Map()
[2024-12-15T16:58:04.313+0000] {spark_submit.py:579} INFO - 24/12/15 16:58:04 INFO TaskSetManager: Finished task 24.0 in stage 8.0 (TID 79) in 26 ms on 172.18.0.9 (executor 0) (25/50)
[2024-12-15T16:58:04.314+0000] {spark_submit.py:579} INFO - 24/12/15 16:58:04 INFO TaskSetManager: Starting task 27.0 in stage 8.0 (TID 82) (172.18.0.9, executor 0, partition 27, PROCESS_LOCAL, 4457 bytes) taskResourceAssignments Map()
[2024-12-15T16:58:04.315+0000] {spark_submit.py:579} INFO - 24/12/15 16:58:04 INFO TaskSetManager: Finished task 25.0 in stage 8.0 (TID 80) in 28 ms on 172.18.0.9 (executor 0) (26/50)
[2024-12-15T16:58:04.332+0000] {spark_submit.py:579} INFO - 24/12/15 16:58:04 INFO TaskSetManager: Starting task 28.0 in stage 8.0 (TID 83) (172.18.0.9, executor 0, partition 28, PROCESS_LOCAL, 4457 bytes) taskResourceAssignments Map()
[2024-12-15T16:58:04.334+0000] {spark_submit.py:579} INFO - 24/12/15 16:58:04 INFO TaskSetManager: Finished task 26.0 in stage 8.0 (TID 81) in 22 ms on 172.18.0.9 (executor 0) (27/50)
[2024-12-15T16:58:04.336+0000] {spark_submit.py:579} INFO - 24/12/15 16:58:04 INFO TaskSetManager: Starting task 29.0 in stage 8.0 (TID 84) (172.18.0.9, executor 0, partition 29, PROCESS_LOCAL, 4457 bytes) taskResourceAssignments Map()
[2024-12-15T16:58:04.337+0000] {spark_submit.py:579} INFO - 24/12/15 16:58:04 INFO TaskSetManager: Finished task 27.0 in stage 8.0 (TID 82) in 25 ms on 172.18.0.9 (executor 0) (28/50)
[2024-12-15T16:58:04.347+0000] {spark_submit.py:579} INFO - 24/12/15 16:58:04 INFO TaskSetManager: Starting task 30.0 in stage 8.0 (TID 85) (172.18.0.9, executor 0, partition 30, PROCESS_LOCAL, 4457 bytes) taskResourceAssignments Map()
[2024-12-15T16:58:04.348+0000] {spark_submit.py:579} INFO - 24/12/15 16:58:04 INFO TaskSetManager: Finished task 28.0 in stage 8.0 (TID 83) in 16 ms on 172.18.0.9 (executor 0) (29/50)
[2024-12-15T16:58:04.351+0000] {spark_submit.py:579} INFO - 24/12/15 16:58:04 INFO TaskSetManager: Starting task 31.0 in stage 8.0 (TID 86) (172.18.0.9, executor 0, partition 31, PROCESS_LOCAL, 4457 bytes) taskResourceAssignments Map()
[2024-12-15T16:58:04.352+0000] {spark_submit.py:579} INFO - 24/12/15 16:58:04 INFO TaskSetManager: Finished task 29.0 in stage 8.0 (TID 84) in 16 ms on 172.18.0.9 (executor 0) (30/50)
[2024-12-15T16:58:04.361+0000] {spark_submit.py:579} INFO - 24/12/15 16:58:04 INFO TaskSetManager: Starting task 32.0 in stage 8.0 (TID 87) (172.18.0.9, executor 0, partition 32, PROCESS_LOCAL, 4457 bytes) taskResourceAssignments Map()
[2024-12-15T16:58:04.362+0000] {spark_submit.py:579} INFO - 24/12/15 16:58:04 INFO TaskSetManager: Finished task 30.0 in stage 8.0 (TID 85) in 15 ms on 172.18.0.9 (executor 0) (31/50)
[2024-12-15T16:58:04.365+0000] {spark_submit.py:579} INFO - 24/12/15 16:58:04 INFO TaskSetManager: Starting task 33.0 in stage 8.0 (TID 88) (172.18.0.9, executor 0, partition 33, PROCESS_LOCAL, 4457 bytes) taskResourceAssignments Map()
[2024-12-15T16:58:04.366+0000] {spark_submit.py:579} INFO - 24/12/15 16:58:04 INFO TaskSetManager: Finished task 31.0 in stage 8.0 (TID 86) in 15 ms on 172.18.0.9 (executor 0) (32/50)
[2024-12-15T16:58:04.375+0000] {spark_submit.py:579} INFO - 24/12/15 16:58:04 INFO TaskSetManager: Starting task 34.0 in stage 8.0 (TID 89) (172.18.0.9, executor 0, partition 34, PROCESS_LOCAL, 4457 bytes) taskResourceAssignments Map()
[2024-12-15T16:58:04.376+0000] {spark_submit.py:579} INFO - 24/12/15 16:58:04 INFO TaskSetManager: Finished task 32.0 in stage 8.0 (TID 87) in 16 ms on 172.18.0.9 (executor 0) (33/50)
[2024-12-15T16:58:04.379+0000] {spark_submit.py:579} INFO - 24/12/15 16:58:04 INFO TaskSetManager: Starting task 35.0 in stage 8.0 (TID 90) (172.18.0.9, executor 0, partition 35, PROCESS_LOCAL, 4457 bytes) taskResourceAssignments Map()
[2024-12-15T16:58:04.380+0000] {spark_submit.py:579} INFO - 24/12/15 16:58:04 INFO TaskSetManager: Finished task 33.0 in stage 8.0 (TID 88) in 15 ms on 172.18.0.9 (executor 0) (34/50)
[2024-12-15T16:58:04.390+0000] {spark_submit.py:579} INFO - 24/12/15 16:58:04 INFO TaskSetManager: Starting task 36.0 in stage 8.0 (TID 91) (172.18.0.9, executor 0, partition 36, PROCESS_LOCAL, 4457 bytes) taskResourceAssignments Map()
[2024-12-15T16:58:04.391+0000] {spark_submit.py:579} INFO - 24/12/15 16:58:04 INFO TaskSetManager: Finished task 34.0 in stage 8.0 (TID 89) in 16 ms on 172.18.0.9 (executor 0) (35/50)
[2024-12-15T16:58:04.392+0000] {spark_submit.py:579} INFO - 24/12/15 16:58:04 INFO TaskSetManager: Starting task 37.0 in stage 8.0 (TID 92) (172.18.0.9, executor 0, partition 37, PROCESS_LOCAL, 4457 bytes) taskResourceAssignments Map()
[2024-12-15T16:58:04.393+0000] {spark_submit.py:579} INFO - 24/12/15 16:58:04 INFO TaskSetManager: Finished task 35.0 in stage 8.0 (TID 90) in 13 ms on 172.18.0.9 (executor 0) (36/50)
[2024-12-15T16:58:04.411+0000] {spark_submit.py:579} INFO - 24/12/15 16:58:04 INFO TaskSetManager: Starting task 38.0 in stage 8.0 (TID 93) (172.18.0.9, executor 0, partition 38, PROCESS_LOCAL, 4457 bytes) taskResourceAssignments Map()
[2024-12-15T16:58:04.412+0000] {spark_submit.py:579} INFO - 24/12/15 16:58:04 INFO TaskSetManager: Finished task 37.0 in stage 8.0 (TID 92) in 20 ms on 172.18.0.9 (executor 0) (37/50)
[2024-12-15T16:58:04.414+0000] {spark_submit.py:579} INFO - 24/12/15 16:58:04 INFO TaskSetManager: Starting task 39.0 in stage 8.0 (TID 94) (172.18.0.9, executor 0, partition 39, PROCESS_LOCAL, 4457 bytes) taskResourceAssignments Map()
[2024-12-15T16:58:04.414+0000] {spark_submit.py:579} INFO - 24/12/15 16:58:04 INFO TaskSetManager: Finished task 36.0 in stage 8.0 (TID 91) in 23 ms on 172.18.0.9 (executor 0) (38/50)
[2024-12-15T16:58:04.424+0000] {spark_submit.py:579} INFO - 24/12/15 16:58:04 INFO TaskSetManager: Starting task 40.0 in stage 8.0 (TID 95) (172.18.0.9, executor 0, partition 40, PROCESS_LOCAL, 4457 bytes) taskResourceAssignments Map()
[2024-12-15T16:58:04.426+0000] {spark_submit.py:579} INFO - 24/12/15 16:58:04 INFO TaskSetManager: Finished task 38.0 in stage 8.0 (TID 93) in 14 ms on 172.18.0.9 (executor 0) (39/50)
[2024-12-15T16:58:04.429+0000] {spark_submit.py:579} INFO - 24/12/15 16:58:04 INFO TaskSetManager: Starting task 41.0 in stage 8.0 (TID 96) (172.18.0.9, executor 0, partition 41, PROCESS_LOCAL, 4457 bytes) taskResourceAssignments Map()
[2024-12-15T16:58:04.430+0000] {spark_submit.py:579} INFO - 24/12/15 16:58:04 INFO TaskSetManager: Finished task 39.0 in stage 8.0 (TID 94) in 17 ms on 172.18.0.9 (executor 0) (40/50)
[2024-12-15T16:58:04.441+0000] {spark_submit.py:579} INFO - 24/12/15 16:58:04 INFO TaskSetManager: Starting task 42.0 in stage 8.0 (TID 97) (172.18.0.9, executor 0, partition 42, PROCESS_LOCAL, 4457 bytes) taskResourceAssignments Map()
[2024-12-15T16:58:04.442+0000] {spark_submit.py:579} INFO - 24/12/15 16:58:04 INFO TaskSetManager: Finished task 40.0 in stage 8.0 (TID 95) in 16 ms on 172.18.0.9 (executor 0) (41/50)
[2024-12-15T16:58:04.443+0000] {spark_submit.py:579} INFO - 24/12/15 16:58:04 INFO TaskSetManager: Starting task 43.0 in stage 8.0 (TID 98) (172.18.0.9, executor 0, partition 43, PROCESS_LOCAL, 4457 bytes) taskResourceAssignments Map()
[2024-12-15T16:58:04.444+0000] {spark_submit.py:579} INFO - 24/12/15 16:58:04 INFO TaskSetManager: Finished task 41.0 in stage 8.0 (TID 96) in 15 ms on 172.18.0.9 (executor 0) (42/50)
[2024-12-15T16:58:04.455+0000] {spark_submit.py:579} INFO - 24/12/15 16:58:04 INFO TaskSetManager: Starting task 44.0 in stage 8.0 (TID 99) (172.18.0.9, executor 0, partition 44, PROCESS_LOCAL, 4457 bytes) taskResourceAssignments Map()
[2024-12-15T16:58:04.456+0000] {spark_submit.py:579} INFO - 24/12/15 16:58:04 INFO TaskSetManager: Finished task 43.0 in stage 8.0 (TID 98) in 13 ms on 172.18.0.9 (executor 0) (43/50)
[2024-12-15T16:58:04.457+0000] {spark_submit.py:579} INFO - 24/12/15 16:58:04 INFO TaskSetManager: Finished task 42.0 in stage 8.0 (TID 97) in 17 ms on 172.18.0.9 (executor 0) (44/50)
[2024-12-15T16:58:04.458+0000] {spark_submit.py:579} INFO - 24/12/15 16:58:04 INFO TaskSetManager: Starting task 45.0 in stage 8.0 (TID 100) (172.18.0.9, executor 0, partition 45, PROCESS_LOCAL, 4457 bytes) taskResourceAssignments Map()
[2024-12-15T16:58:04.469+0000] {spark_submit.py:579} INFO - 24/12/15 16:58:04 INFO TaskSetManager: Starting task 46.0 in stage 8.0 (TID 101) (172.18.0.9, executor 0, partition 46, PROCESS_LOCAL, 4457 bytes) taskResourceAssignments Map()
[2024-12-15T16:58:04.470+0000] {spark_submit.py:579} INFO - 24/12/15 16:58:04 INFO TaskSetManager: Finished task 44.0 in stage 8.0 (TID 99) in 14 ms on 172.18.0.9 (executor 0) (45/50)
[2024-12-15T16:58:04.474+0000] {spark_submit.py:579} INFO - 24/12/15 16:58:04 INFO TaskSetManager: Starting task 47.0 in stage 8.0 (TID 102) (172.18.0.9, executor 0, partition 47, PROCESS_LOCAL, 4457 bytes) taskResourceAssignments Map()
[2024-12-15T16:58:04.475+0000] {spark_submit.py:579} INFO - 24/12/15 16:58:04 INFO TaskSetManager: Finished task 45.0 in stage 8.0 (TID 100) in 14 ms on 172.18.0.9 (executor 0) (46/50)
[2024-12-15T16:58:04.483+0000] {spark_submit.py:579} INFO - 24/12/15 16:58:04 INFO TaskSetManager: Starting task 48.0 in stage 8.0 (TID 103) (172.18.0.9, executor 0, partition 48, PROCESS_LOCAL, 4457 bytes) taskResourceAssignments Map()
[2024-12-15T16:58:04.483+0000] {spark_submit.py:579} INFO - 24/12/15 16:58:04 INFO TaskSetManager: Finished task 46.0 in stage 8.0 (TID 101) in 15 ms on 172.18.0.9 (executor 0) (47/50)
[2024-12-15T16:58:04.485+0000] {spark_submit.py:579} INFO - 24/12/15 16:58:04 INFO TaskSetManager: Finished task 47.0 in stage 8.0 (TID 102) in 14 ms on 172.18.0.9 (executor 0) (48/50)
[2024-12-15T16:58:04.486+0000] {spark_submit.py:579} INFO - 24/12/15 16:58:04 INFO TaskSetManager: Starting task 49.0 in stage 8.0 (TID 104) (172.18.0.9, executor 0, partition 49, PROCESS_LOCAL, 4457 bytes) taskResourceAssignments Map()
[2024-12-15T16:58:04.496+0000] {spark_submit.py:579} INFO - 24/12/15 16:58:04 INFO TaskSetManager: Finished task 48.0 in stage 8.0 (TID 103) in 14 ms on 172.18.0.9 (executor 0) (49/50)
[2024-12-15T16:58:04.500+0000] {spark_submit.py:579} INFO - 24/12/15 16:58:04 INFO TaskSetManager: Finished task 49.0 in stage 8.0 (TID 104) in 16 ms on 172.18.0.9 (executor 0) (50/50)
[2024-12-15T16:58:04.501+0000] {spark_submit.py:579} INFO - 24/12/15 16:58:04 INFO TaskSchedulerImpl: Removed TaskSet 8.0, whose tasks have all completed, from pool
[2024-12-15T16:58:04.502+0000] {spark_submit.py:579} INFO - 24/12/15 16:58:04 INFO DAGScheduler: ResultStage 8 ($anonfun$recordDeltaOperationInternal$1 at DatabricksLogging.scala:128) finished in 0.622 s
[2024-12-15T16:58:04.502+0000] {spark_submit.py:579} INFO - 24/12/15 16:58:04 INFO DAGScheduler: Job 4 is finished. Cancelling potential speculative or zombie tasks for this job
[2024-12-15T16:58:04.503+0000] {spark_submit.py:579} INFO - 24/12/15 16:58:04 INFO TaskSchedulerImpl: Killing all running tasks in stage 8: Stage finished
[2024-12-15T16:58:04.503+0000] {spark_submit.py:579} INFO - 24/12/15 16:58:04 INFO DAGScheduler: Job 4 finished: $anonfun$recordDeltaOperationInternal$1 at DatabricksLogging.scala:128, took 0.629596 s
[2024-12-15T16:58:04.522+0000] {spark_submit.py:579} INFO - 24/12/15 16:58:04 INFO CodeGenerator: Code generated in 13.015331 ms
[2024-12-15T16:58:04.556+0000] {spark_submit.py:579} INFO - 24/12/15 16:58:04 INFO OptimisticTransaction: [tableId=b45ba83f,txnId=0ea3f57f] Attempting to commit version 2 with 3 actions with Serializable isolation level
[2024-12-15T16:58:04.571+0000] {spark_submit.py:579} INFO - 24/12/15 16:58:04 INFO BlockManagerInfo: Removed broadcast_7_piece0 on a2b73f6a4b3a:45891 in memory (size: 112.5 KiB, free: 434.3 MiB)
[2024-12-15T16:58:04.573+0000] {spark_submit.py:579} INFO - 24/12/15 16:58:04 INFO BlockManagerInfo: Removed broadcast_7_piece0 on 172.18.0.9:33561 in memory (size: 112.5 KiB, free: 1048.7 MiB)
[2024-12-15T16:58:04.890+0000] {spark_submit.py:579} INFO - 24/12/15 16:58:04 INFO DeltaLog: Creating a new snapshot v2 for commit version 2
[2024-12-15T16:58:04.890+0000] {spark_submit.py:579} INFO - 24/12/15 16:58:04 INFO DeltaLog: Loading version 2.
[2024-12-15T16:58:04.895+0000] {spark_submit.py:579} INFO - 24/12/15 16:58:04 INFO Snapshot: [tableId=b45ba83f-a96f-4eac-b5d4-ae883121f780] DELTA: Compute snapshot for version: 2
[2024-12-15T16:58:04.899+0000] {spark_submit.py:579} INFO - 24/12/15 16:58:04 INFO MemoryStore: Block broadcast_8 stored as values in memory (estimated size 204.7 KiB, free 433.5 MiB)
