[2025-01-24T15:16:03.269+0000] {taskinstance.py:1159} INFO - Dependencies all met for dep_context=non-requeueable deps ti=<TaskInstance: All_Layer.clean_review scheduled__2025-01-23T00:00:00+00:00 [queued]>
[2025-01-24T15:16:03.283+0000] {taskinstance.py:1159} INFO - Dependencies all met for dep_context=requeueable deps ti=<TaskInstance: All_Layer.clean_review scheduled__2025-01-23T00:00:00+00:00 [queued]>
[2025-01-24T15:16:03.284+0000] {taskinstance.py:1361} INFO - Starting attempt 1 of 2
[2025-01-24T15:16:03.304+0000] {taskinstance.py:1382} INFO - Executing <Task(SparkSubmitOperator): clean_review> on 2025-01-23 00:00:00+00:00
[2025-01-24T15:16:03.312+0000] {standard_task_runner.py:57} INFO - Started process 415 to run task
[2025-01-24T15:16:03.319+0000] {standard_task_runner.py:84} INFO - Running: ['***', 'tasks', 'run', 'All_Layer', 'clean_review', 'scheduled__2025-01-23T00:00:00+00:00', '--job-id', '192', '--raw', '--subdir', 'DAGS_FOLDER/All_Offi.py', '--cfg-path', '/tmp/tmp23ua1kcj']
[2025-01-24T15:16:03.323+0000] {standard_task_runner.py:85} INFO - Job 192: Subtask clean_review
[2025-01-24T15:16:03.413+0000] {task_command.py:416} INFO - Running <TaskInstance: All_Layer.clean_review scheduled__2025-01-23T00:00:00+00:00 [running]> on host 73fc507ad5e4
[2025-01-24T15:16:03.592+0000] {taskinstance.py:1662} INFO - Exporting env vars: AIRFLOW_CTX_DAG_OWNER='***' AIRFLOW_CTX_DAG_ID='All_Layer' AIRFLOW_CTX_TASK_ID='clean_review' AIRFLOW_CTX_EXECUTION_DATE='2025-01-23T00:00:00+00:00' AIRFLOW_CTX_TRY_NUMBER='1' AIRFLOW_CTX_DAG_RUN_ID='scheduled__2025-01-23T00:00:00+00:00'
[2025-01-24T15:16:03.603+0000] {base.py:73} INFO - Using connection ID 'spark-conn' for task execution.
[2025-01-24T15:16:03.607+0000] {spark_submit.py:403} INFO - Spark-Submit cmd: spark-submit --master spark://spark-master:7077 --conf spark.sql.extensions=io.delta.sql.DeltaSparkSessionExtension --conf spark.sql.catalog.spark_catalog=org.apache.spark.sql.delta.catalog.DeltaCatalog --jars /opt/***/jars/hadoop-aws-3.3.4.jar,/opt/***/jars/s3-2.18.41.jar,/opt/***/jars/aws-java-sdk-bundle-1.12.262.jar,/opt/***/jars/aws-java-sdk-1.12.367.jar,/opt/***/jars/delta-core_2.12-2.2.0.jar,/opt/***/jars/delta-storage-2.2.0.jar, --num-executors 2 --total-executor-cores 2 --executor-cores 2 --executor-memory 2g --driver-memory 1g --name arrow-spark --deploy-mode client /opt/***/jobs/python/processing_review.py s3a://lakehouse/bronze/review.parquet s3a://lakehouse/silver/review
[2025-01-24T15:16:04.030+0000] {spark_submit.py:579} INFO - /home/***/.local/lib/python3.9/site-packages/pyspark/bin/load-spark-env.sh: line 68: ps: command not found
[2025-01-24T15:16:09.744+0000] {spark_submit.py:579} INFO - 25/01/24 15:16:09 WARN NativeCodeLoader: Unable to load native-hadoop library for your platform... using builtin-java classes where applicable
[2025-01-24T15:16:12.240+0000] {spark_submit.py:579} INFO - 2025-01-24 15:16:12,239 INFO: Initializing Spark session...
[2025-01-24T15:16:13.090+0000] {spark_submit.py:579} INFO - 25/01/24 15:16:13 INFO SparkContext: Running Spark version 3.3.2
[2025-01-24T15:16:13.161+0000] {spark_submit.py:579} INFO - 25/01/24 15:16:13 INFO ResourceUtils: ==============================================================
[2025-01-24T15:16:13.163+0000] {spark_submit.py:579} INFO - 25/01/24 15:16:13 INFO ResourceUtils: No custom resources configured for spark.driver.
[2025-01-24T15:16:13.164+0000] {spark_submit.py:579} INFO - 25/01/24 15:16:13 INFO ResourceUtils: ==============================================================
[2025-01-24T15:16:13.165+0000] {spark_submit.py:579} INFO - 25/01/24 15:16:13 INFO SparkContext: Submitted application: CleanReview
[2025-01-24T15:16:13.203+0000] {spark_submit.py:579} INFO - 25/01/24 15:16:13 INFO ResourceProfile: Default ResourceProfile created, executor resources: Map(cores -> name: cores, amount: 2, script: , vendor: , memory -> name: memory, amount: 2048, script: , vendor: , offHeap -> name: offHeap, amount: 0, script: , vendor: ), task resources: Map(cpus -> name: cpus, amount: 1.0)
[2025-01-24T15:16:13.233+0000] {spark_submit.py:579} INFO - 25/01/24 15:16:13 INFO ResourceProfile: Limiting resource is cpus at 2 tasks per executor
[2025-01-24T15:16:13.237+0000] {spark_submit.py:579} INFO - 25/01/24 15:16:13 INFO ResourceProfileManager: Added ResourceProfile id: 0
[2025-01-24T15:16:13.414+0000] {spark_submit.py:579} INFO - 25/01/24 15:16:13 INFO SecurityManager: Changing view acls to: ***
[2025-01-24T15:16:13.435+0000] {spark_submit.py:579} INFO - 25/01/24 15:16:13 INFO SecurityManager: Changing modify acls to: ***
[2025-01-24T15:16:13.443+0000] {spark_submit.py:579} INFO - 25/01/24 15:16:13 INFO SecurityManager: Changing view acls groups to:
[2025-01-24T15:16:13.446+0000] {spark_submit.py:579} INFO - 25/01/24 15:16:13 INFO SecurityManager: Changing modify acls groups to:
[2025-01-24T15:16:13.451+0000] {spark_submit.py:579} INFO - 25/01/24 15:16:13 INFO SecurityManager: SecurityManager: authentication disabled; ui acls disabled; users  with view permissions: Set(***); groups with view permissions: Set(); users  with modify permissions: Set(***); groups with modify permissions: Set()
[2025-01-24T15:16:14.483+0000] {spark_submit.py:579} INFO - 25/01/24 15:16:14 INFO Utils: Successfully started service 'sparkDriver' on port 43035.
[2025-01-24T15:16:14.556+0000] {spark_submit.py:579} INFO - 25/01/24 15:16:14 INFO SparkEnv: Registering MapOutputTracker
[2025-01-24T15:16:14.689+0000] {spark_submit.py:579} INFO - 25/01/24 15:16:14 INFO SparkEnv: Registering BlockManagerMaster
[2025-01-24T15:16:14.769+0000] {spark_submit.py:579} INFO - 25/01/24 15:16:14 INFO BlockManagerMasterEndpoint: Using org.apache.spark.storage.DefaultTopologyMapper for getting topology information
[2025-01-24T15:16:14.772+0000] {spark_submit.py:579} INFO - 25/01/24 15:16:14 INFO BlockManagerMasterEndpoint: BlockManagerMasterEndpoint up
[2025-01-24T15:16:14.778+0000] {spark_submit.py:579} INFO - 25/01/24 15:16:14 INFO SparkEnv: Registering BlockManagerMasterHeartbeat
[2025-01-24T15:16:14.840+0000] {spark_submit.py:579} INFO - 25/01/24 15:16:14 INFO DiskBlockManager: Created local directory at /tmp/blockmgr-f6273295-e25e-4597-9a4f-7e4df45692cd
[2025-01-24T15:16:14.908+0000] {spark_submit.py:579} INFO - 25/01/24 15:16:14 INFO MemoryStore: MemoryStore started with capacity 434.4 MiB
[2025-01-24T15:16:14.957+0000] {spark_submit.py:579} INFO - 25/01/24 15:16:14 INFO SparkEnv: Registering OutputCommitCoordinator
[2025-01-24T15:16:15.705+0000] {spark_submit.py:579} INFO - 25/01/24 15:16:15 WARN Utils: Service 'SparkUI' could not bind on port 4040. Attempting port 4041.
[2025-01-24T15:16:15.706+0000] {spark_submit.py:579} INFO - 25/01/24 15:16:15 WARN Utils: Service 'SparkUI' could not bind on port 4041. Attempting port 4042.
[2025-01-24T15:16:15.707+0000] {spark_submit.py:579} INFO - 25/01/24 15:16:15 WARN Utils: Service 'SparkUI' could not bind on port 4042. Attempting port 4043.
[2025-01-24T15:16:15.744+0000] {spark_submit.py:579} INFO - 25/01/24 15:16:15 INFO Utils: Successfully started service 'SparkUI' on port 4043.
[2025-01-24T15:16:15.838+0000] {spark_submit.py:579} INFO - 25/01/24 15:16:15 INFO SparkContext: Added JAR file:///opt/***/jars/hadoop-aws-3.3.4.jar at spark://73fc507ad5e4:43035/jars/hadoop-aws-3.3.4.jar with timestamp 1737731773072
[2025-01-24T15:16:15.849+0000] {spark_submit.py:579} INFO - 25/01/24 15:16:15 INFO SparkContext: Added JAR file:///opt/***/jars/s3-2.18.41.jar at spark://73fc507ad5e4:43035/jars/s3-2.18.41.jar with timestamp 1737731773072
[2025-01-24T15:16:15.866+0000] {spark_submit.py:579} INFO - 25/01/24 15:16:15 INFO SparkContext: Added JAR file:///opt/***/jars/aws-java-sdk-bundle-1.12.262.jar at spark://73fc507ad5e4:43035/jars/aws-java-sdk-bundle-1.12.262.jar with timestamp 1737731773072
[2025-01-24T15:16:15.867+0000] {spark_submit.py:579} INFO - 25/01/24 15:16:15 INFO SparkContext: Added JAR file:///opt/***/jars/aws-java-sdk-1.12.367.jar at spark://73fc507ad5e4:43035/jars/aws-java-sdk-1.12.367.jar with timestamp 1737731773072
[2025-01-24T15:16:15.868+0000] {spark_submit.py:579} INFO - 25/01/24 15:16:15 INFO SparkContext: Added JAR file:///opt/***/jars/delta-core_2.12-2.2.0.jar at spark://73fc507ad5e4:43035/jars/delta-core_2.12-2.2.0.jar with timestamp 1737731773072
[2025-01-24T15:16:15.879+0000] {spark_submit.py:579} INFO - 25/01/24 15:16:15 INFO SparkContext: Added JAR file:///opt/***/jars/delta-storage-2.2.0.jar at spark://73fc507ad5e4:43035/jars/delta-storage-2.2.0.jar with timestamp 1737731773072
[2025-01-24T15:16:16.246+0000] {spark_submit.py:579} INFO - 25/01/24 15:16:16 INFO StandaloneAppClient$ClientEndpoint: Connecting to master spark://spark-master:7077...
[2025-01-24T15:16:16.419+0000] {spark_submit.py:579} INFO - 25/01/24 15:16:16 INFO TransportClientFactory: Successfully created connection to spark-master/172.18.0.7:7077 after 100 ms (0 ms spent in bootstraps)
[2025-01-24T15:16:16.633+0000] {spark_submit.py:579} INFO - 25/01/24 15:16:16 INFO StandaloneSchedulerBackend: Connected to Spark cluster with app ID app-20250124151616-0004
[2025-01-24T15:16:16.658+0000] {spark_submit.py:579} INFO - 25/01/24 15:16:16 INFO Utils: Successfully started service 'org.apache.spark.network.netty.NettyBlockTransferService' on port 38507.
[2025-01-24T15:16:16.659+0000] {spark_submit.py:579} INFO - 25/01/24 15:16:16 INFO NettyBlockTransferService: Server created on 73fc507ad5e4:38507
[2025-01-24T15:16:16.662+0000] {spark_submit.py:579} INFO - 25/01/24 15:16:16 INFO BlockManager: Using org.apache.spark.storage.RandomBlockReplicationPolicy for block replication policy
[2025-01-24T15:16:16.685+0000] {spark_submit.py:579} INFO - 25/01/24 15:16:16 INFO BlockManagerMaster: Registering BlockManager BlockManagerId(driver, 73fc507ad5e4, 38507, None)
[2025-01-24T15:16:16.697+0000] {spark_submit.py:579} INFO - 25/01/24 15:16:16 INFO BlockManagerMasterEndpoint: Registering block manager 73fc507ad5e4:38507 with 434.4 MiB RAM, BlockManagerId(driver, 73fc507ad5e4, 38507, None)
[2025-01-24T15:16:16.700+0000] {spark_submit.py:579} INFO - 25/01/24 15:16:16 INFO BlockManagerMaster: Registered BlockManager BlockManagerId(driver, 73fc507ad5e4, 38507, None)
[2025-01-24T15:16:16.704+0000] {spark_submit.py:579} INFO - 25/01/24 15:16:16 INFO BlockManager: Initialized BlockManager: BlockManagerId(driver, 73fc507ad5e4, 38507, None)
[2025-01-24T15:16:17.624+0000] {spark_submit.py:579} INFO - 25/01/24 15:16:17 INFO StandaloneSchedulerBackend: SchedulerBackend is ready for scheduling beginning after reached minRegisteredResourcesRatio: 0.0
[2025-01-24T15:16:18.131+0000] {spark_submit.py:579} INFO - 2025-01-24 15:16:18,131 INFO: Spark session initialized successfully.
[2025-01-24T15:16:18.132+0000] {spark_submit.py:579} INFO - 2025-01-24 15:16:18,131 INFO: Reading data from s3a://lakehouse/bronze/review.parquet
[2025-01-24T15:16:18.145+0000] {spark_submit.py:579} INFO - 25/01/24 15:16:18 INFO SharedState: Setting hive.metastore.warehouse.dir ('null') to the value of spark.sql.warehouse.dir.
[2025-01-24T15:16:18.159+0000] {spark_submit.py:579} INFO - 25/01/24 15:16:18 INFO SharedState: Warehouse path is 'file:/opt/***/spark-warehouse'.
[2025-01-24T15:16:21.471+0000] {spark_submit.py:579} INFO - 25/01/24 15:16:21 WARN MetricsConfig: Cannot locate configuration: tried hadoop-metrics2-s3a-file-system.properties,hadoop-metrics2.properties
[2025-01-24T15:16:21.504+0000] {spark_submit.py:579} INFO - 25/01/24 15:16:21 INFO MetricsSystemImpl: Scheduled Metric snapshot period at 10 second(s).
[2025-01-24T15:16:21.506+0000] {spark_submit.py:579} INFO - 25/01/24 15:16:21 INFO MetricsSystemImpl: s3a-file-system metrics system started
[2025-01-24T15:16:27.600+0000] {spark_submit.py:579} INFO - 25/01/24 15:16:27 INFO InMemoryFileIndex: It took 164 ms to list leaf files for 1 paths.
[2025-01-24T15:16:31.366+0000] {spark_submit.py:579} INFO - 2025-01-24 15:16:31,362 INFO: Cleaning data...
[2025-01-24T15:16:31.623+0000] {spark_submit.py:579} INFO - 2025-01-24 15:16:31,623 INFO: Saving cleaned data to s3a://lakehouse/silver/review
[2025-01-24T15:16:33.384+0000] {spark_submit.py:579} INFO - 25/01/24 15:16:33 INFO DeltaLog: Loading version 2.
[2025-01-24T15:16:33.595+0000] {spark_submit.py:579} INFO - 25/01/24 15:16:33 INFO Snapshot: [tableId=ca428307-b1f7-4b63-bb4c-465264774665] DELTA: Compute snapshot for version: 2
[2025-01-24T15:16:33.965+0000] {spark_submit.py:579} INFO - 25/01/24 15:16:33 INFO MemoryStore: Block broadcast_0 stored as values in memory (estimated size 202.8 KiB, free 434.2 MiB)
[2025-01-24T15:16:34.041+0000] {spark_submit.py:579} INFO - 25/01/24 15:16:34 INFO MemoryStore: Block broadcast_0_piece0 stored as bytes in memory (estimated size 35.1 KiB, free 434.2 MiB)
[2025-01-24T15:16:34.045+0000] {spark_submit.py:579} INFO - 25/01/24 15:16:34 INFO BlockManagerInfo: Added broadcast_0_piece0 in memory on 73fc507ad5e4:38507 (size: 35.1 KiB, free: 434.4 MiB)
[2025-01-24T15:16:34.051+0000] {spark_submit.py:579} INFO - 25/01/24 15:16:34 INFO SparkContext: Created broadcast 0 from toString at String.java:2951
[2025-01-24T15:16:34.090+0000] {spark_submit.py:579} INFO - 25/01/24 15:16:34 INFO DeltaLogFileIndex: Created DeltaLogFileIndex(JSON, numFilesInSegment: 3, totalFileSize: 5053)
[2025-01-24T15:16:36.605+0000] {spark_submit.py:579} INFO - 25/01/24 15:16:36 INFO FileSourceStrategy: Pushed Filters:
[2025-01-24T15:16:36.606+0000] {spark_submit.py:579} INFO - 25/01/24 15:16:36 INFO FileSourceStrategy: Post-Scan Filters:
[2025-01-24T15:16:36.609+0000] {spark_submit.py:579} INFO - 25/01/24 15:16:36 INFO FileSourceStrategy: Output Data Schema: struct<txn: struct<appId: string, version: bigint, lastUpdated: bigint ... 1 more fields>, add: struct<path: string, partitionValues: map<string,string>, size: bigint, modificationTime: bigint, dataChange: boolean ... 5 more fields>, remove: struct<path: string, deletionTimestamp: bigint, dataChange: boolean, extendedFileMetadata: boolean, partitionValues: map<string,string> ... 5 more fields>, metaData: struct<id: string, name: string, description: string, format: struct<provider: string, options: map<string,string>>, schemaString: string ... 6 more fields>, protocol: struct<minReaderVersion: int, minWriterVersion: int> ... 5 more fields>
[2025-01-24T15:16:36.720+0000] {spark_submit.py:579} INFO - 25/01/24 15:16:36 WARN package: Truncated the string representation of a plan since it was too large. This behavior can be adjusted by setting 'spark.sql.debug.maxToStringFields'.
[2025-01-24T15:16:38.074+0000] {spark_submit.py:579} INFO - 25/01/24 15:16:38 INFO CodeGenerator: Code generated in 759.410524 ms
[2025-01-24T15:16:38.085+0000] {spark_submit.py:579} INFO - 25/01/24 15:16:38 INFO MemoryStore: Block broadcast_1 stored as values in memory (estimated size 203.1 KiB, free 434.0 MiB)
[2025-01-24T15:16:38.120+0000] {spark_submit.py:579} INFO - 25/01/24 15:16:38 INFO MemoryStore: Block broadcast_1_piece0 stored as bytes in memory (estimated size 35.1 KiB, free 433.9 MiB)
[2025-01-24T15:16:38.121+0000] {spark_submit.py:579} INFO - 25/01/24 15:16:38 INFO BlockManagerInfo: Added broadcast_1_piece0 in memory on 73fc507ad5e4:38507 (size: 35.1 KiB, free: 434.3 MiB)
[2025-01-24T15:16:38.124+0000] {spark_submit.py:579} INFO - 25/01/24 15:16:38 INFO SparkContext: Created broadcast 1 from toString at String.java:2951
[2025-01-24T15:16:38.150+0000] {spark_submit.py:579} INFO - 25/01/24 15:16:38 INFO FileSourceScanExec: Planning scan with bin packing, max size: 6293982 bytes, open cost is considered as scanning 4194304 bytes.
[2025-01-24T15:16:38.522+0000] {spark_submit.py:579} INFO - 25/01/24 15:16:38 INFO DAGScheduler: Registering RDD 3 (toString at String.java:2951) as input to shuffle 0
[2025-01-24T15:16:38.530+0000] {spark_submit.py:579} INFO - 25/01/24 15:16:38 INFO DAGScheduler: Got map stage job 0 (toString at String.java:2951) with 2 output partitions
[2025-01-24T15:16:38.533+0000] {spark_submit.py:579} INFO - 25/01/24 15:16:38 INFO DAGScheduler: Final stage: ShuffleMapStage 0 (toString at String.java:2951)
[2025-01-24T15:16:38.534+0000] {spark_submit.py:579} INFO - 25/01/24 15:16:38 INFO DAGScheduler: Parents of final stage: List()
[2025-01-24T15:16:38.538+0000] {spark_submit.py:579} INFO - 25/01/24 15:16:38 INFO DAGScheduler: Missing parents: List()
[2025-01-24T15:16:38.555+0000] {spark_submit.py:579} INFO - 25/01/24 15:16:38 INFO DAGScheduler: Submitting ShuffleMapStage 0 (MapPartitionsRDD[3] at toString at String.java:2951), which has no missing parents
[2025-01-24T15:16:38.683+0000] {spark_submit.py:579} INFO - 25/01/24 15:16:38 INFO MemoryStore: Block broadcast_2 stored as values in memory (estimated size 124.3 KiB, free 433.8 MiB)
[2025-01-24T15:16:38.688+0000] {spark_submit.py:579} INFO - 25/01/24 15:16:38 INFO MemoryStore: Block broadcast_2_piece0 stored as bytes in memory (estimated size 35.1 KiB, free 433.8 MiB)
[2025-01-24T15:16:38.689+0000] {spark_submit.py:579} INFO - 25/01/24 15:16:38 INFO BlockManagerInfo: Added broadcast_2_piece0 in memory on 73fc507ad5e4:38507 (size: 35.1 KiB, free: 434.3 MiB)
[2025-01-24T15:16:38.690+0000] {spark_submit.py:579} INFO - 25/01/24 15:16:38 INFO SparkContext: Created broadcast 2 from broadcast at DAGScheduler.scala:1513
[2025-01-24T15:16:38.711+0000] {spark_submit.py:579} INFO - 25/01/24 15:16:38 INFO DAGScheduler: Submitting 2 missing tasks from ShuffleMapStage 0 (MapPartitionsRDD[3] at toString at String.java:2951) (first 15 tasks are for partitions Vector(0, 1))
[2025-01-24T15:16:38.712+0000] {spark_submit.py:579} INFO - 25/01/24 15:16:38 INFO TaskSchedulerImpl: Adding task set 0.0 with 2 tasks resource profile 0
[2025-01-24T15:16:53.741+0000] {spark_submit.py:579} INFO - 25/01/24 15:16:53 WARN TaskSchedulerImpl: Initial job has not accepted any resources; check your cluster UI to ensure that workers are registered and have sufficient resources
[2025-01-24T15:17:08.740+0000] {spark_submit.py:579} INFO - 25/01/24 15:17:08 WARN TaskSchedulerImpl: Initial job has not accepted any resources; check your cluster UI to ensure that workers are registered and have sufficient resources
[2025-01-24T15:17:23.740+0000] {spark_submit.py:579} INFO - 25/01/24 15:17:23 WARN TaskSchedulerImpl: Initial job has not accepted any resources; check your cluster UI to ensure that workers are registered and have sufficient resources
[2025-01-24T15:17:38.741+0000] {spark_submit.py:579} INFO - 25/01/24 15:17:38 WARN TaskSchedulerImpl: Initial job has not accepted any resources; check your cluster UI to ensure that workers are registered and have sufficient resources
[2025-01-24T15:17:53.740+0000] {spark_submit.py:579} INFO - 25/01/24 15:17:53 WARN TaskSchedulerImpl: Initial job has not accepted any resources; check your cluster UI to ensure that workers are registered and have sufficient resources
[2025-01-24T15:18:08.741+0000] {spark_submit.py:579} INFO - 25/01/24 15:18:08 WARN TaskSchedulerImpl: Initial job has not accepted any resources; check your cluster UI to ensure that workers are registered and have sufficient resources
[2025-01-24T15:18:12.041+0000] {spark_submit.py:579} INFO - 25/01/24 15:18:12 INFO StandaloneAppClient$ClientEndpoint: Executor added: app-20250124151616-0004/0 on worker-20250124151524-172.18.0.10-33905 (172.18.0.10:33905) with 2 core(s)
[2025-01-24T15:18:12.043+0000] {spark_submit.py:579} INFO - 25/01/24 15:18:12 INFO StandaloneSchedulerBackend: Granted executor ID app-20250124151616-0004/0 on hostPort 172.18.0.10:33905 with 2 core(s), 2.0 GiB RAM
[2025-01-24T15:18:12.110+0000] {spark_submit.py:579} INFO - 25/01/24 15:18:12 INFO StandaloneAppClient$ClientEndpoint: Executor updated: app-20250124151616-0004/0 is now RUNNING
[2025-01-24T15:18:13.871+0000] {spark_submit.py:579} INFO - 25/01/24 15:18:13 INFO CoarseGrainedSchedulerBackend$DriverEndpoint: Registered executor NettyRpcEndpointRef(spark-client://Executor) (172.18.0.10:48728) with ID 0,  ResourceProfileId 0
[2025-01-24T15:18:13.928+0000] {spark_submit.py:579} INFO - 25/01/24 15:18:13 INFO BlockManagerMasterEndpoint: Registering block manager 172.18.0.10:39675 with 1048.8 MiB RAM, BlockManagerId(0, 172.18.0.10, 39675, None)
[2025-01-24T15:18:15.823+0000] {spark_submit.py:579} INFO - 25/01/24 15:18:15 INFO TaskSetManager: Starting task 0.0 in stage 0.0 (TID 0) (172.18.0.10, executor 0, partition 0, PROCESS_LOCAL, 5042 bytes) taskResourceAssignments Map()
[2025-01-24T15:18:15.826+0000] {spark_submit.py:579} INFO - 25/01/24 15:18:15 INFO TaskSetManager: Starting task 1.0 in stage 0.0 (TID 1) (172.18.0.10, executor 0, partition 1, PROCESS_LOCAL, 4930 bytes) taskResourceAssignments Map()
[2025-01-24T15:18:16.032+0000] {spark_submit.py:579} INFO - 25/01/24 15:18:16 INFO BlockManagerInfo: Added broadcast_2_piece0 in memory on 172.18.0.10:39675 (size: 35.1 KiB, free: 1048.8 MiB)
[2025-01-24T15:18:17.117+0000] {spark_submit.py:579} INFO - 25/01/24 15:18:17 INFO BlockManagerInfo: Added broadcast_1_piece0 in memory on 172.18.0.10:39675 (size: 35.1 KiB, free: 1048.7 MiB)
[2025-01-24T15:18:18.662+0000] {spark_submit.py:579} INFO - 25/01/24 15:18:18 INFO TaskSetManager: Finished task 0.0 in stage 0.0 (TID 0) in 2847 ms on 172.18.0.10 (executor 0) (1/2)
[2025-01-24T15:18:18.664+0000] {spark_submit.py:579} INFO - 25/01/24 15:18:18 INFO TaskSetManager: Finished task 1.0 in stage 0.0 (TID 1) in 2838 ms on 172.18.0.10 (executor 0) (2/2)
[2025-01-24T15:18:18.666+0000] {spark_submit.py:579} INFO - 25/01/24 15:18:18 INFO TaskSchedulerImpl: Removed TaskSet 0.0, whose tasks have all completed, from pool
[2025-01-24T15:18:18.674+0000] {spark_submit.py:579} INFO - 25/01/24 15:18:18 INFO DAGScheduler: ShuffleMapStage 0 (toString at String.java:2951) finished in 100.099 s
[2025-01-24T15:18:18.675+0000] {spark_submit.py:579} INFO - 25/01/24 15:18:18 INFO DAGScheduler: looking for newly runnable stages
[2025-01-24T15:18:18.676+0000] {spark_submit.py:579} INFO - 25/01/24 15:18:18 INFO DAGScheduler: running: Set()
[2025-01-24T15:18:18.676+0000] {spark_submit.py:579} INFO - 25/01/24 15:18:18 INFO DAGScheduler: waiting: Set()
[2025-01-24T15:18:18.677+0000] {spark_submit.py:579} INFO - 25/01/24 15:18:18 INFO DAGScheduler: failed: Set()
[2025-01-24T15:18:18.861+0000] {spark_submit.py:579} INFO - 25/01/24 15:18:18 INFO BlockManagerInfo: Removed broadcast_2_piece0 on 73fc507ad5e4:38507 in memory (size: 35.1 KiB, free: 434.3 MiB)
[2025-01-24T15:18:18.866+0000] {spark_submit.py:579} INFO - 25/01/24 15:18:18 INFO BlockManagerInfo: Removed broadcast_2_piece0 on 172.18.0.10:39675 in memory (size: 35.1 KiB, free: 1048.8 MiB)
[2025-01-24T15:18:19.033+0000] {spark_submit.py:579} INFO - 25/01/24 15:18:19 INFO CodeGenerator: Generated method too long to be JIT compiled: org.apache.spark.sql.catalyst.expressions.GeneratedClass$GeneratedIteratorForCodegenStage3.serializefromobject_doConsume_0$ is 14899 bytes
[2025-01-24T15:18:19.034+0000] {spark_submit.py:579} INFO - 25/01/24 15:18:19 INFO CodeGenerator: Code generated in 189.821126 ms
[2025-01-24T15:18:19.122+0000] {spark_submit.py:579} INFO - 25/01/24 15:18:19 INFO CodeGenerator: Code generated in 64.788603 ms
[2025-01-24T15:18:19.487+0000] {spark_submit.py:579} INFO - 25/01/24 15:18:19 INFO CodeGenerator: Code generated in 39.311706 ms
[2025-01-24T15:18:19.496+0000] {spark_submit.py:579} INFO - 25/01/24 15:18:19 INFO DAGScheduler: Registering RDD 13 (toString at String.java:2951) as input to shuffle 1
[2025-01-24T15:18:19.497+0000] {spark_submit.py:579} INFO - 25/01/24 15:18:19 INFO DAGScheduler: Got map stage job 1 (toString at String.java:2951) with 50 output partitions
[2025-01-24T15:18:19.497+0000] {spark_submit.py:579} INFO - 25/01/24 15:18:19 INFO DAGScheduler: Final stage: ShuffleMapStage 2 (toString at String.java:2951)
[2025-01-24T15:18:19.498+0000] {spark_submit.py:579} INFO - 25/01/24 15:18:19 INFO DAGScheduler: Parents of final stage: List(ShuffleMapStage 1)
[2025-01-24T15:18:19.500+0000] {spark_submit.py:579} INFO - 25/01/24 15:18:19 INFO DAGScheduler: Missing parents: List()
[2025-01-24T15:18:19.502+0000] {spark_submit.py:579} INFO - 25/01/24 15:18:19 INFO DAGScheduler: Submitting ShuffleMapStage 2 (MapPartitionsRDD[13] at toString at String.java:2951), which has no missing parents
[2025-01-24T15:18:19.598+0000] {spark_submit.py:579} INFO - 25/01/24 15:18:19 INFO MemoryStore: Block broadcast_3 stored as values in memory (estimated size 425.0 KiB, free 433.5 MiB)
[2025-01-24T15:18:19.601+0000] {spark_submit.py:579} INFO - 25/01/24 15:18:19 INFO MemoryStore: Block broadcast_3_piece0 stored as bytes in memory (estimated size 102.2 KiB, free 433.4 MiB)
[2025-01-24T15:18:19.602+0000] {spark_submit.py:579} INFO - 25/01/24 15:18:19 INFO BlockManagerInfo: Added broadcast_3_piece0 in memory on 73fc507ad5e4:38507 (size: 102.2 KiB, free: 434.2 MiB)
[2025-01-24T15:18:19.602+0000] {spark_submit.py:579} INFO - 25/01/24 15:18:19 INFO SparkContext: Created broadcast 3 from broadcast at DAGScheduler.scala:1513
[2025-01-24T15:18:19.603+0000] {spark_submit.py:579} INFO - 25/01/24 15:18:19 INFO DAGScheduler: Submitting 50 missing tasks from ShuffleMapStage 2 (MapPartitionsRDD[13] at toString at String.java:2951) (first 15 tasks are for partitions Vector(0, 1, 2, 3, 4, 5, 6, 7, 8, 9, 10, 11, 12, 13, 14))
[2025-01-24T15:18:19.603+0000] {spark_submit.py:579} INFO - 25/01/24 15:18:19 INFO TaskSchedulerImpl: Adding task set 2.0 with 50 tasks resource profile 0
[2025-01-24T15:18:19.609+0000] {spark_submit.py:579} INFO - 25/01/24 15:18:19 INFO TaskSetManager: Starting task 10.0 in stage 2.0 (TID 2) (172.18.0.10, executor 0, partition 10, NODE_LOCAL, 4446 bytes) taskResourceAssignments Map()
[2025-01-24T15:18:19.610+0000] {spark_submit.py:579} INFO - 25/01/24 15:18:19 INFO TaskSetManager: Starting task 30.0 in stage 2.0 (TID 3) (172.18.0.10, executor 0, partition 30, NODE_LOCAL, 4446 bytes) taskResourceAssignments Map()
[2025-01-24T15:18:19.638+0000] {spark_submit.py:579} INFO - 25/01/24 15:18:19 INFO BlockManagerInfo: Added broadcast_3_piece0 in memory on 172.18.0.10:39675 (size: 102.2 KiB, free: 1048.7 MiB)
[2025-01-24T15:18:19.831+0000] {spark_submit.py:579} INFO - 25/01/24 15:18:19 INFO MapOutputTrackerMasterEndpoint: Asked to send map output locations for shuffle 0 to 172.18.0.10:48728
[2025-01-24T15:18:20.265+0000] {spark_submit.py:579} INFO - 25/01/24 15:18:20 INFO BlockManagerInfo: Added rdd_10_30 in memory on 172.18.0.10:39675 (size: 293.0 B, free: 1048.7 MiB)
[2025-01-24T15:18:20.265+0000] {spark_submit.py:579} INFO - 25/01/24 15:18:20 INFO BlockManagerInfo: Added rdd_10_10 in memory on 172.18.0.10:39675 (size: 477.0 B, free: 1048.7 MiB)
[2025-01-24T15:18:20.517+0000] {spark_submit.py:579} INFO - 25/01/24 15:18:20 INFO TaskSetManager: Starting task 33.0 in stage 2.0 (TID 4) (172.18.0.10, executor 0, partition 33, NODE_LOCAL, 4446 bytes) taskResourceAssignments Map()
[2025-01-24T15:18:20.523+0000] {spark_submit.py:579} INFO - 25/01/24 15:18:20 INFO TaskSetManager: Starting task 37.0 in stage 2.0 (TID 5) (172.18.0.10, executor 0, partition 37, NODE_LOCAL, 4446 bytes) taskResourceAssignments Map()
[2025-01-24T15:18:20.524+0000] {spark_submit.py:579} INFO - 25/01/24 15:18:20 INFO TaskSetManager: Finished task 10.0 in stage 2.0 (TID 2) in 916 ms on 172.18.0.10 (executor 0) (1/50)
[2025-01-24T15:18:20.525+0000] {spark_submit.py:579} INFO - 25/01/24 15:18:20 INFO TaskSetManager: Finished task 30.0 in stage 2.0 (TID 3) in 916 ms on 172.18.0.10 (executor 0) (2/50)
[2025-01-24T15:18:20.611+0000] {spark_submit.py:579} INFO - 25/01/24 15:18:20 INFO BlockManagerInfo: Added rdd_10_37 in memory on 172.18.0.10:39675 (size: 354.0 B, free: 1048.7 MiB)
[2025-01-24T15:18:20.622+0000] {spark_submit.py:579} INFO - 25/01/24 15:18:20 INFO BlockManagerInfo: Added rdd_10_33 in memory on 172.18.0.10:39675 (size: 564.0 B, free: 1048.7 MiB)
[2025-01-24T15:18:20.685+0000] {spark_submit.py:579} INFO - 25/01/24 15:18:20 INFO TaskSetManager: Starting task 42.0 in stage 2.0 (TID 6) (172.18.0.10, executor 0, partition 42, NODE_LOCAL, 4446 bytes) taskResourceAssignments Map()
[2025-01-24T15:18:20.686+0000] {spark_submit.py:579} INFO - 25/01/24 15:18:20 INFO TaskSetManager: Finished task 33.0 in stage 2.0 (TID 4) in 169 ms on 172.18.0.10 (executor 0) (3/50)
[2025-01-24T15:18:20.688+0000] {spark_submit.py:579} INFO - 25/01/24 15:18:20 INFO TaskSetManager: Starting task 0.0 in stage 2.0 (TID 7) (172.18.0.10, executor 0, partition 0, PROCESS_LOCAL, 4446 bytes) taskResourceAssignments Map()
[2025-01-24T15:18:20.690+0000] {spark_submit.py:579} INFO - 25/01/24 15:18:20 INFO TaskSetManager: Finished task 37.0 in stage 2.0 (TID 5) in 168 ms on 172.18.0.10 (executor 0) (4/50)
[2025-01-24T15:18:20.755+0000] {spark_submit.py:579} INFO - 25/01/24 15:18:20 INFO BlockManagerInfo: Added rdd_10_0 in memory on 172.18.0.10:39675 (size: 46.0 B, free: 1048.7 MiB)
[2025-01-24T15:18:20.793+0000] {spark_submit.py:579} INFO - 25/01/24 15:18:20 INFO TaskSetManager: Starting task 1.0 in stage 2.0 (TID 8) (172.18.0.10, executor 0, partition 1, PROCESS_LOCAL, 4446 bytes) taskResourceAssignments Map()
[2025-01-24T15:18:20.795+0000] {spark_submit.py:579} INFO - 25/01/24 15:18:20 INFO TaskSetManager: Finished task 0.0 in stage 2.0 (TID 7) in 108 ms on 172.18.0.10 (executor 0) (5/50)
[2025-01-24T15:18:20.869+0000] {spark_submit.py:579} INFO - 25/01/24 15:18:20 INFO BlockManagerInfo: Added rdd_10_1 in memory on 172.18.0.10:39675 (size: 46.0 B, free: 1048.7 MiB)
[2025-01-24T15:18:20.913+0000] {spark_submit.py:579} INFO - 25/01/24 15:18:20 INFO TaskSetManager: Starting task 2.0 in stage 2.0 (TID 9) (172.18.0.10, executor 0, partition 2, PROCESS_LOCAL, 4446 bytes) taskResourceAssignments Map()
[2025-01-24T15:18:20.914+0000] {spark_submit.py:579} INFO - 25/01/24 15:18:20 INFO TaskSetManager: Finished task 1.0 in stage 2.0 (TID 8) in 122 ms on 172.18.0.10 (executor 0) (6/50)
[2025-01-24T15:18:20.974+0000] {spark_submit.py:579} INFO - 25/01/24 15:18:20 INFO BlockManagerInfo: Added rdd_10_2 in memory on 172.18.0.10:39675 (size: 46.0 B, free: 1048.7 MiB)
[2025-01-24T15:18:20.992+0000] {spark_submit.py:579} INFO - 25/01/24 15:18:20 INFO BlockManagerInfo: Added rdd_10_42 in memory on 172.18.0.10:39675 (size: 448.0 B, free: 1048.7 MiB)
[2025-01-24T15:18:21.015+0000] {spark_submit.py:579} INFO - 25/01/24 15:18:21 INFO TaskSetManager: Starting task 3.0 in stage 2.0 (TID 10) (172.18.0.10, executor 0, partition 3, PROCESS_LOCAL, 4446 bytes) taskResourceAssignments Map()
[2025-01-24T15:18:21.016+0000] {spark_submit.py:579} INFO - 25/01/24 15:18:21 INFO TaskSetManager: Finished task 2.0 in stage 2.0 (TID 9) in 104 ms on 172.18.0.10 (executor 0) (7/50)
[2025-01-24T15:18:21.028+0000] {spark_submit.py:579} INFO - 25/01/24 15:18:21 INFO TaskSetManager: Starting task 4.0 in stage 2.0 (TID 11) (172.18.0.10, executor 0, partition 4, PROCESS_LOCAL, 4446 bytes) taskResourceAssignments Map()
[2025-01-24T15:18:21.029+0000] {spark_submit.py:579} INFO - 25/01/24 15:18:21 INFO TaskSetManager: Finished task 42.0 in stage 2.0 (TID 6) in 345 ms on 172.18.0.10 (executor 0) (8/50)
[2025-01-24T15:18:21.079+0000] {spark_submit.py:579} INFO - 25/01/24 15:18:21 INFO BlockManagerInfo: Added rdd_10_3 in memory on 172.18.0.10:39675 (size: 46.0 B, free: 1048.7 MiB)
[2025-01-24T15:18:21.080+0000] {spark_submit.py:579} INFO - 25/01/24 15:18:21 INFO BlockManagerInfo: Added rdd_10_4 in memory on 172.18.0.10:39675 (size: 46.0 B, free: 1048.7 MiB)
[2025-01-24T15:18:21.116+0000] {spark_submit.py:579} INFO - 25/01/24 15:18:21 INFO TaskSetManager: Starting task 5.0 in stage 2.0 (TID 12) (172.18.0.10, executor 0, partition 5, PROCESS_LOCAL, 4446 bytes) taskResourceAssignments Map()
[2025-01-24T15:18:21.118+0000] {spark_submit.py:579} INFO - 25/01/24 15:18:21 INFO TaskSetManager: Finished task 3.0 in stage 2.0 (TID 10) in 103 ms on 172.18.0.10 (executor 0) (9/50)
[2025-01-24T15:18:21.137+0000] {spark_submit.py:579} INFO - 25/01/24 15:18:21 INFO TaskSetManager: Starting task 6.0 in stage 2.0 (TID 13) (172.18.0.10, executor 0, partition 6, PROCESS_LOCAL, 4446 bytes) taskResourceAssignments Map()
[2025-01-24T15:18:21.138+0000] {spark_submit.py:579} INFO - 25/01/24 15:18:21 INFO TaskSetManager: Finished task 4.0 in stage 2.0 (TID 11) in 109 ms on 172.18.0.10 (executor 0) (10/50)
[2025-01-24T15:18:21.184+0000] {spark_submit.py:579} INFO - 25/01/24 15:18:21 INFO BlockManagerInfo: Added rdd_10_5 in memory on 172.18.0.10:39675 (size: 46.0 B, free: 1048.7 MiB)
[2025-01-24T15:18:21.204+0000] {spark_submit.py:579} INFO - 25/01/24 15:18:21 INFO BlockManagerInfo: Added rdd_10_6 in memory on 172.18.0.10:39675 (size: 46.0 B, free: 1048.7 MiB)
[2025-01-24T15:18:21.232+0000] {spark_submit.py:579} INFO - 25/01/24 15:18:21 INFO TaskSetManager: Starting task 7.0 in stage 2.0 (TID 14) (172.18.0.10, executor 0, partition 7, PROCESS_LOCAL, 4446 bytes) taskResourceAssignments Map()
[2025-01-24T15:18:21.233+0000] {spark_submit.py:579} INFO - 25/01/24 15:18:21 INFO TaskSetManager: Finished task 5.0 in stage 2.0 (TID 12) in 116 ms on 172.18.0.10 (executor 0) (11/50)
[2025-01-24T15:18:21.238+0000] {spark_submit.py:579} INFO - 25/01/24 15:18:21 INFO TaskSetManager: Starting task 8.0 in stage 2.0 (TID 15) (172.18.0.10, executor 0, partition 8, PROCESS_LOCAL, 4446 bytes) taskResourceAssignments Map()
[2025-01-24T15:18:21.239+0000] {spark_submit.py:579} INFO - 25/01/24 15:18:21 INFO TaskSetManager: Finished task 6.0 in stage 2.0 (TID 13) in 104 ms on 172.18.0.10 (executor 0) (12/50)
[2025-01-24T15:18:21.282+0000] {spark_submit.py:579} INFO - 25/01/24 15:18:21 INFO BlockManagerInfo: Added rdd_10_8 in memory on 172.18.0.10:39675 (size: 46.0 B, free: 1048.7 MiB)
[2025-01-24T15:18:21.289+0000] {spark_submit.py:579} INFO - 25/01/24 15:18:21 INFO BlockManagerInfo: Added rdd_10_7 in memory on 172.18.0.10:39675 (size: 46.0 B, free: 1048.7 MiB)
[2025-01-24T15:18:21.309+0000] {spark_submit.py:579} INFO - 25/01/24 15:18:21 INFO TaskSetManager: Starting task 9.0 in stage 2.0 (TID 16) (172.18.0.10, executor 0, partition 9, PROCESS_LOCAL, 4446 bytes) taskResourceAssignments Map()
[2025-01-24T15:18:21.310+0000] {spark_submit.py:579} INFO - 25/01/24 15:18:21 INFO TaskSetManager: Finished task 8.0 in stage 2.0 (TID 15) in 72 ms on 172.18.0.10 (executor 0) (13/50)
[2025-01-24T15:18:21.318+0000] {spark_submit.py:579} INFO - 25/01/24 15:18:21 INFO TaskSetManager: Starting task 11.0 in stage 2.0 (TID 17) (172.18.0.10, executor 0, partition 11, PROCESS_LOCAL, 4446 bytes) taskResourceAssignments Map()
[2025-01-24T15:18:21.319+0000] {spark_submit.py:579} INFO - 25/01/24 15:18:21 INFO TaskSetManager: Finished task 7.0 in stage 2.0 (TID 14) in 87 ms on 172.18.0.10 (executor 0) (14/50)
[2025-01-24T15:18:21.380+0000] {spark_submit.py:579} INFO - 25/01/24 15:18:21 INFO BlockManagerInfo: Added rdd_10_9 in memory on 172.18.0.10:39675 (size: 46.0 B, free: 1048.7 MiB)
[2025-01-24T15:18:21.385+0000] {spark_submit.py:579} INFO - 25/01/24 15:18:21 INFO BlockManagerInfo: Added rdd_10_11 in memory on 172.18.0.10:39675 (size: 46.0 B, free: 1048.7 MiB)
[2025-01-24T15:18:21.411+0000] {spark_submit.py:579} INFO - 25/01/24 15:18:21 INFO TaskSetManager: Finished task 9.0 in stage 2.0 (TID 16) in 100 ms on 172.18.0.10 (executor 0) (15/50)
[2025-01-24T15:18:21.412+0000] {spark_submit.py:579} INFO - 25/01/24 15:18:21 INFO TaskSetManager: Starting task 12.0 in stage 2.0 (TID 18) (172.18.0.10, executor 0, partition 12, PROCESS_LOCAL, 4446 bytes) taskResourceAssignments Map()
[2025-01-24T15:18:21.415+0000] {spark_submit.py:579} INFO - 25/01/24 15:18:21 INFO TaskSetManager: Starting task 13.0 in stage 2.0 (TID 19) (172.18.0.10, executor 0, partition 13, PROCESS_LOCAL, 4446 bytes) taskResourceAssignments Map()
[2025-01-24T15:18:21.418+0000] {spark_submit.py:579} INFO - 25/01/24 15:18:21 INFO TaskSetManager: Finished task 11.0 in stage 2.0 (TID 17) in 99 ms on 172.18.0.10 (executor 0) (16/50)
[2025-01-24T15:18:21.463+0000] {spark_submit.py:579} INFO - 25/01/24 15:18:21 INFO BlockManagerInfo: Added rdd_10_12 in memory on 172.18.0.10:39675 (size: 46.0 B, free: 1048.7 MiB)
[2025-01-24T15:18:21.470+0000] {spark_submit.py:579} INFO - 25/01/24 15:18:21 INFO BlockManagerInfo: Added rdd_10_13 in memory on 172.18.0.10:39675 (size: 46.0 B, free: 1048.7 MiB)
[2025-01-24T15:18:21.491+0000] {spark_submit.py:579} INFO - 25/01/24 15:18:21 INFO TaskSetManager: Starting task 14.0 in stage 2.0 (TID 20) (172.18.0.10, executor 0, partition 14, PROCESS_LOCAL, 4446 bytes) taskResourceAssignments Map()
[2025-01-24T15:18:21.492+0000] {spark_submit.py:579} INFO - 25/01/24 15:18:21 INFO TaskSetManager: Finished task 12.0 in stage 2.0 (TID 18) in 81 ms on 172.18.0.10 (executor 0) (17/50)
[2025-01-24T15:18:21.494+0000] {spark_submit.py:579} INFO - 25/01/24 15:18:21 INFO TaskSetManager: Starting task 15.0 in stage 2.0 (TID 21) (172.18.0.10, executor 0, partition 15, PROCESS_LOCAL, 4446 bytes) taskResourceAssignments Map()
[2025-01-24T15:18:21.495+0000] {spark_submit.py:579} INFO - 25/01/24 15:18:21 INFO TaskSetManager: Finished task 13.0 in stage 2.0 (TID 19) in 80 ms on 172.18.0.10 (executor 0) (18/50)
[2025-01-24T15:18:21.532+0000] {spark_submit.py:579} INFO - 25/01/24 15:18:21 INFO BlockManagerInfo: Added rdd_10_15 in memory on 172.18.0.10:39675 (size: 46.0 B, free: 1048.7 MiB)
[2025-01-24T15:18:21.533+0000] {spark_submit.py:579} INFO - 25/01/24 15:18:21 INFO BlockManagerInfo: Added rdd_10_14 in memory on 172.18.0.10:39675 (size: 46.0 B, free: 1048.7 MiB)
[2025-01-24T15:18:21.555+0000] {spark_submit.py:579} INFO - 25/01/24 15:18:21 INFO TaskSetManager: Starting task 16.0 in stage 2.0 (TID 22) (172.18.0.10, executor 0, partition 16, PROCESS_LOCAL, 4446 bytes) taskResourceAssignments Map()
[2025-01-24T15:18:21.556+0000] {spark_submit.py:579} INFO - 25/01/24 15:18:21 INFO TaskSetManager: Finished task 14.0 in stage 2.0 (TID 20) in 65 ms on 172.18.0.10 (executor 0) (19/50)
[2025-01-24T15:18:21.557+0000] {spark_submit.py:579} INFO - 25/01/24 15:18:21 INFO TaskSetManager: Finished task 15.0 in stage 2.0 (TID 21) in 62 ms on 172.18.0.10 (executor 0) (20/50)
[2025-01-24T15:18:21.558+0000] {spark_submit.py:579} INFO - 25/01/24 15:18:21 INFO TaskSetManager: Starting task 17.0 in stage 2.0 (TID 23) (172.18.0.10, executor 0, partition 17, PROCESS_LOCAL, 4446 bytes) taskResourceAssignments Map()
[2025-01-24T15:18:21.602+0000] {spark_submit.py:579} INFO - 25/01/24 15:18:21 INFO BlockManagerInfo: Added rdd_10_17 in memory on 172.18.0.10:39675 (size: 46.0 B, free: 1048.7 MiB)
[2025-01-24T15:18:21.606+0000] {spark_submit.py:579} INFO - 25/01/24 15:18:21 INFO BlockManagerInfo: Added rdd_10_16 in memory on 172.18.0.10:39675 (size: 46.0 B, free: 1048.7 MiB)
[2025-01-24T15:18:21.627+0000] {spark_submit.py:579} INFO - 25/01/24 15:18:21 INFO TaskSetManager: Starting task 18.0 in stage 2.0 (TID 24) (172.18.0.10, executor 0, partition 18, PROCESS_LOCAL, 4446 bytes) taskResourceAssignments Map()
[2025-01-24T15:18:21.629+0000] {spark_submit.py:579} INFO - 25/01/24 15:18:21 INFO TaskSetManager: Finished task 16.0 in stage 2.0 (TID 22) in 73 ms on 172.18.0.10 (executor 0) (21/50)
[2025-01-24T15:18:21.630+0000] {spark_submit.py:579} INFO - 25/01/24 15:18:21 INFO TaskSetManager: Starting task 19.0 in stage 2.0 (TID 25) (172.18.0.10, executor 0, partition 19, PROCESS_LOCAL, 4446 bytes) taskResourceAssignments Map()
[2025-01-24T15:18:21.631+0000] {spark_submit.py:579} INFO - 25/01/24 15:18:21 INFO TaskSetManager: Finished task 17.0 in stage 2.0 (TID 23) in 72 ms on 172.18.0.10 (executor 0) (22/50)
[2025-01-24T15:18:21.691+0000] {spark_submit.py:579} INFO - 25/01/24 15:18:21 INFO BlockManagerInfo: Added rdd_10_18 in memory on 172.18.0.10:39675 (size: 46.0 B, free: 1048.7 MiB)
[2025-01-24T15:18:21.692+0000] {spark_submit.py:579} INFO - 25/01/24 15:18:21 INFO BlockManagerInfo: Added rdd_10_19 in memory on 172.18.0.10:39675 (size: 46.0 B, free: 1048.7 MiB)
[2025-01-24T15:18:21.725+0000] {spark_submit.py:579} INFO - 25/01/24 15:18:21 INFO TaskSetManager: Starting task 20.0 in stage 2.0 (TID 26) (172.18.0.10, executor 0, partition 20, PROCESS_LOCAL, 4446 bytes) taskResourceAssignments Map()
[2025-01-24T15:18:21.727+0000] {spark_submit.py:579} INFO - 25/01/24 15:18:21 INFO TaskSetManager: Finished task 18.0 in stage 2.0 (TID 24) in 100 ms on 172.18.0.10 (executor 0) (23/50)
[2025-01-24T15:18:21.740+0000] {spark_submit.py:579} INFO - 25/01/24 15:18:21 INFO TaskSetManager: Starting task 21.0 in stage 2.0 (TID 27) (172.18.0.10, executor 0, partition 21, PROCESS_LOCAL, 4446 bytes) taskResourceAssignments Map()
[2025-01-24T15:18:21.752+0000] {spark_submit.py:579} INFO - 25/01/24 15:18:21 INFO TaskSetManager: Finished task 19.0 in stage 2.0 (TID 25) in 117 ms on 172.18.0.10 (executor 0) (24/50)
[2025-01-24T15:18:21.806+0000] {spark_submit.py:579} INFO - 25/01/24 15:18:21 INFO BlockManagerInfo: Added rdd_10_21 in memory on 172.18.0.10:39675 (size: 46.0 B, free: 1048.7 MiB)
[2025-01-24T15:18:21.809+0000] {spark_submit.py:579} INFO - 25/01/24 15:18:21 INFO BlockManagerInfo: Added rdd_10_20 in memory on 172.18.0.10:39675 (size: 46.0 B, free: 1048.7 MiB)
[2025-01-24T15:18:21.840+0000] {spark_submit.py:579} INFO - 25/01/24 15:18:21 INFO TaskSetManager: Starting task 22.0 in stage 2.0 (TID 28) (172.18.0.10, executor 0, partition 22, PROCESS_LOCAL, 4446 bytes) taskResourceAssignments Map()
[2025-01-24T15:18:21.849+0000] {spark_submit.py:579} INFO - 25/01/24 15:18:21 INFO TaskSetManager: Finished task 21.0 in stage 2.0 (TID 27) in 95 ms on 172.18.0.10 (executor 0) (25/50)
[2025-01-24T15:18:21.851+0000] {spark_submit.py:579} INFO - 25/01/24 15:18:21 INFO TaskSetManager: Starting task 23.0 in stage 2.0 (TID 29) (172.18.0.10, executor 0, partition 23, PROCESS_LOCAL, 4446 bytes) taskResourceAssignments Map()
[2025-01-24T15:18:21.852+0000] {spark_submit.py:579} INFO - 25/01/24 15:18:21 INFO TaskSetManager: Finished task 20.0 in stage 2.0 (TID 26) in 119 ms on 172.18.0.10 (executor 0) (26/50)
[2025-01-24T15:18:21.893+0000] {spark_submit.py:579} INFO - 25/01/24 15:18:21 INFO BlockManagerInfo: Added rdd_10_22 in memory on 172.18.0.10:39675 (size: 46.0 B, free: 1048.7 MiB)
[2025-01-24T15:18:21.895+0000] {spark_submit.py:579} INFO - 25/01/24 15:18:21 INFO BlockManagerInfo: Added rdd_10_23 in memory on 172.18.0.10:39675 (size: 46.0 B, free: 1048.7 MiB)
[2025-01-24T15:18:21.925+0000] {spark_submit.py:579} INFO - 25/01/24 15:18:21 INFO TaskSetManager: Starting task 24.0 in stage 2.0 (TID 30) (172.18.0.10, executor 0, partition 24, PROCESS_LOCAL, 4446 bytes) taskResourceAssignments Map()
[2025-01-24T15:18:21.925+0000] {spark_submit.py:579} INFO - 25/01/24 15:18:21 INFO TaskSetManager: Finished task 23.0 in stage 2.0 (TID 29) in 83 ms on 172.18.0.10 (executor 0) (27/50)
[2025-01-24T15:18:21.949+0000] {spark_submit.py:579} INFO - 25/01/24 15:18:21 INFO TaskSetManager: Starting task 25.0 in stage 2.0 (TID 31) (172.18.0.10, executor 0, partition 25, PROCESS_LOCAL, 4446 bytes) taskResourceAssignments Map()
[2025-01-24T15:18:21.950+0000] {spark_submit.py:579} INFO - 25/01/24 15:18:21 INFO TaskSetManager: Finished task 22.0 in stage 2.0 (TID 28) in 117 ms on 172.18.0.10 (executor 0) (28/50)
[2025-01-24T15:18:21.990+0000] {spark_submit.py:579} INFO - 25/01/24 15:18:21 INFO BlockManagerInfo: Added rdd_10_24 in memory on 172.18.0.10:39675 (size: 46.0 B, free: 1048.7 MiB)
[2025-01-24T15:18:21.999+0000] {spark_submit.py:579} INFO - 25/01/24 15:18:21 INFO BlockManagerInfo: Added rdd_10_25 in memory on 172.18.0.10:39675 (size: 46.0 B, free: 1048.7 MiB)
[2025-01-24T15:18:22.016+0000] {spark_submit.py:579} INFO - 25/01/24 15:18:22 INFO TaskSetManager: Starting task 26.0 in stage 2.0 (TID 32) (172.18.0.10, executor 0, partition 26, PROCESS_LOCAL, 4446 bytes) taskResourceAssignments Map()
[2025-01-24T15:18:22.017+0000] {spark_submit.py:579} INFO - 25/01/24 15:18:22 INFO TaskSetManager: Finished task 24.0 in stage 2.0 (TID 30) in 90 ms on 172.18.0.10 (executor 0) (29/50)
[2025-01-24T15:18:22.037+0000] {spark_submit.py:579} INFO - 25/01/24 15:18:22 INFO TaskSetManager: Starting task 27.0 in stage 2.0 (TID 33) (172.18.0.10, executor 0, partition 27, PROCESS_LOCAL, 4446 bytes) taskResourceAssignments Map()
[2025-01-24T15:18:22.040+0000] {spark_submit.py:579} INFO - 25/01/24 15:18:22 INFO TaskSetManager: Finished task 25.0 in stage 2.0 (TID 31) in 86 ms on 172.18.0.10 (executor 0) (30/50)
[2025-01-24T15:18:22.056+0000] {spark_submit.py:579} INFO - 25/01/24 15:18:22 INFO BlockManagerInfo: Added rdd_10_26 in memory on 172.18.0.10:39675 (size: 46.0 B, free: 1048.7 MiB)
[2025-01-24T15:18:22.079+0000] {spark_submit.py:579} INFO - 25/01/24 15:18:22 INFO TaskSetManager: Starting task 28.0 in stage 2.0 (TID 34) (172.18.0.10, executor 0, partition 28, PROCESS_LOCAL, 4446 bytes) taskResourceAssignments Map()
[2025-01-24T15:18:22.080+0000] {spark_submit.py:579} INFO - 25/01/24 15:18:22 INFO TaskSetManager: Finished task 26.0 in stage 2.0 (TID 32) in 66 ms on 172.18.0.10 (executor 0) (31/50)
[2025-01-24T15:18:22.095+0000] {spark_submit.py:579} INFO - 25/01/24 15:18:22 INFO BlockManagerInfo: Added rdd_10_27 in memory on 172.18.0.10:39675 (size: 46.0 B, free: 1048.7 MiB)
[2025-01-24T15:18:22.114+0000] {spark_submit.py:579} INFO - 25/01/24 15:18:22 INFO TaskSetManager: Starting task 29.0 in stage 2.0 (TID 35) (172.18.0.10, executor 0, partition 29, PROCESS_LOCAL, 4446 bytes) taskResourceAssignments Map()
[2025-01-24T15:18:22.115+0000] {spark_submit.py:579} INFO - 25/01/24 15:18:22 INFO TaskSetManager: Finished task 27.0 in stage 2.0 (TID 33) in 82 ms on 172.18.0.10 (executor 0) (32/50)
[2025-01-24T15:18:22.121+0000] {spark_submit.py:579} INFO - 25/01/24 15:18:22 INFO BlockManagerInfo: Added rdd_10_28 in memory on 172.18.0.10:39675 (size: 46.0 B, free: 1048.7 MiB)
[2025-01-24T15:18:22.141+0000] {spark_submit.py:579} INFO - 25/01/24 15:18:22 INFO TaskSetManager: Starting task 31.0 in stage 2.0 (TID 36) (172.18.0.10, executor 0, partition 31, PROCESS_LOCAL, 4446 bytes) taskResourceAssignments Map()
[2025-01-24T15:18:22.142+0000] {spark_submit.py:579} INFO - 25/01/24 15:18:22 INFO TaskSetManager: Finished task 28.0 in stage 2.0 (TID 34) in 63 ms on 172.18.0.10 (executor 0) (33/50)
[2025-01-24T15:18:22.155+0000] {spark_submit.py:579} INFO - 25/01/24 15:18:22 INFO BlockManagerInfo: Added rdd_10_29 in memory on 172.18.0.10:39675 (size: 46.0 B, free: 1048.7 MiB)
[2025-01-24T15:18:22.178+0000] {spark_submit.py:579} INFO - 25/01/24 15:18:22 INFO TaskSetManager: Starting task 32.0 in stage 2.0 (TID 37) (172.18.0.10, executor 0, partition 32, PROCESS_LOCAL, 4446 bytes) taskResourceAssignments Map()
[2025-01-24T15:18:22.180+0000] {spark_submit.py:579} INFO - 25/01/24 15:18:22 INFO TaskSetManager: Finished task 29.0 in stage 2.0 (TID 35) in 65 ms on 172.18.0.10 (executor 0) (34/50)
[2025-01-24T15:18:22.193+0000] {spark_submit.py:579} INFO - 25/01/24 15:18:22 INFO BlockManagerInfo: Added rdd_10_31 in memory on 172.18.0.10:39675 (size: 46.0 B, free: 1048.7 MiB)
[2025-01-24T15:18:22.227+0000] {spark_submit.py:579} INFO - 25/01/24 15:18:22 INFO TaskSetManager: Starting task 34.0 in stage 2.0 (TID 38) (172.18.0.10, executor 0, partition 34, PROCESS_LOCAL, 4446 bytes) taskResourceAssignments Map()
[2025-01-24T15:18:22.228+0000] {spark_submit.py:579} INFO - 25/01/24 15:18:22 INFO TaskSetManager: Finished task 31.0 in stage 2.0 (TID 36) in 87 ms on 172.18.0.10 (executor 0) (35/50)
[2025-01-24T15:18:22.232+0000] {spark_submit.py:579} INFO - 25/01/24 15:18:22 INFO BlockManagerInfo: Added rdd_10_32 in memory on 172.18.0.10:39675 (size: 46.0 B, free: 1048.7 MiB)
[2025-01-24T15:18:22.258+0000] {spark_submit.py:579} INFO - 25/01/24 15:18:22 INFO TaskSetManager: Starting task 35.0 in stage 2.0 (TID 39) (172.18.0.10, executor 0, partition 35, PROCESS_LOCAL, 4446 bytes) taskResourceAssignments Map()
[2025-01-24T15:18:22.260+0000] {spark_submit.py:579} INFO - 25/01/24 15:18:22 INFO TaskSetManager: Finished task 32.0 in stage 2.0 (TID 37) in 83 ms on 172.18.0.10 (executor 0) (36/50)
[2025-01-24T15:18:22.276+0000] {spark_submit.py:579} INFO - 25/01/24 15:18:22 INFO BlockManagerInfo: Added rdd_10_34 in memory on 172.18.0.10:39675 (size: 46.0 B, free: 1048.7 MiB)
[2025-01-24T15:18:22.301+0000] {spark_submit.py:579} INFO - 25/01/24 15:18:22 INFO TaskSetManager: Starting task 36.0 in stage 2.0 (TID 40) (172.18.0.10, executor 0, partition 36, PROCESS_LOCAL, 4446 bytes) taskResourceAssignments Map()
[2025-01-24T15:18:22.302+0000] {spark_submit.py:579} INFO - 25/01/24 15:18:22 INFO TaskSetManager: Finished task 34.0 in stage 2.0 (TID 38) in 75 ms on 172.18.0.10 (executor 0) (37/50)
[2025-01-24T15:18:22.303+0000] {spark_submit.py:579} INFO - 25/01/24 15:18:22 INFO BlockManagerInfo: Added rdd_10_35 in memory on 172.18.0.10:39675 (size: 46.0 B, free: 1048.7 MiB)
[2025-01-24T15:18:22.329+0000] {spark_submit.py:579} INFO - 25/01/24 15:18:22 INFO TaskSetManager: Starting task 38.0 in stage 2.0 (TID 41) (172.18.0.10, executor 0, partition 38, PROCESS_LOCAL, 4446 bytes) taskResourceAssignments Map()
[2025-01-24T15:18:22.331+0000] {spark_submit.py:579} INFO - 25/01/24 15:18:22 INFO TaskSetManager: Finished task 35.0 in stage 2.0 (TID 39) in 73 ms on 172.18.0.10 (executor 0) (38/50)
[2025-01-24T15:18:22.351+0000] {spark_submit.py:579} INFO - 25/01/24 15:18:22 INFO BlockManagerInfo: Added rdd_10_36 in memory on 172.18.0.10:39675 (size: 46.0 B, free: 1048.7 MiB)
[2025-01-24T15:18:22.372+0000] {spark_submit.py:579} INFO - 25/01/24 15:18:22 INFO TaskSetManager: Starting task 39.0 in stage 2.0 (TID 42) (172.18.0.10, executor 0, partition 39, PROCESS_LOCAL, 4446 bytes) taskResourceAssignments Map()
[2025-01-24T15:18:22.374+0000] {spark_submit.py:579} INFO - 25/01/24 15:18:22 INFO TaskSetManager: Finished task 36.0 in stage 2.0 (TID 40) in 73 ms on 172.18.0.10 (executor 0) (39/50)
[2025-01-24T15:18:22.390+0000] {spark_submit.py:579} INFO - 25/01/24 15:18:22 INFO BlockManagerInfo: Added rdd_10_38 in memory on 172.18.0.10:39675 (size: 46.0 B, free: 1048.7 MiB)
[2025-01-24T15:18:22.416+0000] {spark_submit.py:579} INFO - 25/01/24 15:18:22 INFO BlockManagerInfo: Added rdd_10_39 in memory on 172.18.0.10:39675 (size: 46.0 B, free: 1048.7 MiB)
[2025-01-24T15:18:22.431+0000] {spark_submit.py:579} INFO - 25/01/24 15:18:22 INFO TaskSetManager: Starting task 40.0 in stage 2.0 (TID 43) (172.18.0.10, executor 0, partition 40, PROCESS_LOCAL, 4446 bytes) taskResourceAssignments Map()
[2025-01-24T15:18:22.434+0000] {spark_submit.py:579} INFO - 25/01/24 15:18:22 INFO TaskSetManager: Finished task 38.0 in stage 2.0 (TID 41) in 100 ms on 172.18.0.10 (executor 0) (40/50)
[2025-01-24T15:18:22.440+0000] {spark_submit.py:579} INFO - 25/01/24 15:18:22 INFO TaskSetManager: Starting task 41.0 in stage 2.0 (TID 44) (172.18.0.10, executor 0, partition 41, PROCESS_LOCAL, 4446 bytes) taskResourceAssignments Map()
[2025-01-24T15:18:22.441+0000] {spark_submit.py:579} INFO - 25/01/24 15:18:22 INFO TaskSetManager: Finished task 39.0 in stage 2.0 (TID 42) in 67 ms on 172.18.0.10 (executor 0) (41/50)
[2025-01-24T15:18:22.480+0000] {spark_submit.py:579} INFO - 25/01/24 15:18:22 INFO BlockManagerInfo: Added rdd_10_40 in memory on 172.18.0.10:39675 (size: 46.0 B, free: 1048.7 MiB)
[2025-01-24T15:18:22.482+0000] {spark_submit.py:579} INFO - 25/01/24 15:18:22 INFO BlockManagerInfo: Added rdd_10_41 in memory on 172.18.0.10:39675 (size: 46.0 B, free: 1048.7 MiB)
[2025-01-24T15:18:22.498+0000] {spark_submit.py:579} INFO - 25/01/24 15:18:22 INFO TaskSetManager: Starting task 43.0 in stage 2.0 (TID 45) (172.18.0.10, executor 0, partition 43, PROCESS_LOCAL, 4446 bytes) taskResourceAssignments Map()
[2025-01-24T15:18:22.499+0000] {spark_submit.py:579} INFO - 25/01/24 15:18:22 INFO TaskSetManager: Finished task 41.0 in stage 2.0 (TID 44) in 62 ms on 172.18.0.10 (executor 0) (42/50)
[2025-01-24T15:18:22.500+0000] {spark_submit.py:579} INFO - 25/01/24 15:18:22 INFO TaskSetManager: Starting task 44.0 in stage 2.0 (TID 46) (172.18.0.10, executor 0, partition 44, PROCESS_LOCAL, 4446 bytes) taskResourceAssignments Map()
[2025-01-24T15:18:22.507+0000] {spark_submit.py:579} INFO - 25/01/24 15:18:22 INFO TaskSetManager: Finished task 40.0 in stage 2.0 (TID 43) in 72 ms on 172.18.0.10 (executor 0) (43/50)
[2025-01-24T15:18:22.529+0000] {spark_submit.py:579} INFO - 25/01/24 15:18:22 INFO BlockManagerInfo: Added rdd_10_43 in memory on 172.18.0.10:39675 (size: 46.0 B, free: 1048.7 MiB)
[2025-01-24T15:18:22.533+0000] {spark_submit.py:579} INFO - 25/01/24 15:18:22 INFO BlockManagerInfo: Added rdd_10_44 in memory on 172.18.0.10:39675 (size: 46.0 B, free: 1048.7 MiB)
[2025-01-24T15:18:22.549+0000] {spark_submit.py:579} INFO - 25/01/24 15:18:22 INFO TaskSetManager: Starting task 45.0 in stage 2.0 (TID 47) (172.18.0.10, executor 0, partition 45, PROCESS_LOCAL, 4446 bytes) taskResourceAssignments Map()
[2025-01-24T15:18:22.550+0000] {spark_submit.py:579} INFO - 25/01/24 15:18:22 INFO TaskSetManager: Finished task 43.0 in stage 2.0 (TID 45) in 52 ms on 172.18.0.10 (executor 0) (44/50)
[2025-01-24T15:18:22.551+0000] {spark_submit.py:579} INFO - 25/01/24 15:18:22 INFO TaskSetManager: Starting task 46.0 in stage 2.0 (TID 48) (172.18.0.10, executor 0, partition 46, PROCESS_LOCAL, 4446 bytes) taskResourceAssignments Map()
[2025-01-24T15:18:22.551+0000] {spark_submit.py:579} INFO - 25/01/24 15:18:22 INFO TaskSetManager: Finished task 44.0 in stage 2.0 (TID 46) in 52 ms on 172.18.0.10 (executor 0) (45/50)
[2025-01-24T15:18:22.580+0000] {spark_submit.py:579} INFO - 25/01/24 15:18:22 INFO BlockManagerInfo: Added rdd_10_45 in memory on 172.18.0.10:39675 (size: 46.0 B, free: 1048.7 MiB)
[2025-01-24T15:18:22.585+0000] {spark_submit.py:579} INFO - 25/01/24 15:18:22 INFO BlockManagerInfo: Added rdd_10_46 in memory on 172.18.0.10:39675 (size: 46.0 B, free: 1048.7 MiB)
[2025-01-24T15:18:22.596+0000] {spark_submit.py:579} INFO - 25/01/24 15:18:22 INFO TaskSetManager: Starting task 47.0 in stage 2.0 (TID 49) (172.18.0.10, executor 0, partition 47, PROCESS_LOCAL, 4446 bytes) taskResourceAssignments Map()
[2025-01-24T15:18:22.597+0000] {spark_submit.py:579} INFO - 25/01/24 15:18:22 INFO TaskSetManager: Finished task 45.0 in stage 2.0 (TID 47) in 50 ms on 172.18.0.10 (executor 0) (46/50)
[2025-01-24T15:18:22.600+0000] {spark_submit.py:579} INFO - 25/01/24 15:18:22 INFO TaskSetManager: Starting task 48.0 in stage 2.0 (TID 50) (172.18.0.10, executor 0, partition 48, PROCESS_LOCAL, 4446 bytes) taskResourceAssignments Map()
[2025-01-24T15:18:22.601+0000] {spark_submit.py:579} INFO - 25/01/24 15:18:22 INFO TaskSetManager: Finished task 46.0 in stage 2.0 (TID 48) in 51 ms on 172.18.0.10 (executor 0) (47/50)
[2025-01-24T15:18:22.626+0000] {spark_submit.py:579} INFO - 25/01/24 15:18:22 INFO BlockManagerInfo: Added rdd_10_47 in memory on 172.18.0.10:39675 (size: 46.0 B, free: 1048.7 MiB)
[2025-01-24T15:18:22.631+0000] {spark_submit.py:579} INFO - 25/01/24 15:18:22 INFO BlockManagerInfo: Added rdd_10_48 in memory on 172.18.0.10:39675 (size: 46.0 B, free: 1048.7 MiB)
[2025-01-24T15:18:22.641+0000] {spark_submit.py:579} INFO - 25/01/24 15:18:22 INFO TaskSetManager: Starting task 49.0 in stage 2.0 (TID 51) (172.18.0.10, executor 0, partition 49, PROCESS_LOCAL, 4446 bytes) taskResourceAssignments Map()
[2025-01-24T15:18:22.642+0000] {spark_submit.py:579} INFO - 25/01/24 15:18:22 INFO TaskSetManager: Finished task 47.0 in stage 2.0 (TID 49) in 45 ms on 172.18.0.10 (executor 0) (48/50)
[2025-01-24T15:18:22.651+0000] {spark_submit.py:579} INFO - 25/01/24 15:18:22 INFO TaskSetManager: Finished task 48.0 in stage 2.0 (TID 50) in 51 ms on 172.18.0.10 (executor 0) (49/50)
[2025-01-24T15:18:22.671+0000] {spark_submit.py:579} INFO - 25/01/24 15:18:22 INFO BlockManagerInfo: Added rdd_10_49 in memory on 172.18.0.10:39675 (size: 46.0 B, free: 1048.7 MiB)
[2025-01-24T15:18:22.686+0000] {spark_submit.py:579} INFO - 25/01/24 15:18:22 INFO TaskSetManager: Finished task 49.0 in stage 2.0 (TID 51) in 44 ms on 172.18.0.10 (executor 0) (50/50)
[2025-01-24T15:18:22.686+0000] {spark_submit.py:579} INFO - 25/01/24 15:18:22 INFO TaskSchedulerImpl: Removed TaskSet 2.0, whose tasks have all completed, from pool
[2025-01-24T15:18:22.687+0000] {spark_submit.py:579} INFO - 25/01/24 15:18:22 INFO DAGScheduler: ShuffleMapStage 2 (toString at String.java:2951) finished in 3.175 s
[2025-01-24T15:18:22.687+0000] {spark_submit.py:579} INFO - 25/01/24 15:18:22 INFO DAGScheduler: looking for newly runnable stages
[2025-01-24T15:18:22.688+0000] {spark_submit.py:579} INFO - 25/01/24 15:18:22 INFO DAGScheduler: running: Set()
[2025-01-24T15:18:22.688+0000] {spark_submit.py:579} INFO - 25/01/24 15:18:22 INFO DAGScheduler: waiting: Set()
[2025-01-24T15:18:22.688+0000] {spark_submit.py:579} INFO - 25/01/24 15:18:22 INFO DAGScheduler: failed: Set()
[2025-01-24T15:18:22.722+0000] {spark_submit.py:579} INFO - 25/01/24 15:18:22 INFO SparkContext: Starting job: toString at String.java:2951
[2025-01-24T15:18:22.724+0000] {spark_submit.py:579} INFO - 25/01/24 15:18:22 INFO DAGScheduler: Got job 2 (toString at String.java:2951) with 1 output partitions
[2025-01-24T15:18:22.725+0000] {spark_submit.py:579} INFO - 25/01/24 15:18:22 INFO DAGScheduler: Final stage: ResultStage 5 (toString at String.java:2951)
[2025-01-24T15:18:22.725+0000] {spark_submit.py:579} INFO - 25/01/24 15:18:22 INFO DAGScheduler: Parents of final stage: List(ShuffleMapStage 4)
[2025-01-24T15:18:22.726+0000] {spark_submit.py:579} INFO - 25/01/24 15:18:22 INFO DAGScheduler: Missing parents: List()
[2025-01-24T15:18:22.727+0000] {spark_submit.py:579} INFO - 25/01/24 15:18:22 INFO DAGScheduler: Submitting ResultStage 5 (MapPartitionsRDD[16] at toString at String.java:2951), which has no missing parents
[2025-01-24T15:18:22.733+0000] {spark_submit.py:579} INFO - 25/01/24 15:18:22 INFO MemoryStore: Block broadcast_4 stored as values in memory (estimated size 371.0 KiB, free 433.1 MiB)
[2025-01-24T15:18:22.739+0000] {spark_submit.py:579} INFO - 25/01/24 15:18:22 INFO MemoryStore: Block broadcast_4_piece0 stored as bytes in memory (estimated size 91.2 KiB, free 433.0 MiB)
[2025-01-24T15:18:22.740+0000] {spark_submit.py:579} INFO - 25/01/24 15:18:22 INFO BlockManagerInfo: Added broadcast_4_piece0 in memory on 73fc507ad5e4:38507 (size: 91.2 KiB, free: 434.1 MiB)
[2025-01-24T15:18:22.741+0000] {spark_submit.py:579} INFO - 25/01/24 15:18:22 INFO SparkContext: Created broadcast 4 from broadcast at DAGScheduler.scala:1513
[2025-01-24T15:18:22.742+0000] {spark_submit.py:579} INFO - 25/01/24 15:18:22 INFO DAGScheduler: Submitting 1 missing tasks from ResultStage 5 (MapPartitionsRDD[16] at toString at String.java:2951) (first 15 tasks are for partitions Vector(0))
[2025-01-24T15:18:22.743+0000] {spark_submit.py:579} INFO - 25/01/24 15:18:22 INFO TaskSchedulerImpl: Adding task set 5.0 with 1 tasks resource profile 0
[2025-01-24T15:18:22.744+0000] {spark_submit.py:579} INFO - 25/01/24 15:18:22 INFO TaskSetManager: Starting task 0.0 in stage 5.0 (TID 52) (172.18.0.10, executor 0, partition 0, NODE_LOCAL, 4457 bytes) taskResourceAssignments Map()
[2025-01-24T15:18:22.757+0000] {spark_submit.py:579} INFO - 25/01/24 15:18:22 INFO BlockManagerInfo: Added broadcast_4_piece0 in memory on 172.18.0.10:39675 (size: 91.2 KiB, free: 1048.6 MiB)
[2025-01-24T15:18:22.794+0000] {spark_submit.py:579} INFO - 25/01/24 15:18:22 INFO MapOutputTrackerMasterEndpoint: Asked to send map output locations for shuffle 1 to 172.18.0.10:48728
[2025-01-24T15:18:22.804+0000] {spark_submit.py:579} INFO - 25/01/24 15:18:22 INFO BlockManagerInfo: Removed broadcast_3_piece0 on 73fc507ad5e4:38507 in memory (size: 102.2 KiB, free: 434.2 MiB)
[2025-01-24T15:18:22.806+0000] {spark_submit.py:579} INFO - 25/01/24 15:18:22 INFO BlockManagerInfo: Removed broadcast_3_piece0 on 172.18.0.10:39675 in memory (size: 102.2 KiB, free: 1048.7 MiB)
[2025-01-24T15:18:22.881+0000] {spark_submit.py:579} INFO - 25/01/24 15:18:22 INFO TaskSetManager: Finished task 0.0 in stage 5.0 (TID 52) in 137 ms on 172.18.0.10 (executor 0) (1/1)
[2025-01-24T15:18:22.882+0000] {spark_submit.py:579} INFO - 25/01/24 15:18:22 INFO TaskSchedulerImpl: Removed TaskSet 5.0, whose tasks have all completed, from pool
[2025-01-24T15:18:22.882+0000] {spark_submit.py:579} INFO - 25/01/24 15:18:22 INFO DAGScheduler: ResultStage 5 (toString at String.java:2951) finished in 0.153 s
[2025-01-24T15:18:22.884+0000] {spark_submit.py:579} INFO - 25/01/24 15:18:22 INFO DAGScheduler: Job 2 is finished. Cancelling potential speculative or zombie tasks for this job
[2025-01-24T15:18:22.884+0000] {spark_submit.py:579} INFO - 25/01/24 15:18:22 INFO TaskSchedulerImpl: Killing all running tasks in stage 5: Stage finished
[2025-01-24T15:18:22.886+0000] {spark_submit.py:579} INFO - 25/01/24 15:18:22 INFO DAGScheduler: Job 2 finished: toString at String.java:2951, took 0.163724 s
[2025-01-24T15:18:22.959+0000] {spark_submit.py:579} INFO - 25/01/24 15:18:22 INFO CodeGenerator: Code generated in 38.678351 ms
[2025-01-24T15:18:22.966+0000] {spark_submit.py:579} INFO - 25/01/24 15:18:22 INFO Snapshot: [tableId=68163a48-8bd8-405c-8d44-581c09e8e255] DELTA: Done
[2025-01-24T15:18:22.968+0000] {spark_submit.py:579} INFO - 25/01/24 15:18:22 INFO Snapshot: [tableId=49755799-c87e-43c0-8610-b4b09bafd9bd] Created snapshot Snapshot(path=s3a://lakehouse/silver/review/_delta_log, version=2, metadata=Metadata(9c0a6154-fdc0-46b7-add1-7196294bc6bb,null,null,Format(parquet,Map()),{"type":"struct","fields":[{"name":"review","type":"string","nullable":true,"metadata":{}},{"name":"sentiment","type":"string","nullable":true,"metadata":{}}]},List(),Map(),Some(1737605879724)), logSegment=LogSegment(s3a://lakehouse/silver/review/_delta_log,2,WrappedArray(S3AFileStatus{path=s3a://lakehouse/silver/review/_delta_log/00000000000000000000.json; isDirectory=false; length=1689; replication=1; blocksize=33554432; modification_time=1737605889730; access_time=0; owner=***; group=***; permission=rw-rw-rw-; isSymlink=false; hasAcl=false; isEncrypted=true; isErasureCoded=false} isEmptyDirectory=FALSE eTag=61aaea5a111f6bd401d0977dcad4a236 versionId=null, S3AFileStatus{path=s3a://lakehouse/silver/review/_delta_log/00000000000000000001.json; isDirectory=false; length=1682; replication=1; blocksize=33554432; modification_time=1737606122221; access_time=0; owner=***; group=***; permission=rw-rw-rw-; isSymlink=false; hasAcl=false; isEncrypted=true; isErasureCoded=false} isEmptyDirectory=FALSE eTag=27ef9f7d939e8d749c7981332e327d56 versionId=null, S3AFileStatus{path=s3a://lakehouse/silver/review/_delta_log/00000000000000000002.json; isDirectory=false; length=1682; replication=1; blocksize=33554432; modification_time=1737606212274; access_time=0; owner=***; group=***; permission=rw-rw-rw-; isSymlink=false; hasAcl=false; isEncrypted=true; isErasureCoded=false} isEmptyDirectory=FALSE eTag=55c45ea6edd81754dffaf88ba151893f versionId=null),List(),None,1737606212274), checksumOpt=None)
[2025-01-24T15:18:23.237+0000] {spark_submit.py:579} INFO - 25/01/24 15:18:23 INFO FileSourceStrategy: Pushed Filters:
[2025-01-24T15:18:23.238+0000] {spark_submit.py:579} INFO - 25/01/24 15:18:23 INFO FileSourceStrategy: Post-Scan Filters: atleastnnonnulls(2, review#0, sentiment#1)
[2025-01-24T15:18:23.238+0000] {spark_submit.py:579} INFO - 25/01/24 15:18:23 INFO FileSourceStrategy: Output Data Schema: struct<review: string, sentiment: string>
[2025-01-24T15:18:23.299+0000] {spark_submit.py:579} INFO - 25/01/24 15:18:23 INFO DeltaParquetFileFormat: Using default output committer for Parquet: org.apache.parquet.hadoop.ParquetOutputCommitter
[2025-01-24T15:18:23.317+0000] {spark_submit.py:579} INFO - 25/01/24 15:18:23 INFO HashAggregateExec: spark.sql.codegen.aggregate.map.twolevel.enabled is set to true, but current version of codegened fast hashmap does not support this aggregate.
[2025-01-24T15:18:23.362+0000] {spark_submit.py:579} INFO - 25/01/24 15:18:23 INFO CodeGenerator: Code generated in 26.040266 ms
[2025-01-24T15:18:23.372+0000] {spark_submit.py:579} INFO - 25/01/24 15:18:23 INFO MemoryStore: Block broadcast_5 stored as values in memory (estimated size 204.7 KiB, free 433.3 MiB)
[2025-01-24T15:18:23.380+0000] {spark_submit.py:579} INFO - 25/01/24 15:18:23 INFO MemoryStore: Block broadcast_5_piece0 stored as bytes in memory (estimated size 35.6 KiB, free 433.2 MiB)
[2025-01-24T15:18:23.382+0000] {spark_submit.py:579} INFO - 25/01/24 15:18:23 INFO BlockManagerInfo: Added broadcast_5_piece0 in memory on 73fc507ad5e4:38507 (size: 35.6 KiB, free: 434.2 MiB)
[2025-01-24T15:18:23.384+0000] {spark_submit.py:579} INFO - 25/01/24 15:18:23 INFO SparkContext: Created broadcast 5 from save at NativeMethodAccessorImpl.java:0
[2025-01-24T15:18:23.394+0000] {spark_submit.py:579} INFO - 25/01/24 15:18:23 INFO FileSourceScanExec: Planning scan with bin packing, max size: 23437026 bytes, open cost is considered as scanning 4194304 bytes.
[2025-01-24T15:18:23.420+0000] {spark_submit.py:579} INFO - 25/01/24 15:18:23 INFO DAGScheduler: Registering RDD 20 (save at NativeMethodAccessorImpl.java:0) as input to shuffle 2
[2025-01-24T15:18:23.421+0000] {spark_submit.py:579} INFO - 25/01/24 15:18:23 INFO DAGScheduler: Got map stage job 3 (save at NativeMethodAccessorImpl.java:0) with 2 output partitions
[2025-01-24T15:18:23.422+0000] {spark_submit.py:579} INFO - 25/01/24 15:18:23 INFO DAGScheduler: Final stage: ShuffleMapStage 6 (save at NativeMethodAccessorImpl.java:0)
[2025-01-24T15:18:23.422+0000] {spark_submit.py:579} INFO - 25/01/24 15:18:23 INFO DAGScheduler: Parents of final stage: List()
[2025-01-24T15:18:23.423+0000] {spark_submit.py:579} INFO - 25/01/24 15:18:23 INFO DAGScheduler: Missing parents: List()
[2025-01-24T15:18:23.424+0000] {spark_submit.py:579} INFO - 25/01/24 15:18:23 INFO DAGScheduler: Submitting ShuffleMapStage 6 (MapPartitionsRDD[20] at save at NativeMethodAccessorImpl.java:0), which has no missing parents
[2025-01-24T15:18:23.427+0000] {spark_submit.py:579} INFO - 25/01/24 15:18:23 INFO MemoryStore: Block broadcast_6 stored as values in memory (estimated size 26.0 KiB, free 433.2 MiB)
[2025-01-24T15:18:23.429+0000] {spark_submit.py:579} INFO - 25/01/24 15:18:23 INFO MemoryStore: Block broadcast_6_piece0 stored as bytes in memory (estimated size 11.3 KiB, free 433.2 MiB)
[2025-01-24T15:18:23.432+0000] {spark_submit.py:579} INFO - 25/01/24 15:18:23 INFO BlockManagerInfo: Added broadcast_6_piece0 in memory on 73fc507ad5e4:38507 (size: 11.3 KiB, free: 434.2 MiB)
[2025-01-24T15:18:23.433+0000] {spark_submit.py:579} INFO - 25/01/24 15:18:23 INFO SparkContext: Created broadcast 6 from broadcast at DAGScheduler.scala:1513
[2025-01-24T15:18:23.433+0000] {spark_submit.py:579} INFO - 25/01/24 15:18:23 INFO DAGScheduler: Submitting 2 missing tasks from ShuffleMapStage 6 (MapPartitionsRDD[20] at save at NativeMethodAccessorImpl.java:0) (first 15 tasks are for partitions Vector(0, 1))
[2025-01-24T15:18:23.434+0000] {spark_submit.py:579} INFO - 25/01/24 15:18:23 INFO TaskSchedulerImpl: Adding task set 6.0 with 2 tasks resource profile 0
[2025-01-24T15:18:23.435+0000] {spark_submit.py:579} INFO - 25/01/24 15:18:23 INFO TaskSetManager: Starting task 0.0 in stage 6.0 (TID 53) (172.18.0.10, executor 0, partition 0, PROCESS_LOCAL, 4901 bytes) taskResourceAssignments Map()
[2025-01-24T15:18:23.436+0000] {spark_submit.py:579} INFO - 25/01/24 15:18:23 INFO TaskSetManager: Starting task 1.0 in stage 6.0 (TID 54) (172.18.0.10, executor 0, partition 1, PROCESS_LOCAL, 4901 bytes) taskResourceAssignments Map()
[2025-01-24T15:18:23.455+0000] {spark_submit.py:579} INFO - 25/01/24 15:18:23 INFO BlockManagerInfo: Added broadcast_6_piece0 in memory on 172.18.0.10:39675 (size: 11.3 KiB, free: 1048.7 MiB)
[2025-01-24T15:18:23.559+0000] {spark_submit.py:579} INFO - 25/01/24 15:18:23 INFO BlockManagerInfo: Added broadcast_5_piece0 in memory on 172.18.0.10:39675 (size: 35.6 KiB, free: 1048.6 MiB)
[2025-01-24T15:18:23.835+0000] {spark_submit.py:579} INFO - 25/01/24 15:18:23 INFO TaskSetManager: Finished task 1.0 in stage 6.0 (TID 54) in 400 ms on 172.18.0.10 (executor 0) (1/2)
[2025-01-24T15:18:24.787+0000] {spark_submit.py:579} INFO - 25/01/24 15:18:24 INFO TaskSetManager: Finished task 0.0 in stage 6.0 (TID 53) in 1353 ms on 172.18.0.10 (executor 0) (2/2)
[2025-01-24T15:18:24.788+0000] {spark_submit.py:579} INFO - 25/01/24 15:18:24 INFO TaskSchedulerImpl: Removed TaskSet 6.0, whose tasks have all completed, from pool
[2025-01-24T15:18:24.789+0000] {spark_submit.py:579} INFO - 25/01/24 15:18:24 INFO DAGScheduler: ShuffleMapStage 6 (save at NativeMethodAccessorImpl.java:0) finished in 1.365 s
[2025-01-24T15:18:24.789+0000] {spark_submit.py:579} INFO - 25/01/24 15:18:24 INFO DAGScheduler: looking for newly runnable stages
[2025-01-24T15:18:24.790+0000] {spark_submit.py:579} INFO - 25/01/24 15:18:24 INFO DAGScheduler: running: Set()
[2025-01-24T15:18:24.790+0000] {spark_submit.py:579} INFO - 25/01/24 15:18:24 INFO DAGScheduler: waiting: Set()
[2025-01-24T15:18:24.790+0000] {spark_submit.py:579} INFO - 25/01/24 15:18:24 INFO DAGScheduler: failed: Set()
[2025-01-24T15:18:24.796+0000] {spark_submit.py:579} INFO - 25/01/24 15:18:24 INFO ShufflePartitionsUtil: For shuffle(2), advisory target size: 67108864, actual target size 23459326, minimum partition size: 1048576
[2025-01-24T15:18:24.811+0000] {spark_submit.py:579} INFO - 25/01/24 15:18:24 INFO HashAggregateExec: spark.sql.codegen.aggregate.map.twolevel.enabled is set to true, but current version of codegened fast hashmap does not support this aggregate.
[2025-01-24T15:18:24.822+0000] {spark_submit.py:579} INFO - 25/01/24 15:18:24 INFO CodeGenerator: Code generated in 8.342907 ms
[2025-01-24T15:18:24.872+0000] {spark_submit.py:579} INFO - 25/01/24 15:18:24 INFO SparkContext: Starting job: save at NativeMethodAccessorImpl.java:0
[2025-01-24T15:18:24.873+0000] {spark_submit.py:579} INFO - 25/01/24 15:18:24 INFO DAGScheduler: Got job 4 (save at NativeMethodAccessorImpl.java:0) with 2 output partitions
[2025-01-24T15:18:24.874+0000] {spark_submit.py:579} INFO - 25/01/24 15:18:24 INFO DAGScheduler: Final stage: ResultStage 8 (save at NativeMethodAccessorImpl.java:0)
[2025-01-24T15:18:24.875+0000] {spark_submit.py:579} INFO - 25/01/24 15:18:24 INFO DAGScheduler: Parents of final stage: List(ShuffleMapStage 7)
[2025-01-24T15:18:24.875+0000] {spark_submit.py:579} INFO - 25/01/24 15:18:24 INFO DAGScheduler: Missing parents: List()
[2025-01-24T15:18:24.875+0000] {spark_submit.py:579} INFO - 25/01/24 15:18:24 INFO DAGScheduler: Submitting ResultStage 8 (MapPartitionsRDD[22] at save at NativeMethodAccessorImpl.java:0), which has no missing parents
[2025-01-24T15:18:24.897+0000] {spark_submit.py:579} INFO - 25/01/24 15:18:24 INFO MemoryStore: Block broadcast_7 stored as values in memory (estimated size 348.8 KiB, free 432.9 MiB)
[2025-01-24T15:18:24.911+0000] {spark_submit.py:579} INFO - 25/01/24 15:18:24 INFO MemoryStore: Block broadcast_7_piece0 stored as bytes in memory (estimated size 126.1 KiB, free 432.7 MiB)
[2025-01-24T15:18:24.912+0000] {spark_submit.py:579} INFO - 25/01/24 15:18:24 INFO BlockManagerInfo: Removed broadcast_4_piece0 on 73fc507ad5e4:38507 in memory (size: 91.2 KiB, free: 434.3 MiB)
[2025-01-24T15:18:24.920+0000] {spark_submit.py:579} INFO - 25/01/24 15:18:24 INFO BlockManagerInfo: Removed broadcast_4_piece0 on 172.18.0.10:39675 in memory (size: 91.2 KiB, free: 1048.7 MiB)
[2025-01-24T15:18:24.921+0000] {spark_submit.py:579} INFO - 25/01/24 15:18:24 INFO BlockManagerInfo: Added broadcast_7_piece0 in memory on 73fc507ad5e4:38507 (size: 126.1 KiB, free: 434.2 MiB)
[2025-01-24T15:18:24.921+0000] {spark_submit.py:579} INFO - 25/01/24 15:18:24 INFO SparkContext: Created broadcast 7 from broadcast at DAGScheduler.scala:1513
[2025-01-24T15:18:24.922+0000] {spark_submit.py:579} INFO - 25/01/24 15:18:24 INFO DAGScheduler: Submitting 2 missing tasks from ResultStage 8 (MapPartitionsRDD[22] at save at NativeMethodAccessorImpl.java:0) (first 15 tasks are for partitions Vector(0, 1))
[2025-01-24T15:18:24.923+0000] {spark_submit.py:579} INFO - 25/01/24 15:18:24 INFO TaskSchedulerImpl: Adding task set 8.0 with 2 tasks resource profile 0
[2025-01-24T15:18:24.924+0000] {spark_submit.py:579} INFO - 25/01/24 15:18:24 INFO TaskSetManager: Starting task 0.0 in stage 8.0 (TID 55) (172.18.0.10, executor 0, partition 0, NODE_LOCAL, 4457 bytes) taskResourceAssignments Map()
[2025-01-24T15:18:24.924+0000] {spark_submit.py:579} INFO - 25/01/24 15:18:24 INFO TaskSetManager: Starting task 1.0 in stage 8.0 (TID 56) (172.18.0.10, executor 0, partition 1, NODE_LOCAL, 4457 bytes) taskResourceAssignments Map()
[2025-01-24T15:18:24.971+0000] {spark_submit.py:579} INFO - 25/01/24 15:18:24 INFO BlockManagerInfo: Removed broadcast_6_piece0 on 73fc507ad5e4:38507 in memory (size: 11.3 KiB, free: 434.2 MiB)
[2025-01-24T15:18:24.971+0000] {spark_submit.py:579} INFO - 25/01/24 15:18:24 INFO BlockManagerInfo: Added broadcast_7_piece0 in memory on 172.18.0.10:39675 (size: 126.1 KiB, free: 1048.6 MiB)
[2025-01-24T15:18:24.972+0000] {spark_submit.py:579} INFO - 25/01/24 15:18:24 INFO BlockManagerInfo: Removed broadcast_6_piece0 on 172.18.0.10:39675 in memory (size: 11.3 KiB, free: 1048.6 MiB)
[2025-01-24T15:18:25.042+0000] {spark_submit.py:579} INFO - 25/01/24 15:18:25 INFO MapOutputTrackerMasterEndpoint: Asked to send map output locations for shuffle 2 to 172.18.0.10:48728
[2025-01-24T15:18:26.043+0000] {spark_submit.py:579} INFO - 25/01/24 15:18:26 INFO TaskSetManager: Finished task 0.0 in stage 8.0 (TID 55) in 1120 ms on 172.18.0.10 (executor 0) (1/2)
[2025-01-24T15:18:26.048+0000] {spark_submit.py:579} INFO - 25/01/24 15:18:26 INFO TaskSetManager: Finished task 1.0 in stage 8.0 (TID 56) in 1123 ms on 172.18.0.10 (executor 0) (2/2)
[2025-01-24T15:18:26.048+0000] {spark_submit.py:579} INFO - 25/01/24 15:18:26 INFO TaskSchedulerImpl: Removed TaskSet 8.0, whose tasks have all completed, from pool
[2025-01-24T15:18:26.049+0000] {spark_submit.py:579} INFO - 25/01/24 15:18:26 INFO DAGScheduler: ResultStage 8 (save at NativeMethodAccessorImpl.java:0) finished in 1.169 s
[2025-01-24T15:18:26.049+0000] {spark_submit.py:579} INFO - 25/01/24 15:18:26 INFO DAGScheduler: Job 4 is finished. Cancelling potential speculative or zombie tasks for this job
[2025-01-24T15:18:26.050+0000] {spark_submit.py:579} INFO - 25/01/24 15:18:26 INFO TaskSchedulerImpl: Killing all running tasks in stage 8: Stage finished
[2025-01-24T15:18:26.050+0000] {spark_submit.py:579} INFO - 25/01/24 15:18:26 INFO DAGScheduler: Job 4 finished: save at NativeMethodAccessorImpl.java:0, took 1.177036 s
[2025-01-24T15:18:26.051+0000] {spark_submit.py:579} INFO - 25/01/24 15:18:26 INFO FileFormatWriter: Start to commit write Job cd198c39-52e1-4ab5-8c19-1f92bc4f055a.
[2025-01-24T15:18:26.053+0000] {spark_submit.py:579} INFO - 25/01/24 15:18:26 INFO FileFormatWriter: Write Job cd198c39-52e1-4ab5-8c19-1f92bc4f055a committed. Elapsed time: 1 ms.
[2025-01-24T15:18:26.056+0000] {spark_submit.py:579} INFO - 25/01/24 15:18:26 INFO FileFormatWriter: Finished processing stats for write job cd198c39-52e1-4ab5-8c19-1f92bc4f055a.
[2025-01-24T15:18:26.307+0000] {spark_submit.py:579} INFO - 25/01/24 15:18:26 INFO CodeGenerator: Code generated in 65.507826 ms
[2025-01-24T15:18:26.325+0000] {spark_submit.py:579} INFO - 25/01/24 15:18:26 INFO SparkContext: Starting job: $anonfun$recordDeltaOperationInternal$1 at DatabricksLogging.scala:128
[2025-01-24T15:18:26.326+0000] {spark_submit.py:579} INFO - 25/01/24 15:18:26 INFO DAGScheduler: Got job 5 ($anonfun$recordDeltaOperationInternal$1 at DatabricksLogging.scala:128) with 50 output partitions
[2025-01-24T15:18:26.327+0000] {spark_submit.py:579} INFO - 25/01/24 15:18:26 INFO DAGScheduler: Final stage: ResultStage 10 ($anonfun$recordDeltaOperationInternal$1 at DatabricksLogging.scala:128)
[2025-01-24T15:18:26.327+0000] {spark_submit.py:579} INFO - 25/01/24 15:18:26 INFO DAGScheduler: Parents of final stage: List(ShuffleMapStage 9)
[2025-01-24T15:18:26.328+0000] {spark_submit.py:579} INFO - 25/01/24 15:18:26 INFO DAGScheduler: Missing parents: List()
[2025-01-24T15:18:26.329+0000] {spark_submit.py:579} INFO - 25/01/24 15:18:26 INFO DAGScheduler: Submitting ResultStage 10 (MapPartitionsRDD[24] at $anonfun$recordDeltaOperationInternal$1 at DatabricksLogging.scala:128), which has no missing parents
[2025-01-24T15:18:26.347+0000] {spark_submit.py:579} INFO - 25/01/24 15:18:26 INFO MemoryStore: Block broadcast_8 stored as values in memory (estimated size 473.8 KiB, free 432.8 MiB)
[2025-01-24T15:18:26.350+0000] {spark_submit.py:579} INFO - 25/01/24 15:18:26 INFO MemoryStore: Block broadcast_8_piece0 stored as bytes in memory (estimated size 112.1 KiB, free 432.7 MiB)
[2025-01-24T15:18:26.351+0000] {spark_submit.py:579} INFO - 25/01/24 15:18:26 INFO BlockManagerInfo: Added broadcast_8_piece0 in memory on 73fc507ad5e4:38507 (size: 112.1 KiB, free: 434.1 MiB)
[2025-01-24T15:18:26.352+0000] {spark_submit.py:579} INFO - 25/01/24 15:18:26 INFO BlockManagerInfo: Removed broadcast_7_piece0 on 172.18.0.10:39675 in memory (size: 126.1 KiB, free: 1048.7 MiB)
[2025-01-24T15:18:26.354+0000] {spark_submit.py:579} INFO - 25/01/24 15:18:26 INFO SparkContext: Created broadcast 8 from broadcast at DAGScheduler.scala:1513
[2025-01-24T15:18:26.355+0000] {spark_submit.py:579} INFO - 25/01/24 15:18:26 INFO DAGScheduler: Submitting 50 missing tasks from ResultStage 10 (MapPartitionsRDD[24] at $anonfun$recordDeltaOperationInternal$1 at DatabricksLogging.scala:128) (first 15 tasks are for partitions Vector(0, 1, 2, 3, 4, 5, 6, 7, 8, 9, 10, 11, 12, 13, 14))
[2025-01-24T15:18:26.355+0000] {spark_submit.py:579} INFO - 25/01/24 15:18:26 INFO TaskSchedulerImpl: Adding task set 10.0 with 50 tasks resource profile 0
[2025-01-24T15:18:26.357+0000] {spark_submit.py:579} INFO - 25/01/24 15:18:26 INFO TaskSetManager: Starting task 0.0 in stage 10.0 (TID 57) (172.18.0.10, executor 0, partition 0, PROCESS_LOCAL, 4457 bytes) taskResourceAssignments Map()
[2025-01-24T15:18:26.358+0000] {spark_submit.py:579} INFO - 25/01/24 15:18:26 INFO TaskSetManager: Starting task 1.0 in stage 10.0 (TID 58) (172.18.0.10, executor 0, partition 1, PROCESS_LOCAL, 4457 bytes) taskResourceAssignments Map()
[2025-01-24T15:18:26.362+0000] {spark_submit.py:579} INFO - 25/01/24 15:18:26 INFO BlockManagerInfo: Removed broadcast_7_piece0 on 73fc507ad5e4:38507 in memory (size: 126.1 KiB, free: 434.2 MiB)
[2025-01-24T15:18:26.409+0000] {spark_submit.py:579} INFO - 25/01/24 15:18:26 INFO BlockManagerInfo: Added broadcast_8_piece0 in memory on 172.18.0.10:39675 (size: 112.1 KiB, free: 1048.6 MiB)
[2025-01-24T15:18:26.557+0000] {spark_submit.py:579} INFO - 25/01/24 15:18:26 INFO TaskSetManager: Starting task 2.0 in stage 10.0 (TID 59) (172.18.0.10, executor 0, partition 2, PROCESS_LOCAL, 4457 bytes) taskResourceAssignments Map()
[2025-01-24T15:18:26.560+0000] {spark_submit.py:579} INFO - 25/01/24 15:18:26 INFO TaskSetManager: Finished task 1.0 in stage 10.0 (TID 58) in 195 ms on 172.18.0.10 (executor 0) (1/50)
[2025-01-24T15:18:26.561+0000] {spark_submit.py:579} INFO - 25/01/24 15:18:26 INFO TaskSetManager: Starting task 3.0 in stage 10.0 (TID 60) (172.18.0.10, executor 0, partition 3, PROCESS_LOCAL, 4457 bytes) taskResourceAssignments Map()
[2025-01-24T15:18:26.562+0000] {spark_submit.py:579} INFO - 25/01/24 15:18:26 INFO TaskSetManager: Finished task 0.0 in stage 10.0 (TID 57) in 198 ms on 172.18.0.10 (executor 0) (2/50)
[2025-01-24T15:18:26.579+0000] {spark_submit.py:579} INFO - 25/01/24 15:18:26 INFO TaskSetManager: Starting task 4.0 in stage 10.0 (TID 61) (172.18.0.10, executor 0, partition 4, PROCESS_LOCAL, 4457 bytes) taskResourceAssignments Map()
[2025-01-24T15:18:26.583+0000] {spark_submit.py:579} INFO - 25/01/24 15:18:26 INFO TaskSetManager: Finished task 3.0 in stage 10.0 (TID 60) in 20 ms on 172.18.0.10 (executor 0) (3/50)
[2025-01-24T15:18:26.584+0000] {spark_submit.py:579} INFO - 25/01/24 15:18:26 INFO TaskSetManager: Starting task 5.0 in stage 10.0 (TID 62) (172.18.0.10, executor 0, partition 5, PROCESS_LOCAL, 4457 bytes) taskResourceAssignments Map()
[2025-01-24T15:18:26.585+0000] {spark_submit.py:579} INFO - 25/01/24 15:18:26 INFO TaskSetManager: Finished task 2.0 in stage 10.0 (TID 59) in 29 ms on 172.18.0.10 (executor 0) (4/50)
[2025-01-24T15:18:26.618+0000] {spark_submit.py:579} INFO - 25/01/24 15:18:26 INFO TaskSetManager: Starting task 6.0 in stage 10.0 (TID 63) (172.18.0.10, executor 0, partition 6, PROCESS_LOCAL, 4457 bytes) taskResourceAssignments Map()
[2025-01-24T15:18:26.619+0000] {spark_submit.py:579} INFO - 25/01/24 15:18:26 INFO TaskSetManager: Finished task 5.0 in stage 10.0 (TID 62) in 34 ms on 172.18.0.10 (executor 0) (5/50)
[2025-01-24T15:18:26.619+0000] {spark_submit.py:579} INFO - 25/01/24 15:18:26 INFO TaskSetManager: Starting task 7.0 in stage 10.0 (TID 64) (172.18.0.10, executor 0, partition 7, PROCESS_LOCAL, 4457 bytes) taskResourceAssignments Map()
[2025-01-24T15:18:26.620+0000] {spark_submit.py:579} INFO - 25/01/24 15:18:26 INFO TaskSetManager: Finished task 4.0 in stage 10.0 (TID 61) in 40 ms on 172.18.0.10 (executor 0) (6/50)
[2025-01-24T15:18:26.637+0000] {spark_submit.py:579} INFO - 25/01/24 15:18:26 INFO TaskSetManager: Starting task 8.0 in stage 10.0 (TID 65) (172.18.0.10, executor 0, partition 8, PROCESS_LOCAL, 4457 bytes) taskResourceAssignments Map()
[2025-01-24T15:18:26.637+0000] {spark_submit.py:579} INFO - 25/01/24 15:18:26 INFO TaskSetManager: Finished task 7.0 in stage 10.0 (TID 64) in 23 ms on 172.18.0.10 (executor 0) (7/50)
[2025-01-24T15:18:26.641+0000] {spark_submit.py:579} INFO - 25/01/24 15:18:26 INFO TaskSetManager: Starting task 9.0 in stage 10.0 (TID 66) (172.18.0.10, executor 0, partition 9, PROCESS_LOCAL, 4457 bytes) taskResourceAssignments Map()
[2025-01-24T15:18:26.642+0000] {spark_submit.py:579} INFO - 25/01/24 15:18:26 INFO TaskSetManager: Finished task 6.0 in stage 10.0 (TID 63) in 29 ms on 172.18.0.10 (executor 0) (8/50)
[2025-01-24T15:18:26.650+0000] {spark_submit.py:579} INFO - 25/01/24 15:18:26 INFO TaskSetManager: Starting task 10.0 in stage 10.0 (TID 67) (172.18.0.10, executor 0, partition 10, PROCESS_LOCAL, 4457 bytes) taskResourceAssignments Map()
[2025-01-24T15:18:26.651+0000] {spark_submit.py:579} INFO - 25/01/24 15:18:26 INFO TaskSetManager: Finished task 8.0 in stage 10.0 (TID 65) in 14 ms on 172.18.0.10 (executor 0) (9/50)
[2025-01-24T15:18:26.657+0000] {spark_submit.py:579} INFO - 25/01/24 15:18:26 INFO TaskSetManager: Starting task 11.0 in stage 10.0 (TID 68) (172.18.0.10, executor 0, partition 11, PROCESS_LOCAL, 4457 bytes) taskResourceAssignments Map()
[2025-01-24T15:18:26.663+0000] {spark_submit.py:579} INFO - 25/01/24 15:18:26 INFO TaskSetManager: Finished task 9.0 in stage 10.0 (TID 66) in 21 ms on 172.18.0.10 (executor 0) (10/50)
[2025-01-24T15:18:26.680+0000] {spark_submit.py:579} INFO - 25/01/24 15:18:26 INFO TaskSetManager: Starting task 12.0 in stage 10.0 (TID 69) (172.18.0.10, executor 0, partition 12, PROCESS_LOCAL, 4457 bytes) taskResourceAssignments Map()
[2025-01-24T15:18:26.681+0000] {spark_submit.py:579} INFO - 25/01/24 15:18:26 INFO TaskSetManager: Starting task 13.0 in stage 10.0 (TID 70) (172.18.0.10, executor 0, partition 13, PROCESS_LOCAL, 4457 bytes) taskResourceAssignments Map()
[2025-01-24T15:18:26.681+0000] {spark_submit.py:579} INFO - 25/01/24 15:18:26 INFO TaskSetManager: Finished task 11.0 in stage 10.0 (TID 68) in 22 ms on 172.18.0.10 (executor 0) (11/50)
[2025-01-24T15:18:26.681+0000] {spark_submit.py:579} INFO - 25/01/24 15:18:26 INFO TaskSetManager: Finished task 10.0 in stage 10.0 (TID 67) in 31 ms on 172.18.0.10 (executor 0) (12/50)
[2025-01-24T15:18:26.700+0000] {spark_submit.py:579} INFO - 25/01/24 15:18:26 INFO TaskSetManager: Starting task 14.0 in stage 10.0 (TID 71) (172.18.0.10, executor 0, partition 14, PROCESS_LOCAL, 4457 bytes) taskResourceAssignments Map()
[2025-01-24T15:18:26.701+0000] {spark_submit.py:579} INFO - 25/01/24 15:18:26 INFO TaskSetManager: Finished task 13.0 in stage 10.0 (TID 70) in 15 ms on 172.18.0.10 (executor 0) (13/50)
[2025-01-24T15:18:26.701+0000] {spark_submit.py:579} INFO - 25/01/24 15:18:26 INFO TaskSetManager: Starting task 15.0 in stage 10.0 (TID 72) (172.18.0.10, executor 0, partition 15, PROCESS_LOCAL, 4457 bytes) taskResourceAssignments Map()
[2025-01-24T15:18:26.707+0000] {spark_submit.py:579} INFO - 25/01/24 15:18:26 INFO TaskSetManager: Finished task 12.0 in stage 10.0 (TID 69) in 28 ms on 172.18.0.10 (executor 0) (14/50)
[2025-01-24T15:18:26.712+0000] {spark_submit.py:579} INFO - 25/01/24 15:18:26 INFO TaskSetManager: Starting task 16.0 in stage 10.0 (TID 73) (172.18.0.10, executor 0, partition 16, PROCESS_LOCAL, 4457 bytes) taskResourceAssignments Map()
[2025-01-24T15:18:26.713+0000] {spark_submit.py:579} INFO - 25/01/24 15:18:26 INFO TaskSetManager: Finished task 14.0 in stage 10.0 (TID 71) in 21 ms on 172.18.0.10 (executor 0) (15/50)
[2025-01-24T15:18:26.716+0000] {spark_submit.py:579} INFO - 25/01/24 15:18:26 INFO TaskSetManager: Starting task 17.0 in stage 10.0 (TID 74) (172.18.0.10, executor 0, partition 17, PROCESS_LOCAL, 4457 bytes) taskResourceAssignments Map()
[2025-01-24T15:18:26.717+0000] {spark_submit.py:579} INFO - 25/01/24 15:18:26 INFO TaskSetManager: Finished task 15.0 in stage 10.0 (TID 72) in 18 ms on 172.18.0.10 (executor 0) (16/50)
[2025-01-24T15:18:26.726+0000] {spark_submit.py:579} INFO - 25/01/24 15:18:26 INFO TaskSetManager: Starting task 18.0 in stage 10.0 (TID 75) (172.18.0.10, executor 0, partition 18, PROCESS_LOCAL, 4457 bytes) taskResourceAssignments Map()
[2025-01-24T15:18:26.728+0000] {spark_submit.py:579} INFO - 25/01/24 15:18:26 INFO TaskSetManager: Finished task 16.0 in stage 10.0 (TID 73) in 15 ms on 172.18.0.10 (executor 0) (17/50)
[2025-01-24T15:18:26.729+0000] {spark_submit.py:579} INFO - 25/01/24 15:18:26 INFO TaskSetManager: Starting task 19.0 in stage 10.0 (TID 76) (172.18.0.10, executor 0, partition 19, PROCESS_LOCAL, 4457 bytes) taskResourceAssignments Map()
[2025-01-24T15:18:26.731+0000] {spark_submit.py:579} INFO - 25/01/24 15:18:26 INFO TaskSetManager: Finished task 17.0 in stage 10.0 (TID 74) in 14 ms on 172.18.0.10 (executor 0) (18/50)
[2025-01-24T15:18:26.741+0000] {spark_submit.py:579} INFO - 25/01/24 15:18:26 INFO TaskSetManager: Starting task 20.0 in stage 10.0 (TID 77) (172.18.0.10, executor 0, partition 20, PROCESS_LOCAL, 4457 bytes) taskResourceAssignments Map()
[2025-01-24T15:18:26.742+0000] {spark_submit.py:579} INFO - 25/01/24 15:18:26 INFO TaskSetManager: Finished task 18.0 in stage 10.0 (TID 75) in 16 ms on 172.18.0.10 (executor 0) (19/50)
[2025-01-24T15:18:26.743+0000] {spark_submit.py:579} INFO - 25/01/24 15:18:26 INFO TaskSetManager: Starting task 21.0 in stage 10.0 (TID 78) (172.18.0.10, executor 0, partition 21, PROCESS_LOCAL, 4457 bytes) taskResourceAssignments Map()
[2025-01-24T15:18:26.744+0000] {spark_submit.py:579} INFO - 25/01/24 15:18:26 INFO TaskSetManager: Finished task 19.0 in stage 10.0 (TID 76) in 16 ms on 172.18.0.10 (executor 0) (20/50)
[2025-01-24T15:18:26.755+0000] {spark_submit.py:579} INFO - 25/01/24 15:18:26 INFO TaskSetManager: Starting task 22.0 in stage 10.0 (TID 79) (172.18.0.10, executor 0, partition 22, PROCESS_LOCAL, 4457 bytes) taskResourceAssignments Map()
[2025-01-24T15:18:26.756+0000] {spark_submit.py:579} INFO - 25/01/24 15:18:26 INFO TaskSetManager: Finished task 20.0 in stage 10.0 (TID 77) in 15 ms on 172.18.0.10 (executor 0) (21/50)
[2025-01-24T15:18:26.761+0000] {spark_submit.py:579} INFO - 25/01/24 15:18:26 INFO TaskSetManager: Starting task 23.0 in stage 10.0 (TID 80) (172.18.0.10, executor 0, partition 23, PROCESS_LOCAL, 4457 bytes) taskResourceAssignments Map()
[2025-01-24T15:18:26.762+0000] {spark_submit.py:579} INFO - 25/01/24 15:18:26 INFO TaskSetManager: Finished task 21.0 in stage 10.0 (TID 78) in 19 ms on 172.18.0.10 (executor 0) (22/50)
[2025-01-24T15:18:26.769+0000] {spark_submit.py:579} INFO - 25/01/24 15:18:26 INFO TaskSetManager: Starting task 24.0 in stage 10.0 (TID 81) (172.18.0.10, executor 0, partition 24, PROCESS_LOCAL, 4457 bytes) taskResourceAssignments Map()
[2025-01-24T15:18:26.770+0000] {spark_submit.py:579} INFO - 25/01/24 15:18:26 INFO TaskSetManager: Finished task 22.0 in stage 10.0 (TID 79) in 16 ms on 172.18.0.10 (executor 0) (23/50)
[2025-01-24T15:18:26.776+0000] {spark_submit.py:579} INFO - 25/01/24 15:18:26 INFO TaskSetManager: Starting task 25.0 in stage 10.0 (TID 82) (172.18.0.10, executor 0, partition 25, PROCESS_LOCAL, 4457 bytes) taskResourceAssignments Map()
[2025-01-24T15:18:26.778+0000] {spark_submit.py:579} INFO - 25/01/24 15:18:26 INFO TaskSetManager: Finished task 23.0 in stage 10.0 (TID 80) in 17 ms on 172.18.0.10 (executor 0) (24/50)
[2025-01-24T15:18:26.785+0000] {spark_submit.py:579} INFO - 25/01/24 15:18:26 INFO TaskSetManager: Starting task 26.0 in stage 10.0 (TID 83) (172.18.0.10, executor 0, partition 26, PROCESS_LOCAL, 4457 bytes) taskResourceAssignments Map()
[2025-01-24T15:18:26.787+0000] {spark_submit.py:579} INFO - 25/01/24 15:18:26 INFO TaskSetManager: Finished task 24.0 in stage 10.0 (TID 81) in 16 ms on 172.18.0.10 (executor 0) (25/50)
[2025-01-24T15:18:26.793+0000] {spark_submit.py:579} INFO - 25/01/24 15:18:26 INFO TaskSetManager: Starting task 27.0 in stage 10.0 (TID 84) (172.18.0.10, executor 0, partition 27, PROCESS_LOCAL, 4457 bytes) taskResourceAssignments Map()
[2025-01-24T15:18:26.794+0000] {spark_submit.py:579} INFO - 25/01/24 15:18:26 INFO TaskSetManager: Finished task 25.0 in stage 10.0 (TID 82) in 18 ms on 172.18.0.10 (executor 0) (26/50)
[2025-01-24T15:18:26.802+0000] {spark_submit.py:579} INFO - 25/01/24 15:18:26 INFO TaskSetManager: Starting task 28.0 in stage 10.0 (TID 85) (172.18.0.10, executor 0, partition 28, PROCESS_LOCAL, 4457 bytes) taskResourceAssignments Map()
[2025-01-24T15:18:26.803+0000] {spark_submit.py:579} INFO - 25/01/24 15:18:26 INFO TaskSetManager: Finished task 26.0 in stage 10.0 (TID 83) in 18 ms on 172.18.0.10 (executor 0) (27/50)
[2025-01-24T15:18:26.811+0000] {spark_submit.py:579} INFO - 25/01/24 15:18:26 INFO TaskSetManager: Starting task 29.0 in stage 10.0 (TID 86) (172.18.0.10, executor 0, partition 29, PROCESS_LOCAL, 4457 bytes) taskResourceAssignments Map()
[2025-01-24T15:18:26.813+0000] {spark_submit.py:579} INFO - 25/01/24 15:18:26 INFO TaskSetManager: Finished task 27.0 in stage 10.0 (TID 84) in 21 ms on 172.18.0.10 (executor 0) (28/50)
[2025-01-24T15:18:26.818+0000] {spark_submit.py:579} INFO - 25/01/24 15:18:26 INFO TaskSetManager: Starting task 30.0 in stage 10.0 (TID 87) (172.18.0.10, executor 0, partition 30, PROCESS_LOCAL, 4457 bytes) taskResourceAssignments Map()
[2025-01-24T15:18:26.821+0000] {spark_submit.py:579} INFO - 25/01/24 15:18:26 INFO TaskSetManager: Finished task 28.0 in stage 10.0 (TID 85) in 19 ms on 172.18.0.10 (executor 0) (29/50)
[2025-01-24T15:18:26.830+0000] {spark_submit.py:579} INFO - 25/01/24 15:18:26 INFO TaskSetManager: Starting task 31.0 in stage 10.0 (TID 88) (172.18.0.10, executor 0, partition 31, PROCESS_LOCAL, 4457 bytes) taskResourceAssignments Map()
[2025-01-24T15:18:26.831+0000] {spark_submit.py:579} INFO - 25/01/24 15:18:26 INFO TaskSetManager: Finished task 29.0 in stage 10.0 (TID 86) in 19 ms on 172.18.0.10 (executor 0) (30/50)
[2025-01-24T15:18:26.835+0000] {spark_submit.py:579} INFO - 25/01/24 15:18:26 INFO TaskSetManager: Starting task 32.0 in stage 10.0 (TID 89) (172.18.0.10, executor 0, partition 32, PROCESS_LOCAL, 4457 bytes) taskResourceAssignments Map()
[2025-01-24T15:18:26.841+0000] {spark_submit.py:579} INFO - 25/01/24 15:18:26 INFO TaskSetManager: Finished task 30.0 in stage 10.0 (TID 87) in 23 ms on 172.18.0.10 (executor 0) (31/50)
[2025-01-24T15:18:26.849+0000] {spark_submit.py:579} INFO - 25/01/24 15:18:26 INFO TaskSetManager: Starting task 33.0 in stage 10.0 (TID 90) (172.18.0.10, executor 0, partition 33, PROCESS_LOCAL, 4457 bytes) taskResourceAssignments Map()
[2025-01-24T15:18:26.850+0000] {spark_submit.py:579} INFO - 25/01/24 15:18:26 INFO TaskSetManager: Finished task 31.0 in stage 10.0 (TID 88) in 20 ms on 172.18.0.10 (executor 0) (32/50)
[2025-01-24T15:18:26.857+0000] {spark_submit.py:579} INFO - 25/01/24 15:18:26 INFO TaskSetManager: Starting task 34.0 in stage 10.0 (TID 91) (172.18.0.10, executor 0, partition 34, PROCESS_LOCAL, 4457 bytes) taskResourceAssignments Map()
[2025-01-24T15:18:26.861+0000] {spark_submit.py:579} INFO - 25/01/24 15:18:26 INFO TaskSetManager: Finished task 32.0 in stage 10.0 (TID 89) in 23 ms on 172.18.0.10 (executor 0) (33/50)
[2025-01-24T15:18:26.866+0000] {spark_submit.py:579} INFO - 25/01/24 15:18:26 INFO TaskSetManager: Starting task 35.0 in stage 10.0 (TID 92) (172.18.0.10, executor 0, partition 35, PROCESS_LOCAL, 4457 bytes) taskResourceAssignments Map()
[2025-01-24T15:18:26.867+0000] {spark_submit.py:579} INFO - 25/01/24 15:18:26 INFO TaskSetManager: Finished task 33.0 in stage 10.0 (TID 90) in 19 ms on 172.18.0.10 (executor 0) (34/50)
[2025-01-24T15:18:26.880+0000] {spark_submit.py:579} INFO - 25/01/24 15:18:26 INFO TaskSetManager: Starting task 36.0 in stage 10.0 (TID 93) (172.18.0.10, executor 0, partition 36, PROCESS_LOCAL, 4457 bytes) taskResourceAssignments Map()
[2025-01-24T15:18:26.881+0000] {spark_submit.py:579} INFO - 25/01/24 15:18:26 INFO TaskSetManager: Finished task 35.0 in stage 10.0 (TID 92) in 14 ms on 172.18.0.10 (executor 0) (35/50)
[2025-01-24T15:18:26.883+0000] {spark_submit.py:579} INFO - 25/01/24 15:18:26 INFO TaskSetManager: Starting task 37.0 in stage 10.0 (TID 94) (172.18.0.10, executor 0, partition 37, PROCESS_LOCAL, 4457 bytes) taskResourceAssignments Map()
[2025-01-24T15:18:26.884+0000] {spark_submit.py:579} INFO - 25/01/24 15:18:26 INFO TaskSetManager: Finished task 34.0 in stage 10.0 (TID 91) in 27 ms on 172.18.0.10 (executor 0) (36/50)
[2025-01-24T15:18:26.895+0000] {spark_submit.py:579} INFO - 25/01/24 15:18:26 INFO TaskSetManager: Starting task 38.0 in stage 10.0 (TID 95) (172.18.0.10, executor 0, partition 38, PROCESS_LOCAL, 4457 bytes) taskResourceAssignments Map()
[2025-01-24T15:18:26.895+0000] {spark_submit.py:579} INFO - 25/01/24 15:18:26 INFO TaskSetManager: Finished task 36.0 in stage 10.0 (TID 93) in 16 ms on 172.18.0.10 (executor 0) (37/50)
[2025-01-24T15:18:26.897+0000] {spark_submit.py:579} INFO - 25/01/24 15:18:26 INFO TaskSetManager: Starting task 39.0 in stage 10.0 (TID 96) (172.18.0.10, executor 0, partition 39, PROCESS_LOCAL, 4457 bytes) taskResourceAssignments Map()
[2025-01-24T15:18:26.898+0000] {spark_submit.py:579} INFO - 25/01/24 15:18:26 INFO TaskSetManager: Finished task 37.0 in stage 10.0 (TID 94) in 15 ms on 172.18.0.10 (executor 0) (38/50)
[2025-01-24T15:18:26.915+0000] {spark_submit.py:579} INFO - 25/01/24 15:18:26 INFO TaskSetManager: Starting task 40.0 in stage 10.0 (TID 97) (172.18.0.10, executor 0, partition 40, PROCESS_LOCAL, 4457 bytes) taskResourceAssignments Map()
[2025-01-24T15:18:26.916+0000] {spark_submit.py:579} INFO - 25/01/24 15:18:26 INFO TaskSetManager: Finished task 38.0 in stage 10.0 (TID 95) in 18 ms on 172.18.0.10 (executor 0) (39/50)
[2025-01-24T15:18:26.917+0000] {spark_submit.py:579} INFO - 25/01/24 15:18:26 INFO TaskSetManager: Starting task 41.0 in stage 10.0 (TID 98) (172.18.0.10, executor 0, partition 41, PROCESS_LOCAL, 4457 bytes) taskResourceAssignments Map()
[2025-01-24T15:18:26.918+0000] {spark_submit.py:579} INFO - 25/01/24 15:18:26 INFO TaskSetManager: Finished task 39.0 in stage 10.0 (TID 96) in 20 ms on 172.18.0.10 (executor 0) (40/50)
[2025-01-24T15:18:26.928+0000] {spark_submit.py:579} INFO - 25/01/24 15:18:26 INFO TaskSetManager: Starting task 42.0 in stage 10.0 (TID 99) (172.18.0.10, executor 0, partition 42, PROCESS_LOCAL, 4457 bytes) taskResourceAssignments Map()
[2025-01-24T15:18:26.929+0000] {spark_submit.py:579} INFO - 25/01/24 15:18:26 INFO TaskSetManager: Finished task 40.0 in stage 10.0 (TID 97) in 17 ms on 172.18.0.10 (executor 0) (41/50)
[2025-01-24T15:18:26.940+0000] {spark_submit.py:579} INFO - 25/01/24 15:18:26 INFO TaskSetManager: Starting task 43.0 in stage 10.0 (TID 100) (172.18.0.10, executor 0, partition 43, PROCESS_LOCAL, 4457 bytes) taskResourceAssignments Map()
[2025-01-24T15:18:26.940+0000] {spark_submit.py:579} INFO - 25/01/24 15:18:26 INFO TaskSetManager: Finished task 41.0 in stage 10.0 (TID 98) in 25 ms on 172.18.0.10 (executor 0) (42/50)
[2025-01-24T15:18:26.946+0000] {spark_submit.py:579} INFO - 25/01/24 15:18:26 INFO TaskSetManager: Starting task 44.0 in stage 10.0 (TID 101) (172.18.0.10, executor 0, partition 44, PROCESS_LOCAL, 4457 bytes) taskResourceAssignments Map()
[2025-01-24T15:18:26.947+0000] {spark_submit.py:579} INFO - 25/01/24 15:18:26 INFO TaskSetManager: Finished task 42.0 in stage 10.0 (TID 99) in 18 ms on 172.18.0.10 (executor 0) (43/50)
[2025-01-24T15:18:26.953+0000] {spark_submit.py:579} INFO - 25/01/24 15:18:26 INFO TaskSetManager: Finished task 43.0 in stage 10.0 (TID 100) in 14 ms on 172.18.0.10 (executor 0) (44/50)
[2025-01-24T15:18:26.957+0000] {spark_submit.py:579} INFO - 25/01/24 15:18:26 INFO TaskSetManager: Starting task 45.0 in stage 10.0 (TID 102) (172.18.0.10, executor 0, partition 45, PROCESS_LOCAL, 4457 bytes) taskResourceAssignments Map()
[2025-01-24T15:18:26.959+0000] {spark_submit.py:579} INFO - 25/01/24 15:18:26 INFO TaskSetManager: Finished task 44.0 in stage 10.0 (TID 101) in 13 ms on 172.18.0.10 (executor 0) (45/50)
[2025-01-24T15:18:26.960+0000] {spark_submit.py:579} INFO - 25/01/24 15:18:26 INFO TaskSetManager: Starting task 46.0 in stage 10.0 (TID 103) (172.18.0.10, executor 0, partition 46, PROCESS_LOCAL, 4457 bytes) taskResourceAssignments Map()
[2025-01-24T15:18:26.964+0000] {spark_submit.py:579} INFO - 25/01/24 15:18:26 INFO TaskSetManager: Starting task 47.0 in stage 10.0 (TID 104) (172.18.0.10, executor 0, partition 47, PROCESS_LOCAL, 4457 bytes) taskResourceAssignments Map()
[2025-01-24T15:18:26.965+0000] {spark_submit.py:579} INFO - 25/01/24 15:18:26 INFO TaskSetManager: Finished task 45.0 in stage 10.0 (TID 102) in 12 ms on 172.18.0.10 (executor 0) (46/50)
[2025-01-24T15:18:26.975+0000] {spark_submit.py:579} INFO - 25/01/24 15:18:26 INFO TaskSetManager: Starting task 48.0 in stage 10.0 (TID 105) (172.18.0.10, executor 0, partition 48, PROCESS_LOCAL, 4457 bytes) taskResourceAssignments Map()
[2025-01-24T15:18:26.976+0000] {spark_submit.py:579} INFO - 25/01/24 15:18:26 INFO TaskSetManager: Finished task 47.0 in stage 10.0 (TID 104) in 12 ms on 172.18.0.10 (executor 0) (47/50)
[2025-01-24T15:18:26.977+0000] {spark_submit.py:579} INFO - 25/01/24 15:18:26 INFO TaskSetManager: Starting task 49.0 in stage 10.0 (TID 106) (172.18.0.10, executor 0, partition 49, PROCESS_LOCAL, 4457 bytes) taskResourceAssignments Map()
[2025-01-24T15:18:26.980+0000] {spark_submit.py:579} INFO - 25/01/24 15:18:26 INFO TaskSetManager: Finished task 46.0 in stage 10.0 (TID 103) in 19 ms on 172.18.0.10 (executor 0) (48/50)
[2025-01-24T15:18:26.989+0000] {spark_submit.py:579} INFO - 25/01/24 15:18:26 INFO TaskSetManager: Finished task 48.0 in stage 10.0 (TID 105) in 14 ms on 172.18.0.10 (executor 0) (49/50)
[2025-01-24T15:18:26.990+0000] {spark_submit.py:579} INFO - 25/01/24 15:18:26 INFO TaskSetManager: Finished task 49.0 in stage 10.0 (TID 106) in 13 ms on 172.18.0.10 (executor 0) (50/50)
[2025-01-24T15:18:26.991+0000] {spark_submit.py:579} INFO - 25/01/24 15:18:26 INFO TaskSchedulerImpl: Removed TaskSet 10.0, whose tasks have all completed, from pool
[2025-01-24T15:18:26.991+0000] {spark_submit.py:579} INFO - 25/01/24 15:18:26 INFO DAGScheduler: ResultStage 10 ($anonfun$recordDeltaOperationInternal$1 at DatabricksLogging.scala:128) finished in 0.659 s
[2025-01-24T15:18:26.992+0000] {spark_submit.py:579} INFO - 25/01/24 15:18:26 INFO DAGScheduler: Job 5 is finished. Cancelling potential speculative or zombie tasks for this job
[2025-01-24T15:18:26.992+0000] {spark_submit.py:579} INFO - 25/01/24 15:18:26 INFO TaskSchedulerImpl: Killing all running tasks in stage 10: Stage finished
