[2025-01-24T15:15:42.911+0000] {taskinstance.py:1159} INFO - Dependencies all met for dep_context=non-requeueable deps ti=<TaskInstance: test.keyword scheduled__2025-01-23T00:00:00+00:00 [queued]>
[2025-01-24T15:15:42.921+0000] {taskinstance.py:1159} INFO - Dependencies all met for dep_context=requeueable deps ti=<TaskInstance: test.keyword scheduled__2025-01-23T00:00:00+00:00 [queued]>
[2025-01-24T15:15:42.922+0000] {taskinstance.py:1361} INFO - Starting attempt 1 of 2
[2025-01-24T15:15:42.934+0000] {taskinstance.py:1382} INFO - Executing <Task(SparkSubmitOperator): keyword> on 2025-01-23 00:00:00+00:00
[2025-01-24T15:15:42.938+0000] {standard_task_runner.py:57} INFO - Started process 195 to run task
[2025-01-24T15:15:42.940+0000] {standard_task_runner.py:84} INFO - Running: ['***', 'tasks', 'run', 'test', 'keyword', 'scheduled__2025-01-23T00:00:00+00:00', '--job-id', '181', '--raw', '--subdir', 'DAGS_FOLDER/kkk.py', '--cfg-path', '/tmp/tmpbr13l95i']
[2025-01-24T15:15:42.944+0000] {standard_task_runner.py:85} INFO - Job 181: Subtask keyword
[2025-01-24T15:15:42.992+0000] {task_command.py:416} INFO - Running <TaskInstance: test.keyword scheduled__2025-01-23T00:00:00+00:00 [running]> on host 73fc507ad5e4
[2025-01-24T15:15:43.075+0000] {taskinstance.py:1662} INFO - Exporting env vars: AIRFLOW_CTX_DAG_OWNER='***' AIRFLOW_CTX_DAG_ID='test' AIRFLOW_CTX_TASK_ID='keyword' AIRFLOW_CTX_EXECUTION_DATE='2025-01-23T00:00:00+00:00' AIRFLOW_CTX_TRY_NUMBER='1' AIRFLOW_CTX_DAG_RUN_ID='scheduled__2025-01-23T00:00:00+00:00'
[2025-01-24T15:15:43.083+0000] {base.py:73} INFO - Using connection ID 'spark-conn' for task execution.
[2025-01-24T15:15:43.087+0000] {spark_submit.py:403} INFO - Spark-Submit cmd: spark-submit --master spark://spark-master:7077 --conf spark.sql.extensions=io.delta.sql.DeltaSparkSessionExtension --conf spark.sql.catalog.spark_catalog=org.apache.spark.sql.delta.catalog.DeltaCatalog --jars /opt/***/jars/hadoop-aws-3.3.4.jar,/opt/***/jars/s3-2.18.41.jar,/opt/***/jars/aws-java-sdk-bundle-1.12.262.jar,/opt/***/jars/aws-java-sdk-1.12.367.jar,/opt/***/jars/delta-core_2.12-2.2.0.jar,/opt/***/jars/delta-storage-2.2.0.jar, --num-executors 2 --total-executor-cores 2 --executor-cores 2 --executor-memory 2g --driver-memory 1g --name arrow-spark --deploy-mode client /opt/***/jobs/python/processing_keyword.py s3a://lakehouse/bronze/keywords.parquet s3a://lakehouse/silver/keywords
[2025-01-24T15:15:43.312+0000] {spark_submit.py:579} INFO - /home/***/.local/lib/python3.9/site-packages/pyspark/bin/load-spark-env.sh: line 68: ps: command not found
[2025-01-24T15:15:47.414+0000] {spark_submit.py:579} INFO - 25/01/24 15:15:47 WARN NativeCodeLoader: Unable to load native-hadoop library for your platform... using builtin-java classes where applicable
[2025-01-24T15:15:48.886+0000] {spark_submit.py:579} INFO - 2025-01-24 15:15:48,886 INFO: Initializing Spark session...
[2025-01-24T15:15:49.494+0000] {spark_submit.py:579} INFO - 25/01/24 15:15:49 INFO SparkContext: Running Spark version 3.3.2
[2025-01-24T15:15:49.530+0000] {spark_submit.py:579} INFO - 25/01/24 15:15:49 INFO ResourceUtils: ==============================================================
[2025-01-24T15:15:49.531+0000] {spark_submit.py:579} INFO - 25/01/24 15:15:49 INFO ResourceUtils: No custom resources configured for spark.driver.
[2025-01-24T15:15:49.532+0000] {spark_submit.py:579} INFO - 25/01/24 15:15:49 INFO ResourceUtils: ==============================================================
[2025-01-24T15:15:49.533+0000] {spark_submit.py:579} INFO - 25/01/24 15:15:49 INFO SparkContext: Submitted application: CleanCredits
[2025-01-24T15:15:49.562+0000] {spark_submit.py:579} INFO - 25/01/24 15:15:49 INFO ResourceProfile: Default ResourceProfile created, executor resources: Map(cores -> name: cores, amount: 2, script: , vendor: , memory -> name: memory, amount: 2048, script: , vendor: , offHeap -> name: offHeap, amount: 0, script: , vendor: ), task resources: Map(cpus -> name: cpus, amount: 1.0)
[2025-01-24T15:15:49.578+0000] {spark_submit.py:579} INFO - 25/01/24 15:15:49 INFO ResourceProfile: Limiting resource is cpus at 2 tasks per executor
[2025-01-24T15:15:49.580+0000] {spark_submit.py:579} INFO - 25/01/24 15:15:49 INFO ResourceProfileManager: Added ResourceProfile id: 0
[2025-01-24T15:15:49.646+0000] {spark_submit.py:579} INFO - 25/01/24 15:15:49 INFO SecurityManager: Changing view acls to: ***
[2025-01-24T15:15:49.646+0000] {spark_submit.py:579} INFO - 25/01/24 15:15:49 INFO SecurityManager: Changing modify acls to: ***
[2025-01-24T15:15:49.647+0000] {spark_submit.py:579} INFO - 25/01/24 15:15:49 INFO SecurityManager: Changing view acls groups to:
[2025-01-24T15:15:49.647+0000] {spark_submit.py:579} INFO - 25/01/24 15:15:49 INFO SecurityManager: Changing modify acls groups to:
[2025-01-24T15:15:49.648+0000] {spark_submit.py:579} INFO - 25/01/24 15:15:49 INFO SecurityManager: SecurityManager: authentication disabled; ui acls disabled; users  with view permissions: Set(***); groups with view permissions: Set(); users  with modify permissions: Set(***); groups with modify permissions: Set()
[2025-01-24T15:15:49.989+0000] {spark_submit.py:579} INFO - 25/01/24 15:15:49 INFO Utils: Successfully started service 'sparkDriver' on port 44029.
[2025-01-24T15:15:50.038+0000] {spark_submit.py:579} INFO - 25/01/24 15:15:50 INFO SparkEnv: Registering MapOutputTracker
[2025-01-24T15:15:50.091+0000] {spark_submit.py:579} INFO - 25/01/24 15:15:50 INFO SparkEnv: Registering BlockManagerMaster
[2025-01-24T15:15:50.113+0000] {spark_submit.py:579} INFO - 25/01/24 15:15:50 INFO BlockManagerMasterEndpoint: Using org.apache.spark.storage.DefaultTopologyMapper for getting topology information
[2025-01-24T15:15:50.114+0000] {spark_submit.py:579} INFO - 25/01/24 15:15:50 INFO BlockManagerMasterEndpoint: BlockManagerMasterEndpoint up
[2025-01-24T15:15:50.119+0000] {spark_submit.py:579} INFO - 25/01/24 15:15:50 INFO SparkEnv: Registering BlockManagerMasterHeartbeat
[2025-01-24T15:15:50.151+0000] {spark_submit.py:579} INFO - 25/01/24 15:15:50 INFO DiskBlockManager: Created local directory at /tmp/blockmgr-6bfe5587-53b9-46a0-8620-59efe3cc053d
[2025-01-24T15:15:50.170+0000] {spark_submit.py:579} INFO - 25/01/24 15:15:50 INFO MemoryStore: MemoryStore started with capacity 434.4 MiB
[2025-01-24T15:15:50.191+0000] {spark_submit.py:579} INFO - 25/01/24 15:15:50 INFO SparkEnv: Registering OutputCommitCoordinator
[2025-01-24T15:15:50.454+0000] {spark_submit.py:579} INFO - 25/01/24 15:15:50 INFO Utils: Successfully started service 'SparkUI' on port 4040.
[2025-01-24T15:15:50.511+0000] {spark_submit.py:579} INFO - 25/01/24 15:15:50 INFO SparkContext: Added JAR file:///opt/***/jars/hadoop-aws-3.3.4.jar at spark://73fc507ad5e4:44029/jars/hadoop-aws-3.3.4.jar with timestamp 1737731749478
[2025-01-24T15:15:50.512+0000] {spark_submit.py:579} INFO - 25/01/24 15:15:50 INFO SparkContext: Added JAR file:///opt/***/jars/s3-2.18.41.jar at spark://73fc507ad5e4:44029/jars/s3-2.18.41.jar with timestamp 1737731749478
[2025-01-24T15:15:50.513+0000] {spark_submit.py:579} INFO - 25/01/24 15:15:50 INFO SparkContext: Added JAR file:///opt/***/jars/aws-java-sdk-bundle-1.12.262.jar at spark://73fc507ad5e4:44029/jars/aws-java-sdk-bundle-1.12.262.jar with timestamp 1737731749478
[2025-01-24T15:15:50.514+0000] {spark_submit.py:579} INFO - 25/01/24 15:15:50 INFO SparkContext: Added JAR file:///opt/***/jars/aws-java-sdk-1.12.367.jar at spark://73fc507ad5e4:44029/jars/aws-java-sdk-1.12.367.jar with timestamp 1737731749478
[2025-01-24T15:15:50.515+0000] {spark_submit.py:579} INFO - 25/01/24 15:15:50 INFO SparkContext: Added JAR file:///opt/***/jars/delta-core_2.12-2.2.0.jar at spark://73fc507ad5e4:44029/jars/delta-core_2.12-2.2.0.jar with timestamp 1737731749478
[2025-01-24T15:15:50.515+0000] {spark_submit.py:579} INFO - 25/01/24 15:15:50 INFO SparkContext: Added JAR file:///opt/***/jars/delta-storage-2.2.0.jar at spark://73fc507ad5e4:44029/jars/delta-storage-2.2.0.jar with timestamp 1737731749478
[2025-01-24T15:15:50.626+0000] {spark_submit.py:579} INFO - 25/01/24 15:15:50 INFO StandaloneAppClient$ClientEndpoint: Connecting to master spark://spark-master:7077...
[2025-01-24T15:15:50.689+0000] {spark_submit.py:579} INFO - 25/01/24 15:15:50 INFO TransportClientFactory: Successfully created connection to spark-master/172.18.0.7:7077 after 31 ms (0 ms spent in bootstraps)
[2025-01-24T15:15:50.851+0000] {spark_submit.py:579} INFO - 25/01/24 15:15:50 INFO StandaloneSchedulerBackend: Connected to Spark cluster with app ID app-20250124151550-0000
[2025-01-24T15:15:50.861+0000] {spark_submit.py:579} INFO - 25/01/24 15:15:50 INFO Utils: Successfully started service 'org.apache.spark.network.netty.NettyBlockTransferService' on port 46429.
[2025-01-24T15:15:50.862+0000] {spark_submit.py:579} INFO - 25/01/24 15:15:50 INFO NettyBlockTransferService: Server created on 73fc507ad5e4:46429
[2025-01-24T15:15:50.864+0000] {spark_submit.py:579} INFO - 25/01/24 15:15:50 INFO BlockManager: Using org.apache.spark.storage.RandomBlockReplicationPolicy for block replication policy
[2025-01-24T15:15:50.878+0000] {spark_submit.py:579} INFO - 25/01/24 15:15:50 INFO BlockManagerMaster: Registering BlockManager BlockManagerId(driver, 73fc507ad5e4, 46429, None)
[2025-01-24T15:15:50.883+0000] {spark_submit.py:579} INFO - 25/01/24 15:15:50 INFO BlockManagerMasterEndpoint: Registering block manager 73fc507ad5e4:46429 with 434.4 MiB RAM, BlockManagerId(driver, 73fc507ad5e4, 46429, None)
[2025-01-24T15:15:50.886+0000] {spark_submit.py:579} INFO - 25/01/24 15:15:50 INFO BlockManagerMaster: Registered BlockManager BlockManagerId(driver, 73fc507ad5e4, 46429, None)
[2025-01-24T15:15:50.888+0000] {spark_submit.py:579} INFO - 25/01/24 15:15:50 INFO BlockManager: Initialized BlockManager: BlockManagerId(driver, 73fc507ad5e4, 46429, None)
[2025-01-24T15:15:50.903+0000] {spark_submit.py:579} INFO - 25/01/24 15:15:50 INFO StandaloneAppClient$ClientEndpoint: Executor added: app-20250124151550-0000/0 on worker-20250124151524-172.18.0.10-33905 (172.18.0.10:33905) with 2 core(s)
[2025-01-24T15:15:50.905+0000] {spark_submit.py:579} INFO - 25/01/24 15:15:50 INFO StandaloneSchedulerBackend: Granted executor ID app-20250124151550-0000/0 on hostPort 172.18.0.10:33905 with 2 core(s), 2.0 GiB RAM
[2025-01-24T15:15:51.097+0000] {spark_submit.py:579} INFO - 25/01/24 15:15:51 INFO StandaloneAppClient$ClientEndpoint: Executor updated: app-20250124151550-0000/0 is now RUNNING
[2025-01-24T15:15:51.211+0000] {spark_submit.py:579} INFO - 25/01/24 15:15:51 INFO StandaloneSchedulerBackend: SchedulerBackend is ready for scheduling beginning after reached minRegisteredResourcesRatio: 0.0
[2025-01-24T15:15:51.476+0000] {spark_submit.py:579} INFO - 2025-01-24 15:15:51,476 INFO: Spark session initialized successfully.
[2025-01-24T15:15:51.477+0000] {spark_submit.py:579} INFO - 2025-01-24 15:15:51,476 INFO: Reading data from s3a://lakehouse/bronze/keywords.parquet
[2025-01-24T15:15:51.488+0000] {spark_submit.py:579} INFO - 25/01/24 15:15:51 INFO SharedState: Setting hive.metastore.warehouse.dir ('null') to the value of spark.sql.warehouse.dir.
[2025-01-24T15:15:51.492+0000] {spark_submit.py:579} INFO - 25/01/24 15:15:51 INFO SharedState: Warehouse path is 'file:/opt/***/spark-warehouse'.
[2025-01-24T15:15:53.071+0000] {spark_submit.py:579} INFO - 25/01/24 15:15:53 WARN MetricsConfig: Cannot locate configuration: tried hadoop-metrics2-s3a-file-system.properties,hadoop-metrics2.properties
[2025-01-24T15:15:53.088+0000] {spark_submit.py:579} INFO - 25/01/24 15:15:53 INFO MetricsSystemImpl: Scheduled Metric snapshot period at 10 second(s).
[2025-01-24T15:15:53.089+0000] {spark_submit.py:579} INFO - 25/01/24 15:15:53 INFO MetricsSystemImpl: s3a-file-system metrics system started
[2025-01-24T15:15:53.927+0000] {spark_submit.py:579} INFO - 25/01/24 15:15:53 INFO CoarseGrainedSchedulerBackend$DriverEndpoint: Registered executor NettyRpcEndpointRef(spark-client://Executor) (172.18.0.10:39232) with ID 0,  ResourceProfileId 0
[2025-01-24T15:15:54.006+0000] {spark_submit.py:579} INFO - 25/01/24 15:15:54 INFO BlockManagerMasterEndpoint: Registering block manager 172.18.0.10:45289 with 1048.8 MiB RAM, BlockManagerId(0, 172.18.0.10, 45289, None)
[2025-01-24T15:15:55.798+0000] {spark_submit.py:579} INFO - 25/01/24 15:15:55 INFO InMemoryFileIndex: It took 117 ms to list leaf files for 1 paths.
[2025-01-24T15:15:56.466+0000] {spark_submit.py:579} INFO - 25/01/24 15:15:56 INFO SparkContext: Starting job: load at NativeMethodAccessorImpl.java:0
[2025-01-24T15:15:56.489+0000] {spark_submit.py:579} INFO - 25/01/24 15:15:56 INFO DAGScheduler: Got job 0 (load at NativeMethodAccessorImpl.java:0) with 1 output partitions
[2025-01-24T15:15:56.490+0000] {spark_submit.py:579} INFO - 25/01/24 15:15:56 INFO DAGScheduler: Final stage: ResultStage 0 (load at NativeMethodAccessorImpl.java:0)
[2025-01-24T15:15:56.491+0000] {spark_submit.py:579} INFO - 25/01/24 15:15:56 INFO DAGScheduler: Parents of final stage: List()
[2025-01-24T15:15:56.493+0000] {spark_submit.py:579} INFO - 25/01/24 15:15:56 INFO DAGScheduler: Missing parents: List()
[2025-01-24T15:15:56.500+0000] {spark_submit.py:579} INFO - 25/01/24 15:15:56 INFO DAGScheduler: Submitting ResultStage 0 (MapPartitionsRDD[1] at load at NativeMethodAccessorImpl.java:0), which has no missing parents
[2025-01-24T15:15:56.605+0000] {spark_submit.py:579} INFO - 25/01/24 15:15:56 INFO MemoryStore: Block broadcast_0 stored as values in memory (estimated size 104.8 KiB, free 434.3 MiB)
[2025-01-24T15:15:56.824+0000] {spark_submit.py:579} INFO - 25/01/24 15:15:56 INFO MemoryStore: Block broadcast_0_piece0 stored as bytes in memory (estimated size 37.8 KiB, free 434.3 MiB)
[2025-01-24T15:15:56.835+0000] {spark_submit.py:579} INFO - 25/01/24 15:15:56 INFO BlockManagerInfo: Added broadcast_0_piece0 in memory on 73fc507ad5e4:46429 (size: 37.8 KiB, free: 434.4 MiB)
[2025-01-24T15:15:56.842+0000] {spark_submit.py:579} INFO - 25/01/24 15:15:56 INFO SparkContext: Created broadcast 0 from broadcast at DAGScheduler.scala:1513
[2025-01-24T15:15:56.864+0000] {spark_submit.py:579} INFO - 25/01/24 15:15:56 INFO DAGScheduler: Submitting 1 missing tasks from ResultStage 0 (MapPartitionsRDD[1] at load at NativeMethodAccessorImpl.java:0) (first 15 tasks are for partitions Vector(0))
[2025-01-24T15:15:56.866+0000] {spark_submit.py:579} INFO - 25/01/24 15:15:56 INFO TaskSchedulerImpl: Adding task set 0.0 with 1 tasks resource profile 0
[2025-01-24T15:15:57.065+0000] {spark_submit.py:579} INFO - 25/01/24 15:15:57 INFO TaskSetManager: Starting task 0.0 in stage 0.0 (TID 0) (172.18.0.10, executor 0, partition 0, PROCESS_LOCAL, 4591 bytes) taskResourceAssignments Map()
[2025-01-24T15:15:57.272+0000] {spark_submit.py:579} INFO - 25/01/24 15:15:57 INFO BlockManagerInfo: Added broadcast_0_piece0 in memory on 172.18.0.10:45289 (size: 37.8 KiB, free: 1048.8 MiB)
[2025-01-24T15:15:59.164+0000] {spark_submit.py:579} INFO - 25/01/24 15:15:59 INFO TaskSetManager: Finished task 0.0 in stage 0.0 (TID 0) in 2109 ms on 172.18.0.10 (executor 0) (1/1)
[2025-01-24T15:15:59.166+0000] {spark_submit.py:579} INFO - 25/01/24 15:15:59 INFO TaskSchedulerImpl: Removed TaskSet 0.0, whose tasks have all completed, from pool
[2025-01-24T15:15:59.172+0000] {spark_submit.py:579} INFO - 25/01/24 15:15:59 INFO DAGScheduler: ResultStage 0 (load at NativeMethodAccessorImpl.java:0) finished in 2.642 s
[2025-01-24T15:15:59.175+0000] {spark_submit.py:579} INFO - 25/01/24 15:15:59 INFO DAGScheduler: Job 0 is finished. Cancelling potential speculative or zombie tasks for this job
[2025-01-24T15:15:59.176+0000] {spark_submit.py:579} INFO - 25/01/24 15:15:59 INFO TaskSchedulerImpl: Killing all running tasks in stage 0: Stage finished
[2025-01-24T15:15:59.178+0000] {spark_submit.py:579} INFO - 25/01/24 15:15:59 INFO DAGScheduler: Job 0 finished: load at NativeMethodAccessorImpl.java:0, took 2.711118 s
[2025-01-24T15:15:59.602+0000] {spark_submit.py:579} INFO - 25/01/24 15:15:59 INFO BlockManagerInfo: Removed broadcast_0_piece0 on 73fc507ad5e4:46429 in memory (size: 37.8 KiB, free: 434.4 MiB)
[2025-01-24T15:15:59.606+0000] {spark_submit.py:579} INFO - 25/01/24 15:15:59 INFO BlockManagerInfo: Removed broadcast_0_piece0 on 172.18.0.10:45289 in memory (size: 37.8 KiB, free: 1048.8 MiB)
[2025-01-24T15:16:00.900+0000] {spark_submit.py:579} INFO - 2025-01-24 15:16:00,900 INFO: Cleaning data...
[2025-01-24T15:16:01.075+0000] {spark_submit.py:579} INFO - 2025-01-24 15:16:01,075 INFO: Data cleaned and transformed.
[2025-01-24T15:16:01.076+0000] {spark_submit.py:579} INFO - 2025-01-24 15:16:01,075 INFO: Saving cleaned data to s3a://lakehouse/silver/keywords
[2025-01-24T15:16:02.061+0000] {spark_submit.py:579} INFO - 25/01/24 15:16:02 INFO DeltaLog: Loading version 4.
[2025-01-24T15:16:02.113+0000] {spark_submit.py:579} INFO - 25/01/24 15:16:02 INFO Snapshot: [tableId=8c0e5d9d-7d0a-4407-a8df-bced3c3eae09] DELTA: Compute snapshot for version: 4
[2025-01-24T15:16:02.345+0000] {spark_submit.py:579} INFO - 25/01/24 15:16:02 INFO MemoryStore: Block broadcast_1 stored as values in memory (estimated size 202.8 KiB, free 434.2 MiB)
[2025-01-24T15:16:02.376+0000] {spark_submit.py:579} INFO - 25/01/24 15:16:02 INFO MemoryStore: Block broadcast_1_piece0 stored as bytes in memory (estimated size 35.1 KiB, free 434.2 MiB)
[2025-01-24T15:16:02.400+0000] {spark_submit.py:579} INFO - 25/01/24 15:16:02 INFO BlockManagerInfo: Added broadcast_1_piece0 in memory on 73fc507ad5e4:46429 (size: 35.1 KiB, free: 434.4 MiB)
[2025-01-24T15:16:02.415+0000] {spark_submit.py:579} INFO - 25/01/24 15:16:02 INFO SparkContext: Created broadcast 1 from toString at String.java:2951
[2025-01-24T15:16:02.531+0000] {spark_submit.py:579} INFO - 25/01/24 15:16:02 INFO DeltaLogFileIndex: Created DeltaLogFileIndex(JSON, numFilesInSegment: 5, totalFileSize: 8667)
[2025-01-24T15:16:04.729+0000] {spark_submit.py:579} INFO - 25/01/24 15:16:04 INFO FileSourceStrategy: Pushed Filters:
[2025-01-24T15:16:04.731+0000] {spark_submit.py:579} INFO - 25/01/24 15:16:04 INFO FileSourceStrategy: Post-Scan Filters:
[2025-01-24T15:16:04.735+0000] {spark_submit.py:579} INFO - 25/01/24 15:16:04 INFO FileSourceStrategy: Output Data Schema: struct<txn: struct<appId: string, version: bigint, lastUpdated: bigint ... 1 more fields>, add: struct<path: string, partitionValues: map<string,string>, size: bigint, modificationTime: bigint, dataChange: boolean ... 5 more fields>, remove: struct<path: string, deletionTimestamp: bigint, dataChange: boolean, extendedFileMetadata: boolean, partitionValues: map<string,string> ... 5 more fields>, metaData: struct<id: string, name: string, description: string, format: struct<provider: string, options: map<string,string>>, schemaString: string ... 6 more fields>, protocol: struct<minReaderVersion: int, minWriterVersion: int> ... 5 more fields>
[2025-01-24T15:16:04.864+0000] {spark_submit.py:579} INFO - 25/01/24 15:16:04 WARN package: Truncated the string representation of a plan since it was too large. This behavior can be adjusted by setting 'spark.sql.debug.maxToStringFields'.
[2025-01-24T15:16:06.415+0000] {spark_submit.py:579} INFO - 25/01/24 15:16:06 INFO CodeGenerator: Code generated in 1080.005697 ms
[2025-01-24T15:16:06.437+0000] {spark_submit.py:579} INFO - 25/01/24 15:16:06 INFO MemoryStore: Block broadcast_2 stored as values in memory (estimated size 203.1 KiB, free 434.0 MiB)
[2025-01-24T15:16:06.467+0000] {spark_submit.py:579} INFO - 25/01/24 15:16:06 INFO MemoryStore: Block broadcast_2_piece0 stored as bytes in memory (estimated size 35.2 KiB, free 433.9 MiB)
[2025-01-24T15:16:06.477+0000] {spark_submit.py:579} INFO - 25/01/24 15:16:06 INFO BlockManagerInfo: Added broadcast_2_piece0 in memory on 73fc507ad5e4:46429 (size: 35.2 KiB, free: 434.3 MiB)
[2025-01-24T15:16:06.484+0000] {spark_submit.py:579} INFO - 25/01/24 15:16:06 INFO SparkContext: Created broadcast 2 from toString at String.java:2951
[2025-01-24T15:16:06.559+0000] {spark_submit.py:579} INFO - 25/01/24 15:16:06 INFO FileSourceScanExec: Planning scan with bin packing, max size: 10490093 bytes, open cost is considered as scanning 4194304 bytes.
[2025-01-24T15:16:07.022+0000] {spark_submit.py:579} INFO - 25/01/24 15:16:07 INFO DAGScheduler: Registering RDD 5 (toString at String.java:2951) as input to shuffle 0
[2025-01-24T15:16:07.029+0000] {spark_submit.py:579} INFO - 25/01/24 15:16:07 INFO DAGScheduler: Got map stage job 1 (toString at String.java:2951) with 2 output partitions
[2025-01-24T15:16:07.030+0000] {spark_submit.py:579} INFO - 25/01/24 15:16:07 INFO DAGScheduler: Final stage: ShuffleMapStage 1 (toString at String.java:2951)
[2025-01-24T15:16:07.031+0000] {spark_submit.py:579} INFO - 25/01/24 15:16:07 INFO DAGScheduler: Parents of final stage: List()
[2025-01-24T15:16:07.032+0000] {spark_submit.py:579} INFO - 25/01/24 15:16:07 INFO DAGScheduler: Missing parents: List()
[2025-01-24T15:16:07.043+0000] {spark_submit.py:579} INFO - 25/01/24 15:16:07 INFO DAGScheduler: Submitting ShuffleMapStage 1 (MapPartitionsRDD[5] at toString at String.java:2951), which has no missing parents
[2025-01-24T15:16:07.135+0000] {spark_submit.py:579} INFO - 25/01/24 15:16:07 INFO MemoryStore: Block broadcast_3 stored as values in memory (estimated size 124.3 KiB, free 433.8 MiB)
[2025-01-24T15:16:07.192+0000] {spark_submit.py:579} INFO - 25/01/24 15:16:07 INFO MemoryStore: Block broadcast_3_piece0 stored as bytes in memory (estimated size 35.1 KiB, free 433.8 MiB)
[2025-01-24T15:16:07.192+0000] {spark_submit.py:579} INFO - 25/01/24 15:16:07 INFO BlockManagerInfo: Added broadcast_3_piece0 in memory on 73fc507ad5e4:46429 (size: 35.1 KiB, free: 434.3 MiB)
[2025-01-24T15:16:07.193+0000] {spark_submit.py:579} INFO - 25/01/24 15:16:07 INFO SparkContext: Created broadcast 3 from broadcast at DAGScheduler.scala:1513
[2025-01-24T15:16:07.195+0000] {spark_submit.py:579} INFO - 25/01/24 15:16:07 INFO DAGScheduler: Submitting 2 missing tasks from ShuffleMapStage 1 (MapPartitionsRDD[5] at toString at String.java:2951) (first 15 tasks are for partitions Vector(0, 1))
[2025-01-24T15:16:07.196+0000] {spark_submit.py:579} INFO - 25/01/24 15:16:07 INFO TaskSchedulerImpl: Adding task set 1.0 with 2 tasks resource profile 0
[2025-01-24T15:16:07.205+0000] {spark_submit.py:579} INFO - 25/01/24 15:16:07 INFO TaskSetManager: Starting task 0.0 in stage 1.0 (TID 1) (172.18.0.10, executor 0, partition 0, PROCESS_LOCAL, 5160 bytes) taskResourceAssignments Map()
[2025-01-24T15:16:07.206+0000] {spark_submit.py:579} INFO - 25/01/24 15:16:07 INFO TaskSetManager: Starting task 1.0 in stage 1.0 (TID 2) (172.18.0.10, executor 0, partition 1, PROCESS_LOCAL, 5046 bytes) taskResourceAssignments Map()
[2025-01-24T15:16:07.273+0000] {spark_submit.py:579} INFO - 25/01/24 15:16:07 INFO BlockManagerInfo: Added broadcast_3_piece0 in memory on 172.18.0.10:45289 (size: 35.1 KiB, free: 1048.8 MiB)
[2025-01-24T15:16:09.678+0000] {spark_submit.py:579} INFO - 25/01/24 15:16:09 INFO BlockManagerInfo: Added broadcast_2_piece0 in memory on 172.18.0.10:45289 (size: 35.2 KiB, free: 1048.7 MiB)
[2025-01-24T15:16:11.707+0000] {spark_submit.py:579} INFO - 25/01/24 15:16:11 INFO TaskSetManager: Finished task 1.0 in stage 1.0 (TID 2) in 4503 ms on 172.18.0.10 (executor 0) (1/2)
[2025-01-24T15:16:11.736+0000] {spark_submit.py:579} INFO - 25/01/24 15:16:11 INFO TaskSetManager: Finished task 0.0 in stage 1.0 (TID 1) in 4539 ms on 172.18.0.10 (executor 0) (2/2)
[2025-01-24T15:16:11.737+0000] {spark_submit.py:579} INFO - 25/01/24 15:16:11 INFO TaskSchedulerImpl: Removed TaskSet 1.0, whose tasks have all completed, from pool
[2025-01-24T15:16:11.738+0000] {spark_submit.py:579} INFO - 25/01/24 15:16:11 INFO DAGScheduler: ShuffleMapStage 1 (toString at String.java:2951) finished in 4.683 s
[2025-01-24T15:16:11.741+0000] {spark_submit.py:579} INFO - 25/01/24 15:16:11 INFO DAGScheduler: looking for newly runnable stages
[2025-01-24T15:16:11.742+0000] {spark_submit.py:579} INFO - 25/01/24 15:16:11 INFO DAGScheduler: running: Set()
[2025-01-24T15:16:11.743+0000] {spark_submit.py:579} INFO - 25/01/24 15:16:11 INFO DAGScheduler: waiting: Set()
[2025-01-24T15:16:11.746+0000] {spark_submit.py:579} INFO - 25/01/24 15:16:11 INFO DAGScheduler: failed: Set()
[2025-01-24T15:16:12.027+0000] {spark_submit.py:579} INFO - 25/01/24 15:16:12 INFO BlockManagerInfo: Removed broadcast_3_piece0 on 172.18.0.10:45289 in memory (size: 35.1 KiB, free: 1048.8 MiB)
[2025-01-24T15:16:12.050+0000] {spark_submit.py:579} INFO - 25/01/24 15:16:12 INFO BlockManagerInfo: Removed broadcast_3_piece0 on 73fc507ad5e4:46429 in memory (size: 35.1 KiB, free: 434.3 MiB)
[2025-01-24T15:16:12.386+0000] {spark_submit.py:579} INFO - 25/01/24 15:16:12 INFO CodeGenerator: Generated method too long to be JIT compiled: org.apache.spark.sql.catalyst.expressions.GeneratedClass$GeneratedIteratorForCodegenStage3.serializefromobject_doConsume_0$ is 14899 bytes
[2025-01-24T15:16:12.388+0000] {spark_submit.py:579} INFO - 25/01/24 15:16:12 INFO CodeGenerator: Code generated in 331.171328 ms
[2025-01-24T15:16:12.493+0000] {spark_submit.py:579} INFO - 25/01/24 15:16:12 INFO CodeGenerator: Code generated in 61.710389 ms
[2025-01-24T15:16:12.977+0000] {spark_submit.py:579} INFO - 25/01/24 15:16:12 INFO CodeGenerator: Code generated in 59.350424 ms
[2025-01-24T15:16:12.992+0000] {spark_submit.py:579} INFO - 25/01/24 15:16:12 INFO DAGScheduler: Registering RDD 15 (toString at String.java:2951) as input to shuffle 1
[2025-01-24T15:16:12.993+0000] {spark_submit.py:579} INFO - 25/01/24 15:16:12 INFO DAGScheduler: Got map stage job 2 (toString at String.java:2951) with 50 output partitions
[2025-01-24T15:16:12.993+0000] {spark_submit.py:579} INFO - 25/01/24 15:16:12 INFO DAGScheduler: Final stage: ShuffleMapStage 3 (toString at String.java:2951)
[2025-01-24T15:16:12.995+0000] {spark_submit.py:579} INFO - 25/01/24 15:16:12 INFO DAGScheduler: Parents of final stage: List(ShuffleMapStage 2)
[2025-01-24T15:16:12.998+0000] {spark_submit.py:579} INFO - 25/01/24 15:16:12 INFO DAGScheduler: Missing parents: List()
[2025-01-24T15:16:13.015+0000] {spark_submit.py:579} INFO - 25/01/24 15:16:13 INFO DAGScheduler: Submitting ShuffleMapStage 3 (MapPartitionsRDD[15] at toString at String.java:2951), which has no missing parents
[2025-01-24T15:16:13.216+0000] {spark_submit.py:579} INFO - 25/01/24 15:16:13 INFO MemoryStore: Block broadcast_4 stored as values in memory (estimated size 425.0 KiB, free 433.5 MiB)
[2025-01-24T15:16:13.224+0000] {spark_submit.py:579} INFO - 25/01/24 15:16:13 INFO MemoryStore: Block broadcast_4_piece0 stored as bytes in memory (estimated size 102.2 KiB, free 433.4 MiB)
[2025-01-24T15:16:13.242+0000] {spark_submit.py:579} INFO - 25/01/24 15:16:13 INFO BlockManagerInfo: Added broadcast_4_piece0 in memory on 73fc507ad5e4:46429 (size: 102.2 KiB, free: 434.2 MiB)
[2025-01-24T15:16:13.244+0000] {spark_submit.py:579} INFO - 25/01/24 15:16:13 INFO SparkContext: Created broadcast 4 from broadcast at DAGScheduler.scala:1513
[2025-01-24T15:16:13.246+0000] {spark_submit.py:579} INFO - 25/01/24 15:16:13 INFO DAGScheduler: Submitting 50 missing tasks from ShuffleMapStage 3 (MapPartitionsRDD[15] at toString at String.java:2951) (first 15 tasks are for partitions Vector(0, 1, 2, 3, 4, 5, 6, 7, 8, 9, 10, 11, 12, 13, 14))
[2025-01-24T15:16:13.247+0000] {spark_submit.py:579} INFO - 25/01/24 15:16:13 INFO TaskSchedulerImpl: Adding task set 3.0 with 50 tasks resource profile 0
[2025-01-24T15:16:13.256+0000] {spark_submit.py:579} INFO - 25/01/24 15:16:13 INFO TaskSetManager: Starting task 4.0 in stage 3.0 (TID 3) (172.18.0.10, executor 0, partition 4, NODE_LOCAL, 4446 bytes) taskResourceAssignments Map()
[2025-01-24T15:16:13.259+0000] {spark_submit.py:579} INFO - 25/01/24 15:16:13 INFO TaskSetManager: Starting task 15.0 in stage 3.0 (TID 4) (172.18.0.10, executor 0, partition 15, NODE_LOCAL, 4446 bytes) taskResourceAssignments Map()
[2025-01-24T15:16:13.289+0000] {spark_submit.py:579} INFO - 25/01/24 15:16:13 INFO BlockManagerInfo: Added broadcast_4_piece0 in memory on 172.18.0.10:45289 (size: 102.2 KiB, free: 1048.7 MiB)
[2025-01-24T15:16:13.759+0000] {spark_submit.py:579} INFO - 25/01/24 15:16:13 INFO MapOutputTrackerMasterEndpoint: Asked to send map output locations for shuffle 0 to 172.18.0.10:39232
[2025-01-24T15:16:14.749+0000] {spark_submit.py:579} INFO - 25/01/24 15:16:14 INFO BlockManagerInfo: Added rdd_12_4 in memory on 172.18.0.10:45289 (size: 293.0 B, free: 1048.7 MiB)
[2025-01-24T15:16:14.754+0000] {spark_submit.py:579} INFO - 25/01/24 15:16:14 INFO BlockManagerInfo: Added rdd_12_15 in memory on 172.18.0.10:45289 (size: 293.0 B, free: 1048.7 MiB)
[2025-01-24T15:16:15.263+0000] {spark_submit.py:579} INFO - 25/01/24 15:16:15 INFO TaskSetManager: Starting task 16.0 in stage 3.0 (TID 5) (172.18.0.10, executor 0, partition 16, NODE_LOCAL, 4446 bytes) taskResourceAssignments Map()
[2025-01-24T15:16:15.264+0000] {spark_submit.py:579} INFO - 25/01/24 15:16:15 INFO TaskSetManager: Starting task 23.0 in stage 3.0 (TID 6) (172.18.0.10, executor 0, partition 23, NODE_LOCAL, 4446 bytes) taskResourceAssignments Map()
[2025-01-24T15:16:15.268+0000] {spark_submit.py:579} INFO - 25/01/24 15:16:15 INFO TaskSetManager: Finished task 15.0 in stage 3.0 (TID 4) in 2010 ms on 172.18.0.10 (executor 0) (1/50)
[2025-01-24T15:16:15.309+0000] {spark_submit.py:579} INFO - 25/01/24 15:16:15 INFO TaskSetManager: Finished task 4.0 in stage 3.0 (TID 3) in 2056 ms on 172.18.0.10 (executor 0) (2/50)
[2025-01-24T15:16:15.405+0000] {spark_submit.py:579} INFO - 25/01/24 15:16:15 INFO BlockManagerInfo: Added rdd_12_16 in memory on 172.18.0.10:45289 (size: 294.0 B, free: 1048.7 MiB)
[2025-01-24T15:16:15.431+0000] {spark_submit.py:579} INFO - 25/01/24 15:16:15 INFO BlockManagerInfo: Added rdd_12_23 in memory on 172.18.0.10:45289 (size: 479.0 B, free: 1048.7 MiB)
[2025-01-24T15:16:15.522+0000] {spark_submit.py:579} INFO - 25/01/24 15:16:15 INFO TaskSetManager: Starting task 24.0 in stage 3.0 (TID 7) (172.18.0.10, executor 0, partition 24, NODE_LOCAL, 4446 bytes) taskResourceAssignments Map()
[2025-01-24T15:16:15.530+0000] {spark_submit.py:579} INFO - 25/01/24 15:16:15 INFO TaskSetManager: Finished task 16.0 in stage 3.0 (TID 5) in 269 ms on 172.18.0.10 (executor 0) (3/50)
[2025-01-24T15:16:15.535+0000] {spark_submit.py:579} INFO - 25/01/24 15:16:15 INFO TaskSetManager: Starting task 36.0 in stage 3.0 (TID 8) (172.18.0.10, executor 0, partition 36, NODE_LOCAL, 4446 bytes) taskResourceAssignments Map()
[2025-01-24T15:16:15.538+0000] {spark_submit.py:579} INFO - 25/01/24 15:16:15 INFO TaskSetManager: Finished task 23.0 in stage 3.0 (TID 6) in 272 ms on 172.18.0.10 (executor 0) (4/50)
[2025-01-24T15:16:15.628+0000] {spark_submit.py:579} INFO - 25/01/24 15:16:15 INFO BlockManagerInfo: Added rdd_12_36 in memory on 172.18.0.10:45289 (size: 293.0 B, free: 1048.7 MiB)
[2025-01-24T15:16:15.629+0000] {spark_submit.py:579} INFO - 25/01/24 15:16:15 INFO BlockManagerInfo: Added rdd_12_24 in memory on 172.18.0.10:45289 (size: 294.0 B, free: 1048.7 MiB)
[2025-01-24T15:16:15.674+0000] {spark_submit.py:579} INFO - 25/01/24 15:16:15 INFO TaskSetManager: Starting task 37.0 in stage 3.0 (TID 9) (172.18.0.10, executor 0, partition 37, NODE_LOCAL, 4446 bytes) taskResourceAssignments Map()
[2025-01-24T15:16:15.676+0000] {spark_submit.py:579} INFO - 25/01/24 15:16:15 INFO TaskSetManager: Finished task 36.0 in stage 3.0 (TID 8) in 142 ms on 172.18.0.10 (executor 0) (5/50)
[2025-01-24T15:16:15.693+0000] {spark_submit.py:579} INFO - 25/01/24 15:16:15 INFO TaskSetManager: Starting task 38.0 in stage 3.0 (TID 10) (172.18.0.10, executor 0, partition 38, NODE_LOCAL, 4446 bytes) taskResourceAssignments Map()
[2025-01-24T15:16:15.702+0000] {spark_submit.py:579} INFO - 25/01/24 15:16:15 INFO TaskSetManager: Finished task 24.0 in stage 3.0 (TID 7) in 179 ms on 172.18.0.10 (executor 0) (6/50)
[2025-01-24T15:16:15.784+0000] {spark_submit.py:579} INFO - 25/01/24 15:16:15 INFO BlockManagerInfo: Added rdd_12_38 in memory on 172.18.0.10:45289 (size: 294.0 B, free: 1048.7 MiB)
[2025-01-24T15:16:15.824+0000] {spark_submit.py:579} INFO - 25/01/24 15:16:15 INFO BlockManagerInfo: Added rdd_12_37 in memory on 172.18.0.10:45289 (size: 293.0 B, free: 1048.7 MiB)
[2025-01-24T15:16:15.841+0000] {spark_submit.py:579} INFO - 25/01/24 15:16:15 INFO TaskSetManager: Starting task 42.0 in stage 3.0 (TID 11) (172.18.0.10, executor 0, partition 42, NODE_LOCAL, 4446 bytes) taskResourceAssignments Map()
[2025-01-24T15:16:15.842+0000] {spark_submit.py:579} INFO - 25/01/24 15:16:15 INFO TaskSetManager: Finished task 38.0 in stage 3.0 (TID 10) in 148 ms on 172.18.0.10 (executor 0) (7/50)
[2025-01-24T15:16:15.911+0000] {spark_submit.py:579} INFO - 25/01/24 15:16:15 INFO TaskSetManager: Starting task 44.0 in stage 3.0 (TID 12) (172.18.0.10, executor 0, partition 44, NODE_LOCAL, 4446 bytes) taskResourceAssignments Map()
[2025-01-24T15:16:15.913+0000] {spark_submit.py:579} INFO - 25/01/24 15:16:15 INFO TaskSetManager: Finished task 37.0 in stage 3.0 (TID 9) in 240 ms on 172.18.0.10 (executor 0) (8/50)
[2025-01-24T15:16:16.040+0000] {spark_submit.py:579} INFO - 25/01/24 15:16:16 INFO BlockManagerInfo: Added rdd_12_44 in memory on 172.18.0.10:45289 (size: 473.0 B, free: 1048.7 MiB)
[2025-01-24T15:16:16.131+0000] {spark_submit.py:579} INFO - 25/01/24 15:16:16 INFO TaskSetManager: Starting task 46.0 in stage 3.0 (TID 13) (172.18.0.10, executor 0, partition 46, NODE_LOCAL, 4446 bytes) taskResourceAssignments Map()
[2025-01-24T15:16:16.133+0000] {spark_submit.py:579} INFO - 25/01/24 15:16:16 INFO TaskSetManager: Finished task 44.0 in stage 3.0 (TID 12) in 219 ms on 172.18.0.10 (executor 0) (9/50)
[2025-01-24T15:16:16.251+0000] {spark_submit.py:579} INFO - 25/01/24 15:16:16 INFO BlockManagerInfo: Added rdd_12_46 in memory on 172.18.0.10:45289 (size: 294.0 B, free: 1048.7 MiB)
[2025-01-24T15:16:16.306+0000] {spark_submit.py:579} INFO - 25/01/24 15:16:16 INFO TaskSetManager: Starting task 0.0 in stage 3.0 (TID 14) (172.18.0.10, executor 0, partition 0, PROCESS_LOCAL, 4446 bytes) taskResourceAssignments Map()
[2025-01-24T15:16:16.308+0000] {spark_submit.py:579} INFO - 25/01/24 15:16:16 INFO TaskSetManager: Finished task 46.0 in stage 3.0 (TID 13) in 182 ms on 172.18.0.10 (executor 0) (10/50)
[2025-01-24T15:16:16.426+0000] {spark_submit.py:579} INFO - 25/01/24 15:16:16 INFO BlockManagerInfo: Added rdd_12_0 in memory on 172.18.0.10:45289 (size: 46.0 B, free: 1048.7 MiB)
[2025-01-24T15:16:16.486+0000] {spark_submit.py:579} INFO - 25/01/24 15:16:16 INFO TaskSetManager: Starting task 1.0 in stage 3.0 (TID 15) (172.18.0.10, executor 0, partition 1, PROCESS_LOCAL, 4446 bytes) taskResourceAssignments Map()
[2025-01-24T15:16:16.489+0000] {spark_submit.py:579} INFO - 25/01/24 15:16:16 INFO BlockManagerInfo: Added rdd_12_42 in memory on 172.18.0.10:45289 (size: 468.0 B, free: 1048.7 MiB)
[2025-01-24T15:16:16.491+0000] {spark_submit.py:579} INFO - 25/01/24 15:16:16 INFO TaskSetManager: Finished task 0.0 in stage 3.0 (TID 14) in 181 ms on 172.18.0.10 (executor 0) (11/50)
[2025-01-24T15:16:16.557+0000] {spark_submit.py:579} INFO - 25/01/24 15:16:16 INFO TaskSetManager: Starting task 2.0 in stage 3.0 (TID 16) (172.18.0.10, executor 0, partition 2, PROCESS_LOCAL, 4446 bytes) taskResourceAssignments Map()
[2025-01-24T15:16:16.558+0000] {spark_submit.py:579} INFO - 25/01/24 15:16:16 INFO TaskSetManager: Finished task 42.0 in stage 3.0 (TID 11) in 724 ms on 172.18.0.10 (executor 0) (12/50)
[2025-01-24T15:16:16.582+0000] {spark_submit.py:579} INFO - 25/01/24 15:16:16 INFO BlockManagerInfo: Added rdd_12_1 in memory on 172.18.0.10:45289 (size: 46.0 B, free: 1048.7 MiB)
[2025-01-24T15:16:16.639+0000] {spark_submit.py:579} INFO - 25/01/24 15:16:16 INFO TaskSetManager: Starting task 3.0 in stage 3.0 (TID 17) (172.18.0.10, executor 0, partition 3, PROCESS_LOCAL, 4446 bytes) taskResourceAssignments Map()
[2025-01-24T15:16:16.642+0000] {spark_submit.py:579} INFO - 25/01/24 15:16:16 INFO TaskSetManager: Finished task 1.0 in stage 3.0 (TID 15) in 157 ms on 172.18.0.10 (executor 0) (13/50)
[2025-01-24T15:16:16.674+0000] {spark_submit.py:579} INFO - 25/01/24 15:16:16 INFO BlockManagerInfo: Added rdd_12_2 in memory on 172.18.0.10:45289 (size: 46.0 B, free: 1048.7 MiB)
[2025-01-24T15:16:16.737+0000] {spark_submit.py:579} INFO - 25/01/24 15:16:16 INFO TaskSetManager: Starting task 5.0 in stage 3.0 (TID 18) (172.18.0.10, executor 0, partition 5, PROCESS_LOCAL, 4446 bytes) taskResourceAssignments Map()
[2025-01-24T15:16:16.738+0000] {spark_submit.py:579} INFO - 25/01/24 15:16:16 INFO TaskSetManager: Finished task 2.0 in stage 3.0 (TID 16) in 182 ms on 172.18.0.10 (executor 0) (14/50)
[2025-01-24T15:16:16.776+0000] {spark_submit.py:579} INFO - 25/01/24 15:16:16 INFO BlockManagerInfo: Added rdd_12_3 in memory on 172.18.0.10:45289 (size: 46.0 B, free: 1048.7 MiB)
[2025-01-24T15:16:16.845+0000] {spark_submit.py:579} INFO - 25/01/24 15:16:16 INFO TaskSetManager: Starting task 6.0 in stage 3.0 (TID 19) (172.18.0.10, executor 0, partition 6, PROCESS_LOCAL, 4446 bytes) taskResourceAssignments Map()
[2025-01-24T15:16:16.847+0000] {spark_submit.py:579} INFO - 25/01/24 15:16:16 INFO TaskSetManager: Finished task 3.0 in stage 3.0 (TID 17) in 206 ms on 172.18.0.10 (executor 0) (15/50)
[2025-01-24T15:16:16.848+0000] {spark_submit.py:579} INFO - 25/01/24 15:16:16 INFO BlockManagerInfo: Added rdd_12_5 in memory on 172.18.0.10:45289 (size: 46.0 B, free: 1048.7 MiB)
[2025-01-24T15:16:16.885+0000] {spark_submit.py:579} INFO - 25/01/24 15:16:16 INFO TaskSetManager: Starting task 7.0 in stage 3.0 (TID 20) (172.18.0.10, executor 0, partition 7, PROCESS_LOCAL, 4446 bytes) taskResourceAssignments Map()
[2025-01-24T15:16:16.888+0000] {spark_submit.py:579} INFO - 25/01/24 15:16:16 INFO TaskSetManager: Finished task 5.0 in stage 3.0 (TID 18) in 151 ms on 172.18.0.10 (executor 0) (16/50)
[2025-01-24T15:16:16.936+0000] {spark_submit.py:579} INFO - 25/01/24 15:16:16 INFO BlockManagerInfo: Added rdd_12_6 in memory on 172.18.0.10:45289 (size: 46.0 B, free: 1048.7 MiB)
[2025-01-24T15:16:16.998+0000] {spark_submit.py:579} INFO - 25/01/24 15:16:16 INFO TaskSetManager: Starting task 8.0 in stage 3.0 (TID 21) (172.18.0.10, executor 0, partition 8, PROCESS_LOCAL, 4446 bytes) taskResourceAssignments Map()
[2025-01-24T15:16:17.000+0000] {spark_submit.py:579} INFO - 25/01/24 15:16:16 INFO TaskSetManager: Finished task 6.0 in stage 3.0 (TID 19) in 156 ms on 172.18.0.10 (executor 0) (17/50)
[2025-01-24T15:16:17.022+0000] {spark_submit.py:579} INFO - 25/01/24 15:16:17 INFO BlockManagerInfo: Added rdd_12_7 in memory on 172.18.0.10:45289 (size: 46.0 B, free: 1048.7 MiB)
[2025-01-24T15:16:17.074+0000] {spark_submit.py:579} INFO - 25/01/24 15:16:17 INFO TaskSetManager: Starting task 9.0 in stage 3.0 (TID 22) (172.18.0.10, executor 0, partition 9, PROCESS_LOCAL, 4446 bytes) taskResourceAssignments Map()
[2025-01-24T15:16:17.076+0000] {spark_submit.py:579} INFO - 25/01/24 15:16:17 INFO TaskSetManager: Finished task 7.0 in stage 3.0 (TID 20) in 192 ms on 172.18.0.10 (executor 0) (18/50)
[2025-01-24T15:16:17.095+0000] {spark_submit.py:579} INFO - 25/01/24 15:16:17 INFO BlockManagerInfo: Added rdd_12_8 in memory on 172.18.0.10:45289 (size: 46.0 B, free: 1048.7 MiB)
[2025-01-24T15:16:17.139+0000] {spark_submit.py:579} INFO - 25/01/24 15:16:17 INFO TaskSetManager: Starting task 10.0 in stage 3.0 (TID 23) (172.18.0.10, executor 0, partition 10, PROCESS_LOCAL, 4446 bytes) taskResourceAssignments Map()
[2025-01-24T15:16:17.141+0000] {spark_submit.py:579} INFO - 25/01/24 15:16:17 INFO TaskSetManager: Finished task 8.0 in stage 3.0 (TID 21) in 145 ms on 172.18.0.10 (executor 0) (19/50)
[2025-01-24T15:16:17.171+0000] {spark_submit.py:579} INFO - 25/01/24 15:16:17 INFO BlockManagerInfo: Added rdd_12_9 in memory on 172.18.0.10:45289 (size: 46.0 B, free: 1048.7 MiB)
[2025-01-24T15:16:17.249+0000] {spark_submit.py:579} INFO - 25/01/24 15:16:17 INFO TaskSetManager: Starting task 11.0 in stage 3.0 (TID 24) (172.18.0.10, executor 0, partition 11, PROCESS_LOCAL, 4446 bytes) taskResourceAssignments Map()
[2025-01-24T15:16:17.251+0000] {spark_submit.py:579} INFO - 25/01/24 15:16:17 INFO TaskSetManager: Finished task 9.0 in stage 3.0 (TID 22) in 176 ms on 172.18.0.10 (executor 0) (20/50)
[2025-01-24T15:16:17.256+0000] {spark_submit.py:579} INFO - 25/01/24 15:16:17 INFO BlockManagerInfo: Added rdd_12_10 in memory on 172.18.0.10:45289 (size: 46.0 B, free: 1048.7 MiB)
[2025-01-24T15:16:17.320+0000] {spark_submit.py:579} INFO - 25/01/24 15:16:17 INFO TaskSetManager: Starting task 12.0 in stage 3.0 (TID 25) (172.18.0.10, executor 0, partition 12, PROCESS_LOCAL, 4446 bytes) taskResourceAssignments Map()
[2025-01-24T15:16:17.321+0000] {spark_submit.py:579} INFO - 25/01/24 15:16:17 INFO TaskSetManager: Finished task 10.0 in stage 3.0 (TID 23) in 183 ms on 172.18.0.10 (executor 0) (21/50)
[2025-01-24T15:16:17.346+0000] {spark_submit.py:579} INFO - 25/01/24 15:16:17 INFO BlockManagerInfo: Added rdd_12_11 in memory on 172.18.0.10:45289 (size: 46.0 B, free: 1048.7 MiB)
[2025-01-24T15:16:17.395+0000] {spark_submit.py:579} INFO - 25/01/24 15:16:17 INFO TaskSetManager: Starting task 13.0 in stage 3.0 (TID 26) (172.18.0.10, executor 0, partition 13, PROCESS_LOCAL, 4446 bytes) taskResourceAssignments Map()
[2025-01-24T15:16:17.396+0000] {spark_submit.py:579} INFO - 25/01/24 15:16:17 INFO TaskSetManager: Finished task 11.0 in stage 3.0 (TID 24) in 147 ms on 172.18.0.10 (executor 0) (22/50)
[2025-01-24T15:16:17.401+0000] {spark_submit.py:579} INFO - 25/01/24 15:16:17 INFO BlockManagerInfo: Added rdd_12_12 in memory on 172.18.0.10:45289 (size: 46.0 B, free: 1048.7 MiB)
[2025-01-24T15:16:17.444+0000] {spark_submit.py:579} INFO - 25/01/24 15:16:17 INFO TaskSetManager: Starting task 14.0 in stage 3.0 (TID 27) (172.18.0.10, executor 0, partition 14, PROCESS_LOCAL, 4446 bytes) taskResourceAssignments Map()
[2025-01-24T15:16:17.446+0000] {spark_submit.py:579} INFO - 25/01/24 15:16:17 INFO TaskSetManager: Finished task 12.0 in stage 3.0 (TID 25) in 123 ms on 172.18.0.10 (executor 0) (23/50)
[2025-01-24T15:16:17.504+0000] {spark_submit.py:579} INFO - 25/01/24 15:16:17 INFO BlockManagerInfo: Added rdd_12_13 in memory on 172.18.0.10:45289 (size: 46.0 B, free: 1048.7 MiB)
[2025-01-24T15:16:17.522+0000] {spark_submit.py:579} INFO - 25/01/24 15:16:17 INFO BlockManagerInfo: Added rdd_12_14 in memory on 172.18.0.10:45289 (size: 46.0 B, free: 1048.7 MiB)
[2025-01-24T15:16:17.547+0000] {spark_submit.py:579} INFO - 25/01/24 15:16:17 INFO TaskSetManager: Starting task 17.0 in stage 3.0 (TID 28) (172.18.0.10, executor 0, partition 17, PROCESS_LOCAL, 4446 bytes) taskResourceAssignments Map()
[2025-01-24T15:16:17.549+0000] {spark_submit.py:579} INFO - 25/01/24 15:16:17 INFO TaskSetManager: Finished task 14.0 in stage 3.0 (TID 27) in 105 ms on 172.18.0.10 (executor 0) (24/50)
[2025-01-24T15:16:17.561+0000] {spark_submit.py:579} INFO - 25/01/24 15:16:17 INFO TaskSetManager: Starting task 18.0 in stage 3.0 (TID 29) (172.18.0.10, executor 0, partition 18, PROCESS_LOCAL, 4446 bytes) taskResourceAssignments Map()
[2025-01-24T15:16:17.564+0000] {spark_submit.py:579} INFO - 25/01/24 15:16:17 INFO TaskSetManager: Finished task 13.0 in stage 3.0 (TID 26) in 167 ms on 172.18.0.10 (executor 0) (25/50)
[2025-01-24T15:16:17.648+0000] {spark_submit.py:579} INFO - 25/01/24 15:16:17 INFO BlockManagerInfo: Added rdd_12_17 in memory on 172.18.0.10:45289 (size: 46.0 B, free: 1048.7 MiB)
[2025-01-24T15:16:17.698+0000] {spark_submit.py:579} INFO - 25/01/24 15:16:17 INFO BlockManagerInfo: Added rdd_12_18 in memory on 172.18.0.10:45289 (size: 46.0 B, free: 1048.7 MiB)
[2025-01-24T15:16:17.705+0000] {spark_submit.py:579} INFO - 25/01/24 15:16:17 INFO TaskSetManager: Starting task 19.0 in stage 3.0 (TID 30) (172.18.0.10, executor 0, partition 19, PROCESS_LOCAL, 4446 bytes) taskResourceAssignments Map()
[2025-01-24T15:16:17.708+0000] {spark_submit.py:579} INFO - 25/01/24 15:16:17 INFO TaskSetManager: Finished task 17.0 in stage 3.0 (TID 28) in 154 ms on 172.18.0.10 (executor 0) (26/50)
[2025-01-24T15:16:17.728+0000] {spark_submit.py:579} INFO - 25/01/24 15:16:17 INFO TaskSetManager: Starting task 20.0 in stage 3.0 (TID 31) (172.18.0.10, executor 0, partition 20, PROCESS_LOCAL, 4446 bytes) taskResourceAssignments Map()
[2025-01-24T15:16:17.738+0000] {spark_submit.py:579} INFO - 25/01/24 15:16:17 INFO TaskSetManager: Finished task 18.0 in stage 3.0 (TID 29) in 168 ms on 172.18.0.10 (executor 0) (27/50)
[2025-01-24T15:16:17.810+0000] {spark_submit.py:579} INFO - 25/01/24 15:16:17 INFO BlockManagerInfo: Added rdd_12_19 in memory on 172.18.0.10:45289 (size: 46.0 B, free: 1048.7 MiB)
[2025-01-24T15:16:17.811+0000] {spark_submit.py:579} INFO - 25/01/24 15:16:17 INFO BlockManagerInfo: Added rdd_12_20 in memory on 172.18.0.10:45289 (size: 46.0 B, free: 1048.7 MiB)
[2025-01-24T15:16:17.857+0000] {spark_submit.py:579} INFO - 25/01/24 15:16:17 INFO TaskSetManager: Starting task 21.0 in stage 3.0 (TID 32) (172.18.0.10, executor 0, partition 21, PROCESS_LOCAL, 4446 bytes) taskResourceAssignments Map()
[2025-01-24T15:16:17.858+0000] {spark_submit.py:579} INFO - 25/01/24 15:16:17 INFO TaskSetManager: Finished task 20.0 in stage 3.0 (TID 31) in 138 ms on 172.18.0.10 (executor 0) (28/50)
[2025-01-24T15:16:17.867+0000] {spark_submit.py:579} INFO - 25/01/24 15:16:17 INFO TaskSetManager: Starting task 22.0 in stage 3.0 (TID 33) (172.18.0.10, executor 0, partition 22, PROCESS_LOCAL, 4446 bytes) taskResourceAssignments Map()
[2025-01-24T15:16:17.868+0000] {spark_submit.py:579} INFO - 25/01/24 15:16:17 INFO TaskSetManager: Finished task 19.0 in stage 3.0 (TID 30) in 168 ms on 172.18.0.10 (executor 0) (29/50)
[2025-01-24T15:16:17.917+0000] {spark_submit.py:579} INFO - 25/01/24 15:16:17 INFO BlockManagerInfo: Added rdd_12_21 in memory on 172.18.0.10:45289 (size: 46.0 B, free: 1048.7 MiB)
[2025-01-24T15:16:17.941+0000] {spark_submit.py:579} INFO - 25/01/24 15:16:17 INFO BlockManagerInfo: Added rdd_12_22 in memory on 172.18.0.10:45289 (size: 46.0 B, free: 1048.7 MiB)
[2025-01-24T15:16:17.950+0000] {spark_submit.py:579} INFO - 25/01/24 15:16:17 INFO TaskSetManager: Starting task 25.0 in stage 3.0 (TID 34) (172.18.0.10, executor 0, partition 25, PROCESS_LOCAL, 4446 bytes) taskResourceAssignments Map()
[2025-01-24T15:16:17.953+0000] {spark_submit.py:579} INFO - 25/01/24 15:16:17 INFO TaskSetManager: Finished task 21.0 in stage 3.0 (TID 32) in 93 ms on 172.18.0.10 (executor 0) (30/50)
[2025-01-24T15:16:17.979+0000] {spark_submit.py:579} INFO - 25/01/24 15:16:17 INFO TaskSetManager: Starting task 26.0 in stage 3.0 (TID 35) (172.18.0.10, executor 0, partition 26, PROCESS_LOCAL, 4446 bytes) taskResourceAssignments Map()
[2025-01-24T15:16:17.980+0000] {spark_submit.py:579} INFO - 25/01/24 15:16:17 INFO TaskSetManager: Finished task 22.0 in stage 3.0 (TID 33) in 115 ms on 172.18.0.10 (executor 0) (31/50)
[2025-01-24T15:16:18.034+0000] {spark_submit.py:579} INFO - 25/01/24 15:16:18 INFO BlockManagerInfo: Added rdd_12_25 in memory on 172.18.0.10:45289 (size: 46.0 B, free: 1048.7 MiB)
[2025-01-24T15:16:18.057+0000] {spark_submit.py:579} INFO - 25/01/24 15:16:18 INFO BlockManagerInfo: Added rdd_12_26 in memory on 172.18.0.10:45289 (size: 46.0 B, free: 1048.7 MiB)
[2025-01-24T15:16:18.074+0000] {spark_submit.py:579} INFO - 25/01/24 15:16:18 INFO TaskSetManager: Starting task 27.0 in stage 3.0 (TID 36) (172.18.0.10, executor 0, partition 27, PROCESS_LOCAL, 4446 bytes) taskResourceAssignments Map()
[2025-01-24T15:16:18.075+0000] {spark_submit.py:579} INFO - 25/01/24 15:16:18 INFO TaskSetManager: Finished task 25.0 in stage 3.0 (TID 34) in 127 ms on 172.18.0.10 (executor 0) (32/50)
[2025-01-24T15:16:18.111+0000] {spark_submit.py:579} INFO - 25/01/24 15:16:18 INFO TaskSetManager: Starting task 28.0 in stage 3.0 (TID 37) (172.18.0.10, executor 0, partition 28, PROCESS_LOCAL, 4446 bytes) taskResourceAssignments Map()
[2025-01-24T15:16:18.112+0000] {spark_submit.py:579} INFO - 25/01/24 15:16:18 INFO TaskSetManager: Finished task 26.0 in stage 3.0 (TID 35) in 135 ms on 172.18.0.10 (executor 0) (33/50)
[2025-01-24T15:16:18.161+0000] {spark_submit.py:579} INFO - 25/01/24 15:16:18 INFO BlockManagerInfo: Added rdd_12_27 in memory on 172.18.0.10:45289 (size: 46.0 B, free: 1048.7 MiB)
[2025-01-24T15:16:18.177+0000] {spark_submit.py:579} INFO - 25/01/24 15:16:18 INFO BlockManagerInfo: Added rdd_12_28 in memory on 172.18.0.10:45289 (size: 46.0 B, free: 1048.7 MiB)
[2025-01-24T15:16:18.214+0000] {spark_submit.py:579} INFO - 25/01/24 15:16:18 INFO TaskSetManager: Starting task 29.0 in stage 3.0 (TID 38) (172.18.0.10, executor 0, partition 29, PROCESS_LOCAL, 4446 bytes) taskResourceAssignments Map()
[2025-01-24T15:16:18.216+0000] {spark_submit.py:579} INFO - 25/01/24 15:16:18 INFO TaskSetManager: Finished task 27.0 in stage 3.0 (TID 36) in 142 ms on 172.18.0.10 (executor 0) (34/50)
[2025-01-24T15:16:18.242+0000] {spark_submit.py:579} INFO - 25/01/24 15:16:18 INFO TaskSetManager: Starting task 30.0 in stage 3.0 (TID 39) (172.18.0.10, executor 0, partition 30, PROCESS_LOCAL, 4446 bytes) taskResourceAssignments Map()
[2025-01-24T15:16:18.244+0000] {spark_submit.py:579} INFO - 25/01/24 15:16:18 INFO TaskSetManager: Finished task 28.0 in stage 3.0 (TID 37) in 135 ms on 172.18.0.10 (executor 0) (35/50)
[2025-01-24T15:16:18.284+0000] {spark_submit.py:579} INFO - 25/01/24 15:16:18 INFO BlockManagerInfo: Added rdd_12_29 in memory on 172.18.0.10:45289 (size: 46.0 B, free: 1048.7 MiB)
[2025-01-24T15:16:18.286+0000] {spark_submit.py:579} INFO - 25/01/24 15:16:18 INFO BlockManagerInfo: Added rdd_12_30 in memory on 172.18.0.10:45289 (size: 46.0 B, free: 1048.7 MiB)
[2025-01-24T15:16:18.312+0000] {spark_submit.py:579} INFO - 25/01/24 15:16:18 INFO TaskSetManager: Starting task 31.0 in stage 3.0 (TID 40) (172.18.0.10, executor 0, partition 31, PROCESS_LOCAL, 4446 bytes) taskResourceAssignments Map()
[2025-01-24T15:16:18.313+0000] {spark_submit.py:579} INFO - 25/01/24 15:16:18 INFO TaskSetManager: Finished task 29.0 in stage 3.0 (TID 38) in 101 ms on 172.18.0.10 (executor 0) (36/50)
[2025-01-24T15:16:18.316+0000] {spark_submit.py:579} INFO - 25/01/24 15:16:18 INFO TaskSetManager: Starting task 32.0 in stage 3.0 (TID 41) (172.18.0.10, executor 0, partition 32, PROCESS_LOCAL, 4446 bytes) taskResourceAssignments Map()
[2025-01-24T15:16:18.318+0000] {spark_submit.py:579} INFO - 25/01/24 15:16:18 INFO TaskSetManager: Finished task 30.0 in stage 3.0 (TID 39) in 77 ms on 172.18.0.10 (executor 0) (37/50)
[2025-01-24T15:16:18.372+0000] {spark_submit.py:579} INFO - 25/01/24 15:16:18 INFO BlockManagerInfo: Added rdd_12_32 in memory on 172.18.0.10:45289 (size: 46.0 B, free: 1048.7 MiB)
[2025-01-24T15:16:18.397+0000] {spark_submit.py:579} INFO - 25/01/24 15:16:18 INFO BlockManagerInfo: Added rdd_12_31 in memory on 172.18.0.10:45289 (size: 46.0 B, free: 1048.7 MiB)
[2025-01-24T15:16:18.406+0000] {spark_submit.py:579} INFO - 25/01/24 15:16:18 INFO TaskSetManager: Starting task 33.0 in stage 3.0 (TID 42) (172.18.0.10, executor 0, partition 33, PROCESS_LOCAL, 4446 bytes) taskResourceAssignments Map()
[2025-01-24T15:16:18.407+0000] {spark_submit.py:579} INFO - 25/01/24 15:16:18 INFO TaskSetManager: Finished task 32.0 in stage 3.0 (TID 41) in 90 ms on 172.18.0.10 (executor 0) (38/50)
[2025-01-24T15:16:18.417+0000] {spark_submit.py:579} INFO - 25/01/24 15:16:18 INFO TaskSetManager: Finished task 31.0 in stage 3.0 (TID 40) in 106 ms on 172.18.0.10 (executor 0) (39/50)
[2025-01-24T15:16:18.428+0000] {spark_submit.py:579} INFO - 25/01/24 15:16:18 INFO TaskSetManager: Starting task 34.0 in stage 3.0 (TID 43) (172.18.0.10, executor 0, partition 34, PROCESS_LOCAL, 4446 bytes) taskResourceAssignments Map()
[2025-01-24T15:16:18.456+0000] {spark_submit.py:579} INFO - 25/01/24 15:16:18 INFO BlockManagerInfo: Added rdd_12_33 in memory on 172.18.0.10:45289 (size: 46.0 B, free: 1048.7 MiB)
[2025-01-24T15:16:18.490+0000] {spark_submit.py:579} INFO - 25/01/24 15:16:18 INFO BlockManagerInfo: Added rdd_12_34 in memory on 172.18.0.10:45289 (size: 46.0 B, free: 1048.7 MiB)
[2025-01-24T15:16:18.496+0000] {spark_submit.py:579} INFO - 25/01/24 15:16:18 INFO TaskSetManager: Starting task 35.0 in stage 3.0 (TID 44) (172.18.0.10, executor 0, partition 35, PROCESS_LOCAL, 4446 bytes) taskResourceAssignments Map()
[2025-01-24T15:16:18.497+0000] {spark_submit.py:579} INFO - 25/01/24 15:16:18 INFO TaskSetManager: Finished task 33.0 in stage 3.0 (TID 42) in 85 ms on 172.18.0.10 (executor 0) (40/50)
[2025-01-24T15:16:18.523+0000] {spark_submit.py:579} INFO - 25/01/24 15:16:18 INFO TaskSetManager: Finished task 34.0 in stage 3.0 (TID 43) in 104 ms on 172.18.0.10 (executor 0) (41/50)
[2025-01-24T15:16:18.525+0000] {spark_submit.py:579} INFO - 25/01/24 15:16:18 INFO TaskSetManager: Starting task 39.0 in stage 3.0 (TID 45) (172.18.0.10, executor 0, partition 39, PROCESS_LOCAL, 4446 bytes) taskResourceAssignments Map()
[2025-01-24T15:16:18.553+0000] {spark_submit.py:579} INFO - 25/01/24 15:16:18 INFO BlockManagerInfo: Added rdd_12_35 in memory on 172.18.0.10:45289 (size: 46.0 B, free: 1048.7 MiB)
[2025-01-24T15:16:18.576+0000] {spark_submit.py:579} INFO - 25/01/24 15:16:18 INFO BlockManagerInfo: Added rdd_12_39 in memory on 172.18.0.10:45289 (size: 46.0 B, free: 1048.7 MiB)
[2025-01-24T15:16:18.588+0000] {spark_submit.py:579} INFO - 25/01/24 15:16:18 INFO TaskSetManager: Starting task 40.0 in stage 3.0 (TID 46) (172.18.0.10, executor 0, partition 40, PROCESS_LOCAL, 4446 bytes) taskResourceAssignments Map()
[2025-01-24T15:16:18.589+0000] {spark_submit.py:579} INFO - 25/01/24 15:16:18 INFO TaskSetManager: Finished task 35.0 in stage 3.0 (TID 44) in 99 ms on 172.18.0.10 (executor 0) (42/50)
[2025-01-24T15:16:18.608+0000] {spark_submit.py:579} INFO - 25/01/24 15:16:18 INFO TaskSetManager: Starting task 41.0 in stage 3.0 (TID 47) (172.18.0.10, executor 0, partition 41, PROCESS_LOCAL, 4446 bytes) taskResourceAssignments Map()
[2025-01-24T15:16:18.609+0000] {spark_submit.py:579} INFO - 25/01/24 15:16:18 INFO TaskSetManager: Finished task 39.0 in stage 3.0 (TID 45) in 84 ms on 172.18.0.10 (executor 0) (43/50)
[2025-01-24T15:16:18.658+0000] {spark_submit.py:579} INFO - 25/01/24 15:16:18 INFO BlockManagerInfo: Added rdd_12_40 in memory on 172.18.0.10:45289 (size: 46.0 B, free: 1048.7 MiB)
[2025-01-24T15:16:18.659+0000] {spark_submit.py:579} INFO - 25/01/24 15:16:18 INFO BlockManagerInfo: Added rdd_12_41 in memory on 172.18.0.10:45289 (size: 46.0 B, free: 1048.7 MiB)
[2025-01-24T15:16:18.682+0000] {spark_submit.py:579} INFO - 25/01/24 15:16:18 INFO TaskSetManager: Starting task 43.0 in stage 3.0 (TID 48) (172.18.0.10, executor 0, partition 43, PROCESS_LOCAL, 4446 bytes) taskResourceAssignments Map()
[2025-01-24T15:16:18.686+0000] {spark_submit.py:579} INFO - 25/01/24 15:16:18 INFO TaskSetManager: Finished task 41.0 in stage 3.0 (TID 47) in 79 ms on 172.18.0.10 (executor 0) (44/50)
[2025-01-24T15:16:18.688+0000] {spark_submit.py:579} INFO - 25/01/24 15:16:18 INFO TaskSetManager: Starting task 45.0 in stage 3.0 (TID 49) (172.18.0.10, executor 0, partition 45, PROCESS_LOCAL, 4446 bytes) taskResourceAssignments Map()
[2025-01-24T15:16:18.690+0000] {spark_submit.py:579} INFO - 25/01/24 15:16:18 INFO TaskSetManager: Finished task 40.0 in stage 3.0 (TID 46) in 103 ms on 172.18.0.10 (executor 0) (45/50)
[2025-01-24T15:16:18.738+0000] {spark_submit.py:579} INFO - 25/01/24 15:16:18 INFO BlockManagerInfo: Added rdd_12_43 in memory on 172.18.0.10:45289 (size: 46.0 B, free: 1048.7 MiB)
[2025-01-24T15:16:18.741+0000] {spark_submit.py:579} INFO - 25/01/24 15:16:18 INFO BlockManagerInfo: Added rdd_12_45 in memory on 172.18.0.10:45289 (size: 46.0 B, free: 1048.7 MiB)
[2025-01-24T15:16:18.761+0000] {spark_submit.py:579} INFO - 25/01/24 15:16:18 INFO TaskSetManager: Starting task 47.0 in stage 3.0 (TID 50) (172.18.0.10, executor 0, partition 47, PROCESS_LOCAL, 4446 bytes) taskResourceAssignments Map()
[2025-01-24T15:16:18.763+0000] {spark_submit.py:579} INFO - 25/01/24 15:16:18 INFO TaskSetManager: Finished task 43.0 in stage 3.0 (TID 48) in 79 ms on 172.18.0.10 (executor 0) (46/50)
[2025-01-24T15:16:18.769+0000] {spark_submit.py:579} INFO - 25/01/24 15:16:18 INFO TaskSetManager: Starting task 48.0 in stage 3.0 (TID 51) (172.18.0.10, executor 0, partition 48, PROCESS_LOCAL, 4446 bytes) taskResourceAssignments Map()
[2025-01-24T15:16:18.770+0000] {spark_submit.py:579} INFO - 25/01/24 15:16:18 INFO TaskSetManager: Finished task 45.0 in stage 3.0 (TID 49) in 83 ms on 172.18.0.10 (executor 0) (47/50)
[2025-01-24T15:16:18.808+0000] {spark_submit.py:579} INFO - 25/01/24 15:16:18 INFO BlockManagerInfo: Added rdd_12_47 in memory on 172.18.0.10:45289 (size: 46.0 B, free: 1048.7 MiB)
[2025-01-24T15:16:18.814+0000] {spark_submit.py:579} INFO - 25/01/24 15:16:18 INFO BlockManagerInfo: Added rdd_12_48 in memory on 172.18.0.10:45289 (size: 46.0 B, free: 1048.7 MiB)
[2025-01-24T15:16:18.849+0000] {spark_submit.py:579} INFO - 25/01/24 15:16:18 INFO TaskSetManager: Starting task 49.0 in stage 3.0 (TID 52) (172.18.0.10, executor 0, partition 49, PROCESS_LOCAL, 4446 bytes) taskResourceAssignments Map()
[2025-01-24T15:16:18.866+0000] {spark_submit.py:579} INFO - 25/01/24 15:16:18 INFO TaskSetManager: Finished task 47.0 in stage 3.0 (TID 50) in 105 ms on 172.18.0.10 (executor 0) (48/50)
[2025-01-24T15:16:18.867+0000] {spark_submit.py:579} INFO - 25/01/24 15:16:18 INFO TaskSetManager: Finished task 48.0 in stage 3.0 (TID 51) in 97 ms on 172.18.0.10 (executor 0) (49/50)
[2025-01-24T15:16:18.902+0000] {spark_submit.py:579} INFO - 25/01/24 15:16:18 INFO BlockManagerInfo: Added rdd_12_49 in memory on 172.18.0.10:45289 (size: 46.0 B, free: 1048.7 MiB)
[2025-01-24T15:16:18.940+0000] {spark_submit.py:579} INFO - 25/01/24 15:16:18 INFO TaskSetManager: Finished task 49.0 in stage 3.0 (TID 52) in 91 ms on 172.18.0.10 (executor 0) (50/50)
[2025-01-24T15:16:18.942+0000] {spark_submit.py:579} INFO - 25/01/24 15:16:18 INFO TaskSchedulerImpl: Removed TaskSet 3.0, whose tasks have all completed, from pool
[2025-01-24T15:16:18.944+0000] {spark_submit.py:579} INFO - 25/01/24 15:16:18 INFO DAGScheduler: ShuffleMapStage 3 (toString at String.java:2951) finished in 5.912 s
[2025-01-24T15:16:18.944+0000] {spark_submit.py:579} INFO - 25/01/24 15:16:18 INFO DAGScheduler: looking for newly runnable stages
[2025-01-24T15:16:18.945+0000] {spark_submit.py:579} INFO - 25/01/24 15:16:18 INFO DAGScheduler: running: Set()
[2025-01-24T15:16:18.945+0000] {spark_submit.py:579} INFO - 25/01/24 15:16:18 INFO DAGScheduler: waiting: Set()
[2025-01-24T15:16:18.946+0000] {spark_submit.py:579} INFO - 25/01/24 15:16:18 INFO DAGScheduler: failed: Set()
[2025-01-24T15:16:19.045+0000] {spark_submit.py:579} INFO - 25/01/24 15:16:19 INFO BlockManagerInfo: Removed broadcast_4_piece0 on 172.18.0.10:45289 in memory (size: 102.2 KiB, free: 1048.8 MiB)
[2025-01-24T15:16:19.045+0000] {spark_submit.py:579} INFO - 25/01/24 15:16:19 INFO BlockManagerInfo: Removed broadcast_4_piece0 on 73fc507ad5e4:46429 in memory (size: 102.2 KiB, free: 434.3 MiB)
[2025-01-24T15:16:19.064+0000] {spark_submit.py:579} INFO - 25/01/24 15:16:19 INFO SparkContext: Starting job: toString at String.java:2951
[2025-01-24T15:16:19.064+0000] {spark_submit.py:579} INFO - 25/01/24 15:16:19 INFO DAGScheduler: Got job 3 (toString at String.java:2951) with 1 output partitions
[2025-01-24T15:16:19.065+0000] {spark_submit.py:579} INFO - 25/01/24 15:16:19 INFO DAGScheduler: Final stage: ResultStage 6 (toString at String.java:2951)
[2025-01-24T15:16:19.065+0000] {spark_submit.py:579} INFO - 25/01/24 15:16:19 INFO DAGScheduler: Parents of final stage: List(ShuffleMapStage 5)
[2025-01-24T15:16:19.066+0000] {spark_submit.py:579} INFO - 25/01/24 15:16:19 INFO DAGScheduler: Missing parents: List()
[2025-01-24T15:16:19.070+0000] {spark_submit.py:579} INFO - 25/01/24 15:16:19 INFO DAGScheduler: Submitting ResultStage 6 (MapPartitionsRDD[18] at toString at String.java:2951), which has no missing parents
[2025-01-24T15:16:19.077+0000] {spark_submit.py:579} INFO - 25/01/24 15:16:19 INFO MemoryStore: Block broadcast_5 stored as values in memory (estimated size 371.0 KiB, free 433.6 MiB)
[2025-01-24T15:16:19.086+0000] {spark_submit.py:579} INFO - 25/01/24 15:16:19 INFO MemoryStore: Block broadcast_5_piece0 stored as bytes in memory (estimated size 91.3 KiB, free 433.5 MiB)
[2025-01-24T15:16:19.100+0000] {spark_submit.py:579} INFO - 25/01/24 15:16:19 INFO BlockManagerInfo: Added broadcast_5_piece0 in memory on 73fc507ad5e4:46429 (size: 91.3 KiB, free: 434.2 MiB)
[2025-01-24T15:16:19.102+0000] {spark_submit.py:579} INFO - 25/01/24 15:16:19 INFO SparkContext: Created broadcast 5 from broadcast at DAGScheduler.scala:1513
[2025-01-24T15:16:19.103+0000] {spark_submit.py:579} INFO - 25/01/24 15:16:19 INFO DAGScheduler: Submitting 1 missing tasks from ResultStage 6 (MapPartitionsRDD[18] at toString at String.java:2951) (first 15 tasks are for partitions Vector(0))
[2025-01-24T15:16:19.104+0000] {spark_submit.py:579} INFO - 25/01/24 15:16:19 INFO TaskSchedulerImpl: Adding task set 6.0 with 1 tasks resource profile 0
[2025-01-24T15:16:19.106+0000] {spark_submit.py:579} INFO - 25/01/24 15:16:19 INFO TaskSetManager: Starting task 0.0 in stage 6.0 (TID 53) (172.18.0.10, executor 0, partition 0, NODE_LOCAL, 4457 bytes) taskResourceAssignments Map()
[2025-01-24T15:16:19.138+0000] {spark_submit.py:579} INFO - 25/01/24 15:16:19 INFO BlockManagerInfo: Added broadcast_5_piece0 in memory on 172.18.0.10:45289 (size: 91.3 KiB, free: 1048.7 MiB)
[2025-01-24T15:16:19.177+0000] {spark_submit.py:579} INFO - 25/01/24 15:16:19 INFO MapOutputTrackerMasterEndpoint: Asked to send map output locations for shuffle 1 to 172.18.0.10:39232
[2025-01-24T15:16:19.330+0000] {spark_submit.py:579} INFO - 25/01/24 15:16:19 INFO TaskSetManager: Finished task 0.0 in stage 6.0 (TID 53) in 225 ms on 172.18.0.10 (executor 0) (1/1)
[2025-01-24T15:16:19.331+0000] {spark_submit.py:579} INFO - 25/01/24 15:16:19 INFO TaskSchedulerImpl: Removed TaskSet 6.0, whose tasks have all completed, from pool
[2025-01-24T15:16:19.331+0000] {spark_submit.py:579} INFO - 25/01/24 15:16:19 INFO DAGScheduler: ResultStage 6 (toString at String.java:2951) finished in 0.259 s
[2025-01-24T15:16:19.332+0000] {spark_submit.py:579} INFO - 25/01/24 15:16:19 INFO DAGScheduler: Job 3 is finished. Cancelling potential speculative or zombie tasks for this job
[2025-01-24T15:16:19.332+0000] {spark_submit.py:579} INFO - 25/01/24 15:16:19 INFO TaskSchedulerImpl: Killing all running tasks in stage 6: Stage finished
[2025-01-24T15:16:19.333+0000] {spark_submit.py:579} INFO - 25/01/24 15:16:19 INFO DAGScheduler: Job 3 finished: toString at String.java:2951, took 0.272951 s
[2025-01-24T15:16:19.542+0000] {spark_submit.py:579} INFO - 25/01/24 15:16:19 INFO CodeGenerator: Code generated in 116.831144 ms
[2025-01-24T15:16:19.562+0000] {spark_submit.py:579} INFO - 25/01/24 15:16:19 INFO Snapshot: [tableId=20030bd1-1d27-4bb0-b8ac-775d5b872cc5] DELTA: Done
[2025-01-24T15:16:19.563+0000] {spark_submit.py:579} INFO - 25/01/24 15:16:19 INFO Snapshot: [tableId=d9af5495-ee5a-448e-8d7a-60a6717f75e0] Created snapshot Snapshot(path=s3a://lakehouse/silver/keywords/_delta_log, version=4, metadata=Metadata(46f6dce4-59e3-4d9d-9ec0-1d3310ae28ba,null,null,Format(parquet,Map()),{"type":"struct","fields":[{"name":"id","type":"long","nullable":true,"metadata":{}},{"name":"keywords","type":"string","nullable":true,"metadata":{}},{"name":"keyword_convert","type":"string","nullable":true,"metadata":{}}]},List(),Map(),Some(1737605554439)), logSegment=LogSegment(s3a://lakehouse/silver/keywords/_delta_log,4,WrappedArray(S3AFileStatus{path=s3a://lakehouse/silver/keywords/_delta_log/00000000000000000000.json; isDirectory=false; length=1803; replication=1; blocksize=33554432; modification_time=1737605563501; access_time=0; owner=***; group=***; permission=rw-rw-rw-; isSymlink=false; hasAcl=false; isEncrypted=true; isErasureCoded=false} isEmptyDirectory=FALSE eTag=724ffa41d46a8dde2a094df109c67b15 versionId=null, S3AFileStatus{path=s3a://lakehouse/silver/keywords/_delta_log/00000000000000000001.json; isDirectory=false; length=1716; replication=1; blocksize=33554432; modification_time=1737605795759; access_time=0; owner=***; group=***; permission=rw-rw-rw-; isSymlink=false; hasAcl=false; isEncrypted=true; isErasureCoded=false} isEmptyDirectory=FALSE eTag=5298fea5b4a3db91c4e35fc7a6d5e13d versionId=null, S3AFileStatus{path=s3a://lakehouse/silver/keywords/_delta_log/00000000000000000002.json; isDirectory=false; length=1716; replication=1; blocksize=33554432; modification_time=1737605917906; access_time=0; owner=***; group=***; permission=rw-rw-rw-; isSymlink=false; hasAcl=false; isEncrypted=true; isErasureCoded=false} isEmptyDirectory=FALSE eTag=b625597340a15e98ad1d1f3d5ea3af20 versionId=null, S3AFileStatus{path=s3a://lakehouse/silver/keywords/_delta_log/00000000000000000003.json; isDirectory=false; length=1716; replication=1; blocksize=33554432; modification_time=1737606101127; access_time=0; owner=***; group=***; permission=rw-rw-rw-; isSymlink=false; hasAcl=false; isEncrypted=true; isErasureCoded=false} isEmptyDirectory=FALSE eTag=07f65be5d436fbf3cdd8ef278155aec0 versionId=null, S3AFileStatus{path=s3a://lakehouse/silver/keywords/_delta_log/00000000000000000004.json; isDirectory=false; length=1716; replication=1; blocksize=33554432; modification_time=1737606237825; access_time=0; owner=***; group=***; permission=rw-rw-rw-; isSymlink=false; hasAcl=false; isEncrypted=true; isErasureCoded=false} isEmptyDirectory=FALSE eTag=8a53993f7aca4e67be83d4149a84077e versionId=null),List(),None,1737606237825), checksumOpt=None)
[2025-01-24T15:16:20.086+0000] {spark_submit.py:579} INFO - 25/01/24 15:16:20 INFO FileSourceStrategy: Pushed Filters: IsNotNull(keywords)
[2025-01-24T15:16:20.087+0000] {spark_submit.py:579} INFO - 25/01/24 15:16:20 INFO FileSourceStrategy: Post-Scan Filters: isnotnull(keywords#1)
[2025-01-24T15:16:20.087+0000] {spark_submit.py:579} INFO - 25/01/24 15:16:20 INFO FileSourceStrategy: Output Data Schema: struct<id: bigint, keywords: string>
[2025-01-24T15:16:20.263+0000] {spark_submit.py:579} INFO - 25/01/24 15:16:20 INFO DeltaParquetFileFormat: Using default output committer for Parquet: org.apache.parquet.hadoop.ParquetOutputCommitter
[2025-01-24T15:16:20.412+0000] {spark_submit.py:579} INFO - 25/01/24 15:16:20 INFO HashAggregateExec: spark.sql.codegen.aggregate.map.twolevel.enabled is set to true, but current version of codegened fast hashmap does not support this aggregate.
[2025-01-24T15:16:20.421+0000] {spark_submit.py:579} INFO - 25/01/24 15:16:20 INFO BlockManagerInfo: Removed broadcast_5_piece0 on 172.18.0.10:45289 in memory (size: 91.3 KiB, free: 1048.8 MiB)
[2025-01-24T15:16:20.440+0000] {spark_submit.py:579} INFO - 25/01/24 15:16:20 INFO BlockManagerInfo: Removed broadcast_5_piece0 on 73fc507ad5e4:46429 in memory (size: 91.3 KiB, free: 434.3 MiB)
[2025-01-24T15:16:20.570+0000] {spark_submit.py:579} INFO - 25/01/24 15:16:20 INFO CodeGenerator: Code generated in 71.732796 ms
[2025-01-24T15:16:20.604+0000] {spark_submit.py:579} INFO - 25/01/24 15:16:20 INFO MemoryStore: Block broadcast_6 stored as values in memory (estimated size 204.5 KiB, free 433.7 MiB)
[2025-01-24T15:16:20.670+0000] {spark_submit.py:579} INFO - 25/01/24 15:16:20 INFO MemoryStore: Block broadcast_6_piece0 stored as bytes in memory (estimated size 35.6 KiB, free 433.7 MiB)
[2025-01-24T15:16:20.674+0000] {spark_submit.py:579} INFO - 25/01/24 15:16:20 INFO BlockManagerInfo: Added broadcast_6_piece0 in memory on 73fc507ad5e4:46429 (size: 35.6 KiB, free: 434.3 MiB)
[2025-01-24T15:16:20.677+0000] {spark_submit.py:579} INFO - 25/01/24 15:16:20 INFO SparkContext: Created broadcast 6 from save at NativeMethodAccessorImpl.java:0
[2025-01-24T15:16:20.684+0000] {spark_submit.py:579} INFO - 25/01/24 15:16:20 INFO FileSourceScanExec: Planning scan with bin packing, max size: 4194304 bytes, open cost is considered as scanning 4194304 bytes.
[2025-01-24T15:16:20.755+0000] {spark_submit.py:579} INFO - 25/01/24 15:16:20 INFO DAGScheduler: Registering RDD 22 (save at NativeMethodAccessorImpl.java:0) as input to shuffle 2
[2025-01-24T15:16:20.757+0000] {spark_submit.py:579} INFO - 25/01/24 15:16:20 INFO DAGScheduler: Got map stage job 4 (save at NativeMethodAccessorImpl.java:0) with 1 output partitions
[2025-01-24T15:16:20.758+0000] {spark_submit.py:579} INFO - 25/01/24 15:16:20 INFO DAGScheduler: Final stage: ShuffleMapStage 7 (save at NativeMethodAccessorImpl.java:0)
[2025-01-24T15:16:20.759+0000] {spark_submit.py:579} INFO - 25/01/24 15:16:20 INFO DAGScheduler: Parents of final stage: List()
[2025-01-24T15:16:20.763+0000] {spark_submit.py:579} INFO - 25/01/24 15:16:20 INFO DAGScheduler: Missing parents: List()
[2025-01-24T15:16:20.764+0000] {spark_submit.py:579} INFO - 25/01/24 15:16:20 INFO DAGScheduler: Submitting ShuffleMapStage 7 (MapPartitionsRDD[22] at save at NativeMethodAccessorImpl.java:0), which has no missing parents
[2025-01-24T15:16:20.769+0000] {spark_submit.py:579} INFO - 25/01/24 15:16:20 INFO MemoryStore: Block broadcast_7 stored as values in memory (estimated size 31.5 KiB, free 433.7 MiB)
[2025-01-24T15:16:20.775+0000] {spark_submit.py:579} INFO - 25/01/24 15:16:20 INFO MemoryStore: Block broadcast_7_piece0 stored as bytes in memory (estimated size 13.9 KiB, free 433.7 MiB)
[2025-01-24T15:16:20.776+0000] {spark_submit.py:579} INFO - 25/01/24 15:16:20 INFO BlockManagerInfo: Added broadcast_7_piece0 in memory on 73fc507ad5e4:46429 (size: 13.9 KiB, free: 434.3 MiB)
[2025-01-24T15:16:20.777+0000] {spark_submit.py:579} INFO - 25/01/24 15:16:20 INFO SparkContext: Created broadcast 7 from broadcast at DAGScheduler.scala:1513
[2025-01-24T15:16:20.778+0000] {spark_submit.py:579} INFO - 25/01/24 15:16:20 INFO DAGScheduler: Submitting 1 missing tasks from ShuffleMapStage 7 (MapPartitionsRDD[22] at save at NativeMethodAccessorImpl.java:0) (first 15 tasks are for partitions Vector(0))
[2025-01-24T15:16:20.779+0000] {spark_submit.py:579} INFO - 25/01/24 15:16:20 INFO TaskSchedulerImpl: Adding task set 7.0 with 1 tasks resource profile 0
[2025-01-24T15:16:20.782+0000] {spark_submit.py:579} INFO - 25/01/24 15:16:20 INFO TaskSetManager: Starting task 0.0 in stage 7.0 (TID 54) (172.18.0.10, executor 0, partition 0, PROCESS_LOCAL, 4903 bytes) taskResourceAssignments Map()
[2025-01-24T15:16:20.859+0000] {spark_submit.py:579} INFO - 25/01/24 15:16:20 INFO BlockManagerInfo: Added broadcast_7_piece0 in memory on 172.18.0.10:45289 (size: 13.9 KiB, free: 1048.7 MiB)
[2025-01-24T15:16:21.010+0000] {spark_submit.py:579} INFO - 25/01/24 15:16:21 INFO BlockManagerInfo: Added broadcast_6_piece0 in memory on 172.18.0.10:45289 (size: 35.6 KiB, free: 1048.7 MiB)
[2025-01-24T15:16:22.112+0000] {spark_submit.py:579} INFO - 25/01/24 15:16:22 INFO TaskSetManager: Finished task 0.0 in stage 7.0 (TID 54) in 1335 ms on 172.18.0.10 (executor 0) (1/1)
[2025-01-24T15:16:22.115+0000] {spark_submit.py:579} INFO - 25/01/24 15:16:22 INFO TaskSchedulerImpl: Removed TaskSet 7.0, whose tasks have all completed, from pool
[2025-01-24T15:16:22.117+0000] {spark_submit.py:579} INFO - 25/01/24 15:16:22 INFO DAGScheduler: ShuffleMapStage 7 (save at NativeMethodAccessorImpl.java:0) finished in 1.353 s
[2025-01-24T15:16:22.118+0000] {spark_submit.py:579} INFO - 25/01/24 15:16:22 INFO DAGScheduler: looking for newly runnable stages
[2025-01-24T15:16:22.119+0000] {spark_submit.py:579} INFO - 25/01/24 15:16:22 INFO DAGScheduler: running: Set()
[2025-01-24T15:16:22.119+0000] {spark_submit.py:579} INFO - 25/01/24 15:16:22 INFO DAGScheduler: waiting: Set()
[2025-01-24T15:16:22.120+0000] {spark_submit.py:579} INFO - 25/01/24 15:16:22 INFO DAGScheduler: failed: Set()
[2025-01-24T15:16:22.134+0000] {spark_submit.py:579} INFO - 25/01/24 15:16:22 INFO ShufflePartitionsUtil: For shuffle(2), advisory target size: 67108864, actual target size 1480508, minimum partition size: 1048576
[2025-01-24T15:16:22.179+0000] {spark_submit.py:579} INFO - 25/01/24 15:16:22 INFO CodeGenerator: Code generated in 10.393911 ms
[2025-01-24T15:16:22.181+0000] {spark_submit.py:579} INFO - 25/01/24 15:16:22 INFO HashAggregateExec: spark.sql.codegen.aggregate.map.twolevel.enabled is set to true, but current version of codegened fast hashmap does not support this aggregate.
[2025-01-24T15:16:22.201+0000] {spark_submit.py:579} INFO - 25/01/24 15:16:22 INFO CodeGenerator: Code generated in 14.562744 ms
[2025-01-24T15:16:22.349+0000] {spark_submit.py:579} INFO - 25/01/24 15:16:22 INFO SparkContext: Starting job: save at NativeMethodAccessorImpl.java:0
[2025-01-24T15:16:22.351+0000] {spark_submit.py:579} INFO - 25/01/24 15:16:22 INFO DAGScheduler: Got job 5 (save at NativeMethodAccessorImpl.java:0) with 2 output partitions
[2025-01-24T15:16:22.355+0000] {spark_submit.py:579} INFO - 25/01/24 15:16:22 INFO DAGScheduler: Final stage: ResultStage 9 (save at NativeMethodAccessorImpl.java:0)
[2025-01-24T15:16:22.356+0000] {spark_submit.py:579} INFO - 25/01/24 15:16:22 INFO DAGScheduler: Parents of final stage: List(ShuffleMapStage 8)
[2025-01-24T15:16:22.357+0000] {spark_submit.py:579} INFO - 25/01/24 15:16:22 INFO DAGScheduler: Missing parents: List()
[2025-01-24T15:16:22.357+0000] {spark_submit.py:579} INFO - 25/01/24 15:16:22 INFO DAGScheduler: Submitting ResultStage 9 (MapPartitionsRDD[27] at save at NativeMethodAccessorImpl.java:0), which has no missing parents
[2025-01-24T15:16:22.442+0000] {spark_submit.py:579} INFO - 25/01/24 15:16:22 INFO BlockManagerInfo: Removed broadcast_7_piece0 on 172.18.0.10:45289 in memory (size: 13.9 KiB, free: 1048.7 MiB)
[2025-01-24T15:16:22.443+0000] {spark_submit.py:579} INFO - 25/01/24 15:16:22 INFO MemoryStore: Block broadcast_8 stored as values in memory (estimated size 355.9 KiB, free 433.3 MiB)
[2025-01-24T15:16:22.447+0000] {spark_submit.py:579} INFO - 25/01/24 15:16:22 INFO MemoryStore: Block broadcast_8_piece0 stored as bytes in memory (estimated size 130.0 KiB, free 433.2 MiB)
[2025-01-24T15:16:22.450+0000] {spark_submit.py:579} INFO - 25/01/24 15:16:22 INFO BlockManagerInfo: Added broadcast_8_piece0 in memory on 73fc507ad5e4:46429 (size: 130.0 KiB, free: 434.2 MiB)
[2025-01-24T15:16:22.452+0000] {spark_submit.py:579} INFO - 25/01/24 15:16:22 INFO SparkContext: Created broadcast 8 from broadcast at DAGScheduler.scala:1513
[2025-01-24T15:16:22.453+0000] {spark_submit.py:579} INFO - 25/01/24 15:16:22 INFO DAGScheduler: Submitting 2 missing tasks from ResultStage 9 (MapPartitionsRDD[27] at save at NativeMethodAccessorImpl.java:0) (first 15 tasks are for partitions Vector(0, 1))
[2025-01-24T15:16:22.453+0000] {spark_submit.py:579} INFO - 25/01/24 15:16:22 INFO TaskSchedulerImpl: Adding task set 9.0 with 2 tasks resource profile 0
[2025-01-24T15:16:22.455+0000] {spark_submit.py:579} INFO - 25/01/24 15:16:22 INFO TaskSetManager: Starting task 0.0 in stage 9.0 (TID 55) (172.18.0.10, executor 0, partition 0, NODE_LOCAL, 4457 bytes) taskResourceAssignments Map()
[2025-01-24T15:16:22.456+0000] {spark_submit.py:579} INFO - 25/01/24 15:16:22 INFO TaskSetManager: Starting task 1.0 in stage 9.0 (TID 56) (172.18.0.10, executor 0, partition 1, NODE_LOCAL, 4457 bytes) taskResourceAssignments Map()
[2025-01-24T15:16:22.462+0000] {spark_submit.py:579} INFO - 25/01/24 15:16:22 INFO BlockManagerInfo: Removed broadcast_7_piece0 on 73fc507ad5e4:46429 in memory (size: 13.9 KiB, free: 434.2 MiB)
[2025-01-24T15:16:22.499+0000] {spark_submit.py:579} INFO - 25/01/24 15:16:22 INFO BlockManagerInfo: Added broadcast_8_piece0 in memory on 172.18.0.10:45289 (size: 130.0 KiB, free: 1048.6 MiB)
[2025-01-24T15:16:22.677+0000] {spark_submit.py:579} INFO - 25/01/24 15:16:22 INFO MapOutputTrackerMasterEndpoint: Asked to send map output locations for shuffle 2 to 172.18.0.10:39232
[2025-01-24T15:16:27.198+0000] {spark_submit.py:579} INFO - 25/01/24 15:16:27 INFO TaskSetManager: Finished task 0.0 in stage 9.0 (TID 55) in 4744 ms on 172.18.0.10 (executor 0) (1/2)
[2025-01-24T15:16:27.203+0000] {spark_submit.py:579} INFO - 25/01/24 15:16:27 INFO TaskSetManager: Finished task 1.0 in stage 9.0 (TID 56) in 4745 ms on 172.18.0.10 (executor 0) (2/2)
[2025-01-24T15:16:27.203+0000] {spark_submit.py:579} INFO - 25/01/24 15:16:27 INFO TaskSchedulerImpl: Removed TaskSet 9.0, whose tasks have all completed, from pool
[2025-01-24T15:16:27.206+0000] {spark_submit.py:579} INFO - 25/01/24 15:16:27 INFO PythonAccumulatorV2: Connected to AccumulatorServer at host: 127.0.0.1 port: 36553
[2025-01-24T15:16:27.283+0000] {spark_submit.py:579} INFO - 25/01/24 15:16:27 INFO DAGScheduler: ResultStage 9 (save at NativeMethodAccessorImpl.java:0) finished in 4.927 s
[2025-01-24T15:16:27.285+0000] {spark_submit.py:579} INFO - 25/01/24 15:16:27 INFO DAGScheduler: Job 5 is finished. Cancelling potential speculative or zombie tasks for this job
[2025-01-24T15:16:27.293+0000] {spark_submit.py:579} INFO - 25/01/24 15:16:27 INFO TaskSchedulerImpl: Killing all running tasks in stage 9: Stage finished
[2025-01-24T15:16:27.295+0000] {spark_submit.py:579} INFO - 25/01/24 15:16:27 INFO DAGScheduler: Job 5 finished: save at NativeMethodAccessorImpl.java:0, took 4.941575 s
[2025-01-24T15:16:27.298+0000] {spark_submit.py:579} INFO - 25/01/24 15:16:27 INFO FileFormatWriter: Start to commit write Job d5ea44a6-748f-40d5-898b-ac180127b3b8.
[2025-01-24T15:16:27.301+0000] {spark_submit.py:579} INFO - 25/01/24 15:16:27 INFO FileFormatWriter: Write Job d5ea44a6-748f-40d5-898b-ac180127b3b8 committed. Elapsed time: 1 ms.
[2025-01-24T15:16:27.304+0000] {spark_submit.py:579} INFO - 25/01/24 15:16:27 INFO FileFormatWriter: Finished processing stats for write job d5ea44a6-748f-40d5-898b-ac180127b3b8.
[2025-01-24T15:16:28.157+0000] {spark_submit.py:579} INFO - 25/01/24 15:16:28 INFO BlockManagerInfo: Removed broadcast_8_piece0 on 172.18.0.10:45289 in memory (size: 130.0 KiB, free: 1048.7 MiB)
[2025-01-24T15:16:28.165+0000] {spark_submit.py:579} INFO - 25/01/24 15:16:28 INFO BlockManagerInfo: Removed broadcast_8_piece0 on 73fc507ad5e4:46429 in memory (size: 130.0 KiB, free: 434.3 MiB)
[2025-01-24T15:16:28.285+0000] {spark_submit.py:579} INFO - 25/01/24 15:16:28 INFO CodeGenerator: Code generated in 219.442596 ms
[2025-01-24T15:16:28.349+0000] {spark_submit.py:579} INFO - 25/01/24 15:16:28 INFO SparkContext: Starting job: $anonfun$recordDeltaOperationInternal$1 at DatabricksLogging.scala:128
[2025-01-24T15:16:28.352+0000] {spark_submit.py:579} INFO - 25/01/24 15:16:28 INFO DAGScheduler: Got job 6 ($anonfun$recordDeltaOperationInternal$1 at DatabricksLogging.scala:128) with 50 output partitions
[2025-01-24T15:16:28.355+0000] {spark_submit.py:579} INFO - 25/01/24 15:16:28 INFO DAGScheduler: Final stage: ResultStage 11 ($anonfun$recordDeltaOperationInternal$1 at DatabricksLogging.scala:128)
[2025-01-24T15:16:28.360+0000] {spark_submit.py:579} INFO - 25/01/24 15:16:28 INFO DAGScheduler: Parents of final stage: List(ShuffleMapStage 10)
[2025-01-24T15:16:28.361+0000] {spark_submit.py:579} INFO - 25/01/24 15:16:28 INFO DAGScheduler: Missing parents: List()
[2025-01-24T15:16:28.362+0000] {spark_submit.py:579} INFO - 25/01/24 15:16:28 INFO DAGScheduler: Submitting ResultStage 11 (MapPartitionsRDD[29] at $anonfun$recordDeltaOperationInternal$1 at DatabricksLogging.scala:128), which has no missing parents
[2025-01-24T15:16:28.364+0000] {spark_submit.py:579} INFO - 25/01/24 15:16:28 INFO MemoryStore: Block broadcast_9 stored as values in memory (estimated size 473.8 KiB, free 433.2 MiB)
[2025-01-24T15:16:28.383+0000] {spark_submit.py:579} INFO - 25/01/24 15:16:28 INFO MemoryStore: Block broadcast_9_piece0 stored as bytes in memory (estimated size 112.0 KiB, free 433.1 MiB)
[2025-01-24T15:16:28.398+0000] {spark_submit.py:579} INFO - 25/01/24 15:16:28 INFO BlockManagerInfo: Added broadcast_9_piece0 in memory on 73fc507ad5e4:46429 (size: 112.0 KiB, free: 434.2 MiB)
[2025-01-24T15:16:28.400+0000] {spark_submit.py:579} INFO - 25/01/24 15:16:28 INFO SparkContext: Created broadcast 9 from broadcast at DAGScheduler.scala:1513
[2025-01-24T15:16:28.404+0000] {spark_submit.py:579} INFO - 25/01/24 15:16:28 INFO DAGScheduler: Submitting 50 missing tasks from ResultStage 11 (MapPartitionsRDD[29] at $anonfun$recordDeltaOperationInternal$1 at DatabricksLogging.scala:128) (first 15 tasks are for partitions Vector(0, 1, 2, 3, 4, 5, 6, 7, 8, 9, 10, 11, 12, 13, 14))
[2025-01-24T15:16:28.404+0000] {spark_submit.py:579} INFO - 25/01/24 15:16:28 INFO TaskSchedulerImpl: Adding task set 11.0 with 50 tasks resource profile 0
[2025-01-24T15:16:28.409+0000] {spark_submit.py:579} INFO - 25/01/24 15:16:28 INFO TaskSetManager: Starting task 0.0 in stage 11.0 (TID 57) (172.18.0.10, executor 0, partition 0, PROCESS_LOCAL, 4457 bytes) taskResourceAssignments Map()
[2025-01-24T15:16:28.412+0000] {spark_submit.py:579} INFO - 25/01/24 15:16:28 INFO TaskSetManager: Starting task 1.0 in stage 11.0 (TID 58) (172.18.0.10, executor 0, partition 1, PROCESS_LOCAL, 4457 bytes) taskResourceAssignments Map()
[2025-01-24T15:16:28.443+0000] {spark_submit.py:579} INFO - 25/01/24 15:16:28 INFO BlockManagerInfo: Added broadcast_9_piece0 in memory on 172.18.0.10:45289 (size: 112.0 KiB, free: 1048.6 MiB)
[2025-01-24T15:16:28.799+0000] {spark_submit.py:579} INFO - 25/01/24 15:16:28 INFO TaskSetManager: Starting task 2.0 in stage 11.0 (TID 59) (172.18.0.10, executor 0, partition 2, PROCESS_LOCAL, 4457 bytes) taskResourceAssignments Map()
[2025-01-24T15:16:28.801+0000] {spark_submit.py:579} INFO - 25/01/24 15:16:28 INFO TaskSetManager: Starting task 3.0 in stage 11.0 (TID 60) (172.18.0.10, executor 0, partition 3, PROCESS_LOCAL, 4457 bytes) taskResourceAssignments Map()
[2025-01-24T15:16:28.803+0000] {spark_submit.py:579} INFO - 25/01/24 15:16:28 INFO TaskSetManager: Finished task 1.0 in stage 11.0 (TID 58) in 393 ms on 172.18.0.10 (executor 0) (1/50)
[2025-01-24T15:16:28.806+0000] {spark_submit.py:579} INFO - 25/01/24 15:16:28 INFO TaskSetManager: Finished task 0.0 in stage 11.0 (TID 57) in 396 ms on 172.18.0.10 (executor 0) (2/50)
[2025-01-24T15:16:28.868+0000] {spark_submit.py:579} INFO - 25/01/24 15:16:28 INFO TaskSetManager: Starting task 4.0 in stage 11.0 (TID 61) (172.18.0.10, executor 0, partition 4, PROCESS_LOCAL, 4457 bytes) taskResourceAssignments Map()
[2025-01-24T15:16:28.873+0000] {spark_submit.py:579} INFO - 25/01/24 15:16:28 INFO TaskSetManager: Finished task 3.0 in stage 11.0 (TID 60) in 46 ms on 172.18.0.10 (executor 0) (3/50)
[2025-01-24T15:16:28.877+0000] {spark_submit.py:579} INFO - 25/01/24 15:16:28 INFO TaskSetManager: Starting task 5.0 in stage 11.0 (TID 62) (172.18.0.10, executor 0, partition 5, PROCESS_LOCAL, 4457 bytes) taskResourceAssignments Map()
[2025-01-24T15:16:28.877+0000] {spark_submit.py:579} INFO - 25/01/24 15:16:28 INFO TaskSetManager: Finished task 2.0 in stage 11.0 (TID 59) in 53 ms on 172.18.0.10 (executor 0) (4/50)
[2025-01-24T15:16:28.908+0000] {spark_submit.py:579} INFO - 25/01/24 15:16:28 INFO TaskSetManager: Starting task 6.0 in stage 11.0 (TID 63) (172.18.0.10, executor 0, partition 6, PROCESS_LOCAL, 4457 bytes) taskResourceAssignments Map()
[2025-01-24T15:16:28.919+0000] {spark_submit.py:579} INFO - 25/01/24 15:16:28 INFO TaskSetManager: Finished task 5.0 in stage 11.0 (TID 62) in 55 ms on 172.18.0.10 (executor 0) (5/50)
[2025-01-24T15:16:28.941+0000] {spark_submit.py:579} INFO - 25/01/24 15:16:28 INFO TaskSetManager: Starting task 7.0 in stage 11.0 (TID 64) (172.18.0.10, executor 0, partition 7, PROCESS_LOCAL, 4457 bytes) taskResourceAssignments Map()
[2025-01-24T15:16:28.942+0000] {spark_submit.py:579} INFO - 25/01/24 15:16:28 INFO TaskSetManager: Finished task 4.0 in stage 11.0 (TID 61) in 97 ms on 172.18.0.10 (executor 0) (6/50)
[2025-01-24T15:16:28.977+0000] {spark_submit.py:579} INFO - 25/01/24 15:16:28 INFO TaskSetManager: Starting task 8.0 in stage 11.0 (TID 65) (172.18.0.10, executor 0, partition 8, PROCESS_LOCAL, 4457 bytes) taskResourceAssignments Map()
[2025-01-24T15:16:28.982+0000] {spark_submit.py:579} INFO - 25/01/24 15:16:28 INFO TaskSetManager: Finished task 7.0 in stage 11.0 (TID 64) in 37 ms on 172.18.0.10 (executor 0) (7/50)
[2025-01-24T15:16:28.984+0000] {spark_submit.py:579} INFO - 25/01/24 15:16:28 INFO TaskSetManager: Starting task 9.0 in stage 11.0 (TID 66) (172.18.0.10, executor 0, partition 9, PROCESS_LOCAL, 4457 bytes) taskResourceAssignments Map()
[2025-01-24T15:16:28.985+0000] {spark_submit.py:579} INFO - 25/01/24 15:16:28 INFO TaskSetManager: Finished task 6.0 in stage 11.0 (TID 63) in 81 ms on 172.18.0.10 (executor 0) (8/50)
[2025-01-24T15:16:29.026+0000] {spark_submit.py:579} INFO - 25/01/24 15:16:29 INFO TaskSetManager: Starting task 10.0 in stage 11.0 (TID 67) (172.18.0.10, executor 0, partition 10, PROCESS_LOCAL, 4457 bytes) taskResourceAssignments Map()
[2025-01-24T15:16:29.030+0000] {spark_submit.py:579} INFO - 25/01/24 15:16:29 INFO TaskSetManager: Starting task 11.0 in stage 11.0 (TID 68) (172.18.0.10, executor 0, partition 11, PROCESS_LOCAL, 4457 bytes) taskResourceAssignments Map()
[2025-01-24T15:16:29.036+0000] {spark_submit.py:579} INFO - 25/01/24 15:16:29 INFO TaskSetManager: Finished task 9.0 in stage 11.0 (TID 66) in 55 ms on 172.18.0.10 (executor 0) (9/50)
[2025-01-24T15:16:29.039+0000] {spark_submit.py:579} INFO - 25/01/24 15:16:29 INFO TaskSetManager: Finished task 8.0 in stage 11.0 (TID 65) in 60 ms on 172.18.0.10 (executor 0) (10/50)
[2025-01-24T15:16:29.083+0000] {spark_submit.py:579} INFO - 25/01/24 15:16:29 INFO TaskSetManager: Starting task 12.0 in stage 11.0 (TID 69) (172.18.0.10, executor 0, partition 12, PROCESS_LOCAL, 4457 bytes) taskResourceAssignments Map()
[2025-01-24T15:16:29.085+0000] {spark_submit.py:579} INFO - 25/01/24 15:16:29 INFO TaskSetManager: Starting task 13.0 in stage 11.0 (TID 70) (172.18.0.10, executor 0, partition 13, PROCESS_LOCAL, 4457 bytes) taskResourceAssignments Map()
[2025-01-24T15:16:29.085+0000] {spark_submit.py:579} INFO - 25/01/24 15:16:29 INFO TaskSetManager: Finished task 10.0 in stage 11.0 (TID 67) in 64 ms on 172.18.0.10 (executor 0) (11/50)
[2025-01-24T15:16:29.086+0000] {spark_submit.py:579} INFO - 25/01/24 15:16:29 INFO TaskSetManager: Finished task 11.0 in stage 11.0 (TID 68) in 58 ms on 172.18.0.10 (executor 0) (12/50)
[2025-01-24T15:16:29.125+0000] {spark_submit.py:579} INFO - 25/01/24 15:16:29 INFO TaskSetManager: Starting task 14.0 in stage 11.0 (TID 71) (172.18.0.10, executor 0, partition 14, PROCESS_LOCAL, 4457 bytes) taskResourceAssignments Map()
[2025-01-24T15:16:29.131+0000] {spark_submit.py:579} INFO - 25/01/24 15:16:29 INFO TaskSetManager: Finished task 13.0 in stage 11.0 (TID 70) in 43 ms on 172.18.0.10 (executor 0) (13/50)
[2025-01-24T15:16:29.150+0000] {spark_submit.py:579} INFO - 25/01/24 15:16:29 INFO TaskSetManager: Starting task 15.0 in stage 11.0 (TID 72) (172.18.0.10, executor 0, partition 15, PROCESS_LOCAL, 4457 bytes) taskResourceAssignments Map()
[2025-01-24T15:16:29.158+0000] {spark_submit.py:579} INFO - 25/01/24 15:16:29 INFO TaskSetManager: Finished task 12.0 in stage 11.0 (TID 69) in 70 ms on 172.18.0.10 (executor 0) (14/50)
[2025-01-24T15:16:29.175+0000] {spark_submit.py:579} INFO - 25/01/24 15:16:29 INFO TaskSetManager: Starting task 16.0 in stage 11.0 (TID 73) (172.18.0.10, executor 0, partition 16, PROCESS_LOCAL, 4457 bytes) taskResourceAssignments Map()
[2025-01-24T15:16:29.181+0000] {spark_submit.py:579} INFO - 25/01/24 15:16:29 INFO TaskSetManager: Finished task 14.0 in stage 11.0 (TID 71) in 49 ms on 172.18.0.10 (executor 0) (15/50)
[2025-01-24T15:16:29.191+0000] {spark_submit.py:579} INFO - 25/01/24 15:16:29 INFO TaskSetManager: Finished task 15.0 in stage 11.0 (TID 72) in 40 ms on 172.18.0.10 (executor 0) (16/50)
[2025-01-24T15:16:29.192+0000] {spark_submit.py:579} INFO - 25/01/24 15:16:29 INFO TaskSetManager: Starting task 17.0 in stage 11.0 (TID 74) (172.18.0.10, executor 0, partition 17, PROCESS_LOCAL, 4457 bytes) taskResourceAssignments Map()
[2025-01-24T15:16:29.203+0000] {spark_submit.py:579} INFO - 25/01/24 15:16:29 INFO TaskSetManager: Finished task 16.0 in stage 11.0 (TID 73) in 31 ms on 172.18.0.10 (executor 0) (17/50)
[2025-01-24T15:16:29.204+0000] {spark_submit.py:579} INFO - 25/01/24 15:16:29 INFO TaskSetManager: Starting task 18.0 in stage 11.0 (TID 75) (172.18.0.10, executor 0, partition 18, PROCESS_LOCAL, 4457 bytes) taskResourceAssignments Map()
[2025-01-24T15:16:29.221+0000] {spark_submit.py:579} INFO - 25/01/24 15:16:29 INFO TaskSetManager: Finished task 17.0 in stage 11.0 (TID 74) in 29 ms on 172.18.0.10 (executor 0) (18/50)
[2025-01-24T15:16:29.227+0000] {spark_submit.py:579} INFO - 25/01/24 15:16:29 INFO TaskSetManager: Starting task 19.0 in stage 11.0 (TID 76) (172.18.0.10, executor 0, partition 19, PROCESS_LOCAL, 4457 bytes) taskResourceAssignments Map()
[2025-01-24T15:16:29.235+0000] {spark_submit.py:579} INFO - 25/01/24 15:16:29 INFO TaskSetManager: Starting task 20.0 in stage 11.0 (TID 77) (172.18.0.10, executor 0, partition 20, PROCESS_LOCAL, 4457 bytes) taskResourceAssignments Map()
[2025-01-24T15:16:29.237+0000] {spark_submit.py:579} INFO - 25/01/24 15:16:29 INFO TaskSetManager: Finished task 18.0 in stage 11.0 (TID 75) in 23 ms on 172.18.0.10 (executor 0) (19/50)
[2025-01-24T15:16:29.258+0000] {spark_submit.py:579} INFO - 25/01/24 15:16:29 INFO TaskSetManager: Starting task 21.0 in stage 11.0 (TID 78) (172.18.0.10, executor 0, partition 21, PROCESS_LOCAL, 4457 bytes) taskResourceAssignments Map()
[2025-01-24T15:16:29.259+0000] {spark_submit.py:579} INFO - 25/01/24 15:16:29 INFO TaskSetManager: Finished task 19.0 in stage 11.0 (TID 76) in 40 ms on 172.18.0.10 (executor 0) (20/50)
[2025-01-24T15:16:29.285+0000] {spark_submit.py:579} INFO - 25/01/24 15:16:29 INFO TaskSetManager: Starting task 22.0 in stage 11.0 (TID 79) (172.18.0.10, executor 0, partition 22, PROCESS_LOCAL, 4457 bytes) taskResourceAssignments Map()
[2025-01-24T15:16:29.286+0000] {spark_submit.py:579} INFO - 25/01/24 15:16:29 INFO TaskSetManager: Finished task 20.0 in stage 11.0 (TID 77) in 62 ms on 172.18.0.10 (executor 0) (21/50)
[2025-01-24T15:16:29.290+0000] {spark_submit.py:579} INFO - 25/01/24 15:16:29 INFO TaskSetManager: Finished task 21.0 in stage 11.0 (TID 78) in 34 ms on 172.18.0.10 (executor 0) (22/50)
[2025-01-24T15:16:29.292+0000] {spark_submit.py:579} INFO - 25/01/24 15:16:29 INFO TaskSetManager: Starting task 23.0 in stage 11.0 (TID 80) (172.18.0.10, executor 0, partition 23, PROCESS_LOCAL, 4457 bytes) taskResourceAssignments Map()
[2025-01-24T15:16:29.324+0000] {spark_submit.py:579} INFO - 25/01/24 15:16:29 INFO TaskSetManager: Starting task 24.0 in stage 11.0 (TID 81) (172.18.0.10, executor 0, partition 24, PROCESS_LOCAL, 4457 bytes) taskResourceAssignments Map()
[2025-01-24T15:16:29.325+0000] {spark_submit.py:579} INFO - 25/01/24 15:16:29 INFO TaskSetManager: Finished task 22.0 in stage 11.0 (TID 79) in 32 ms on 172.18.0.10 (executor 0) (23/50)
[2025-01-24T15:16:29.343+0000] {spark_submit.py:579} INFO - 25/01/24 15:16:29 INFO TaskSetManager: Starting task 25.0 in stage 11.0 (TID 82) (172.18.0.10, executor 0, partition 25, PROCESS_LOCAL, 4457 bytes) taskResourceAssignments Map()
[2025-01-24T15:16:29.344+0000] {spark_submit.py:579} INFO - 25/01/24 15:16:29 INFO TaskSetManager: Finished task 23.0 in stage 11.0 (TID 80) in 52 ms on 172.18.0.10 (executor 0) (24/50)
[2025-01-24T15:16:29.346+0000] {spark_submit.py:579} INFO - 25/01/24 15:16:29 INFO TaskSetManager: Starting task 26.0 in stage 11.0 (TID 83) (172.18.0.10, executor 0, partition 26, PROCESS_LOCAL, 4457 bytes) taskResourceAssignments Map()
[2025-01-24T15:16:29.346+0000] {spark_submit.py:579} INFO - 25/01/24 15:16:29 INFO TaskSetManager: Finished task 24.0 in stage 11.0 (TID 81) in 31 ms on 172.18.0.10 (executor 0) (25/50)
[2025-01-24T15:16:29.371+0000] {spark_submit.py:579} INFO - 25/01/24 15:16:29 INFO TaskSetManager: Starting task 27.0 in stage 11.0 (TID 84) (172.18.0.10, executor 0, partition 27, PROCESS_LOCAL, 4457 bytes) taskResourceAssignments Map()
[2025-01-24T15:16:29.372+0000] {spark_submit.py:579} INFO - 25/01/24 15:16:29 INFO TaskSetManager: Finished task 25.0 in stage 11.0 (TID 82) in 29 ms on 172.18.0.10 (executor 0) (26/50)
[2025-01-24T15:16:29.379+0000] {spark_submit.py:579} INFO - 25/01/24 15:16:29 INFO TaskSetManager: Starting task 28.0 in stage 11.0 (TID 85) (172.18.0.10, executor 0, partition 28, PROCESS_LOCAL, 4457 bytes) taskResourceAssignments Map()
[2025-01-24T15:16:29.395+0000] {spark_submit.py:579} INFO - 25/01/24 15:16:29 INFO TaskSetManager: Finished task 26.0 in stage 11.0 (TID 83) in 30 ms on 172.18.0.10 (executor 0) (27/50)
[2025-01-24T15:16:29.405+0000] {spark_submit.py:579} INFO - 25/01/24 15:16:29 INFO TaskSetManager: Starting task 29.0 in stage 11.0 (TID 86) (172.18.0.10, executor 0, partition 29, PROCESS_LOCAL, 4457 bytes) taskResourceAssignments Map()
[2025-01-24T15:16:29.406+0000] {spark_submit.py:579} INFO - 25/01/24 15:16:29 INFO TaskSetManager: Finished task 27.0 in stage 11.0 (TID 84) in 37 ms on 172.18.0.10 (executor 0) (28/50)
[2025-01-24T15:16:29.410+0000] {spark_submit.py:579} INFO - 25/01/24 15:16:29 INFO TaskSetManager: Starting task 30.0 in stage 11.0 (TID 87) (172.18.0.10, executor 0, partition 30, PROCESS_LOCAL, 4457 bytes) taskResourceAssignments Map()
[2025-01-24T15:16:29.411+0000] {spark_submit.py:579} INFO - 25/01/24 15:16:29 INFO TaskSetManager: Finished task 28.0 in stage 11.0 (TID 85) in 37 ms on 172.18.0.10 (executor 0) (29/50)
[2025-01-24T15:16:29.439+0000] {spark_submit.py:579} INFO - 25/01/24 15:16:29 INFO TaskSetManager: Starting task 31.0 in stage 11.0 (TID 88) (172.18.0.10, executor 0, partition 31, PROCESS_LOCAL, 4457 bytes) taskResourceAssignments Map()
[2025-01-24T15:16:29.441+0000] {spark_submit.py:579} INFO - 25/01/24 15:16:29 INFO TaskSetManager: Starting task 32.0 in stage 11.0 (TID 89) (172.18.0.10, executor 0, partition 32, PROCESS_LOCAL, 4457 bytes) taskResourceAssignments Map()
[2025-01-24T15:16:29.444+0000] {spark_submit.py:579} INFO - 25/01/24 15:16:29 INFO TaskSetManager: Finished task 30.0 in stage 11.0 (TID 87) in 34 ms on 172.18.0.10 (executor 0) (30/50)
[2025-01-24T15:16:29.446+0000] {spark_submit.py:579} INFO - 25/01/24 15:16:29 INFO TaskSetManager: Finished task 29.0 in stage 11.0 (TID 86) in 40 ms on 172.18.0.10 (executor 0) (31/50)
[2025-01-24T15:16:29.461+0000] {spark_submit.py:579} INFO - 25/01/24 15:16:29 INFO TaskSetManager: Starting task 33.0 in stage 11.0 (TID 90) (172.18.0.10, executor 0, partition 33, PROCESS_LOCAL, 4457 bytes) taskResourceAssignments Map()
[2025-01-24T15:16:29.463+0000] {spark_submit.py:579} INFO - 25/01/24 15:16:29 INFO TaskSetManager: Finished task 31.0 in stage 11.0 (TID 88) in 25 ms on 172.18.0.10 (executor 0) (32/50)
[2025-01-24T15:16:29.484+0000] {spark_submit.py:579} INFO - 25/01/24 15:16:29 INFO TaskSetManager: Starting task 34.0 in stage 11.0 (TID 91) (172.18.0.10, executor 0, partition 34, PROCESS_LOCAL, 4457 bytes) taskResourceAssignments Map()
[2025-01-24T15:16:29.486+0000] {spark_submit.py:579} INFO - 25/01/24 15:16:29 INFO TaskSetManager: Finished task 32.0 in stage 11.0 (TID 89) in 45 ms on 172.18.0.10 (executor 0) (33/50)
[2025-01-24T15:16:29.521+0000] {spark_submit.py:579} INFO - 25/01/24 15:16:29 INFO TaskSetManager: Starting task 35.0 in stage 11.0 (TID 92) (172.18.0.10, executor 0, partition 35, PROCESS_LOCAL, 4457 bytes) taskResourceAssignments Map()
[2025-01-24T15:16:29.522+0000] {spark_submit.py:579} INFO - 25/01/24 15:16:29 INFO TaskSetManager: Starting task 36.0 in stage 11.0 (TID 93) (172.18.0.10, executor 0, partition 36, PROCESS_LOCAL, 4457 bytes) taskResourceAssignments Map()
[2025-01-24T15:16:29.524+0000] {spark_submit.py:579} INFO - 25/01/24 15:16:29 INFO TaskSetManager: Finished task 34.0 in stage 11.0 (TID 91) in 40 ms on 172.18.0.10 (executor 0) (34/50)
[2025-01-24T15:16:29.525+0000] {spark_submit.py:579} INFO - 25/01/24 15:16:29 INFO TaskSetManager: Finished task 33.0 in stage 11.0 (TID 90) in 64 ms on 172.18.0.10 (executor 0) (35/50)
[2025-01-24T15:16:29.548+0000] {spark_submit.py:579} INFO - 25/01/24 15:16:29 INFO TaskSetManager: Starting task 37.0 in stage 11.0 (TID 94) (172.18.0.10, executor 0, partition 37, PROCESS_LOCAL, 4457 bytes) taskResourceAssignments Map()
[2025-01-24T15:16:29.550+0000] {spark_submit.py:579} INFO - 25/01/24 15:16:29 INFO TaskSetManager: Finished task 35.0 in stage 11.0 (TID 92) in 31 ms on 172.18.0.10 (executor 0) (36/50)
[2025-01-24T15:16:29.556+0000] {spark_submit.py:579} INFO - 25/01/24 15:16:29 INFO TaskSetManager: Starting task 38.0 in stage 11.0 (TID 95) (172.18.0.10, executor 0, partition 38, PROCESS_LOCAL, 4457 bytes) taskResourceAssignments Map()
[2025-01-24T15:16:29.558+0000] {spark_submit.py:579} INFO - 25/01/24 15:16:29 INFO TaskSetManager: Finished task 36.0 in stage 11.0 (TID 93) in 35 ms on 172.18.0.10 (executor 0) (37/50)
[2025-01-24T15:16:29.579+0000] {spark_submit.py:579} INFO - 25/01/24 15:16:29 INFO TaskSetManager: Starting task 39.0 in stage 11.0 (TID 96) (172.18.0.10, executor 0, partition 39, PROCESS_LOCAL, 4457 bytes) taskResourceAssignments Map()
[2025-01-24T15:16:29.580+0000] {spark_submit.py:579} INFO - 25/01/24 15:16:29 INFO TaskSetManager: Finished task 38.0 in stage 11.0 (TID 95) in 23 ms on 172.18.0.10 (executor 0) (38/50)
[2025-01-24T15:16:29.588+0000] {spark_submit.py:579} INFO - 25/01/24 15:16:29 INFO TaskSetManager: Finished task 37.0 in stage 11.0 (TID 94) in 40 ms on 172.18.0.10 (executor 0) (39/50)
[2025-01-24T15:16:29.598+0000] {spark_submit.py:579} INFO - 25/01/24 15:16:29 INFO TaskSetManager: Starting task 40.0 in stage 11.0 (TID 97) (172.18.0.10, executor 0, partition 40, PROCESS_LOCAL, 4457 bytes) taskResourceAssignments Map()
[2025-01-24T15:16:29.602+0000] {spark_submit.py:579} INFO - 25/01/24 15:16:29 INFO TaskSetManager: Starting task 41.0 in stage 11.0 (TID 98) (172.18.0.10, executor 0, partition 41, PROCESS_LOCAL, 4457 bytes) taskResourceAssignments Map()
[2025-01-24T15:16:29.603+0000] {spark_submit.py:579} INFO - 25/01/24 15:16:29 INFO TaskSetManager: Finished task 39.0 in stage 11.0 (TID 96) in 24 ms on 172.18.0.10 (executor 0) (40/50)
[2025-01-24T15:16:29.629+0000] {spark_submit.py:579} INFO - 25/01/24 15:16:29 INFO TaskSetManager: Starting task 42.0 in stage 11.0 (TID 99) (172.18.0.10, executor 0, partition 42, PROCESS_LOCAL, 4457 bytes) taskResourceAssignments Map()
[2025-01-24T15:16:29.630+0000] {spark_submit.py:579} INFO - 25/01/24 15:16:29 INFO TaskSetManager: Finished task 41.0 in stage 11.0 (TID 98) in 24 ms on 172.18.0.10 (executor 0) (41/50)
[2025-01-24T15:16:29.638+0000] {spark_submit.py:579} INFO - 25/01/24 15:16:29 INFO TaskSetManager: Starting task 43.0 in stage 11.0 (TID 100) (172.18.0.10, executor 0, partition 43, PROCESS_LOCAL, 4457 bytes) taskResourceAssignments Map()
[2025-01-24T15:16:29.641+0000] {spark_submit.py:579} INFO - 25/01/24 15:16:29 INFO TaskSetManager: Finished task 40.0 in stage 11.0 (TID 97) in 43 ms on 172.18.0.10 (executor 0) (42/50)
[2025-01-24T15:16:29.651+0000] {spark_submit.py:579} INFO - 25/01/24 15:16:29 INFO TaskSetManager: Starting task 44.0 in stage 11.0 (TID 101) (172.18.0.10, executor 0, partition 44, PROCESS_LOCAL, 4457 bytes) taskResourceAssignments Map()
[2025-01-24T15:16:29.652+0000] {spark_submit.py:579} INFO - 25/01/24 15:16:29 INFO TaskSetManager: Finished task 42.0 in stage 11.0 (TID 99) in 27 ms on 172.18.0.10 (executor 0) (43/50)
[2025-01-24T15:16:29.667+0000] {spark_submit.py:579} INFO - 25/01/24 15:16:29 INFO TaskSetManager: Starting task 45.0 in stage 11.0 (TID 102) (172.18.0.10, executor 0, partition 45, PROCESS_LOCAL, 4457 bytes) taskResourceAssignments Map()
